Workbook

Sheet Trade_Log
A1: trade_id | B1: account_id | C1: system | D1: underlying_symbol | E1: asset_type | F1: direction | G1: open_date | H1: open_datetime | I1: qty | J1: entry_price | K1: stop_price | L1: risk_amount | M1: total_commissions | N1: status | O1: realized_pnl | P1: realized_R | Q1: schwab_transaction_id | R1: notes
A2: 2384 | B2: AJZ6348 | C2: TOS_Import | D2: TCBX | E2: stock | F2: long | G2: 2024-10-29 | I2: 40 | J2: 33.4175 | L2: 20.05 | M2: 0.05 | N2: closed | O2: -35.5 | P2: -1.77
A3: 2383 | B3: AJZ6348 | C3: TOS_Import | D3: AMSC | E3: stock | F3: long | G3: 2024-11-04 | I3: 65 | J3: 28.1133 | L3: 27.41 | M3: 0.07 | N3: closed | O3: 360.54 | P3: 13.15
A4: 2381 | B4: AJZ6348 | C4: TOS_Import | D4: ANGI | E4: stock | F4: long | G4: 2024-11-05 | I4: 775 | J4: 2.47 | L4: 28.71 | M4: 0.17 | N4: closed | O4: -333.25 | P4: -11.61
A5: 2382 | B5: AJZ6348 | C5: TOS_Import | D5: CF | E5: stock | F5: long | G5: 2024-11-05 | I5: 20 | J5: 85.89 | L5: 25.77 | M5: 0.05 | N5: closed | O5: -39.8 | P5: -1.54
A6: 2380 | B6: AJZ6348 | C6: TOS_Import | D6: EDN | E6: stock | F6: long | G6: 2024-11-06 | I6: 50 | J6: 32.39 | L6: 24.29 | M6: 0.05 | N6: closed | O6: -143.5 | P6: -5.91
A7: 2379 | B7: AJZ6348 | C7: TOS_Import | D7: TILE | E7: stock | F7: long | G7: 2024-11-07 | I7: 50 | J7: 24.4999 | L7: 18.37 | M7: 0.05 | N7: closed | O7: 62.5 | P7: 3.4
A8: 2374 | B8: AJZ6348 | C8: TOS_Import | D8: MCB | E8: stock | F8: long | G8: 2024-11-12 | I8: 30 | J8: 64.5607 | L8: 29.05 | M8: 0.05 | N8: closed | O8: -137.42 | P8: -4.73
A9: 2375 | B9: AJZ6348 | C9: TOS_Import | D9: DYNF | E9: stock | F9: long | G9: 2024-11-12 | I9: 35 | J9: 52.2001 | L9: 27.41 | M9: 0.06 | N9: closed | O9: 0 | P9: 0
A10: 2376 | B10: AJZ6348 | C10: TOS_Import | D10: INSG | E10: stock | F10: long | G10: 2024-11-12 | I10: 95 | J10: 18.63 | L10: 26.55 | M10: 0.07 | N10: closed | O10: -37.05 | P10: -1.4
A11: 2377 | B11: AJZ6348 | C11: TOS_Import | D11: CSV | E11: stock | F11: long | G11: 2024-11-12 | I11: 440 | J11: 40.0577 | L11: 264.38 | M11: 0.56 | N11: closed | O11: -171.79 | P11: -0.65
A12: 2378 | B12: AJZ6348 | C12: TOS_Import | D12: CEIX | E12: stock | F12: long | G12: 2024-11-12 | I12: 15 | J12: 128.66 | L12: 28.95 | M12: 0.05 | N12: closed | O12: -39.3 | P12: -1.36
A13: 2373 | B13: AJZ6348 | C13: TOS_Import | D13: FTNT | E13: stock | F13: long | G13: 2024-11-13 | I13: 20 | J13: 98.08 | L13: 29.42 | M13: 0.05 | N13: closed | O13: -129.6 | P13: -4.41
... A24: 2361 | B24: AJZ6348 | C24: TOS_Import | D24: RAND | E24: stock | F24: long | G24: 2024-12-12 | I24: 80 | J24: 22.62 | L24: 27.14 | M24: 0.06 | N24: closed | O24: -381.73 | P24: -14.07
A25: 2362 | B25: AJZ6348 | C25: TOS_Import | D25: SMLR | E25: stock | F25: long | G25: 2024-12-12 | I25: 20 | J25: 70.4178 | L25: 21.13 | M25: 0 | N25: closed | O25: 0 | P25: 0 | R25: Administratively closed 2026-09-02 -- pre-2026 legacy trade, no relevance to 2026 strategy tracking (Tony's directive).
A26: 2360 | B26: AJZ6348 | C26: TOS_Import | D26: SOUN | E26: stock | F26: long | G26: 2024-12-13 | I26: 100 | J26: 16.082 | L26: 24.12 | M26: 0.07 | N26: closed | O26: 275.55 | P26: 11.42
A27: 2359 | B27: AJZ6348 | C27: TOS_Import | D27: C | E27: call | F27: long | G27: 2024-12-16 | I27: 2 | J27: 4.89 | L27: 14.67 | M27: 2.67 | N27: closed | O27: -218 | P27: -14.86
A28: 2357 | B28: AJZ6348 | C28: TOS_Import | D28: SMLR | E28: stock | F28: long | G28: 2024-12-17 | I28: 20 | J28: 74.87 | L28: 22.46 | M28: 0.08 | N28: closed | O28: -143 | P28: -6.37
A29: 2358 | B29: AJZ6348 | C29: TOS_Import | D29: SUPV | E29: stock | F29: long | G29: 2024-12-17 | I29: 100 | J29: 15.9277 | L29: 23.89 | M29: 0.07 | N29: closed | O29: 201.23 | P29: 8.42
A30: 2356 | B30: AJZ6348 | C30: TOS_Import | D30: XMTR | E30: stock | F30: long | G30: 2024-12-18 | I30: 30 | J30: 40.32 | L30: 18.14 | M30: 0.03 | N30: closed | O30: 30 | P30: 1.65
A31: 2355 | B31: AJZ6348 | C31: TOS_Import | D31: FEIM | E31: stock | F31: long | G31: 2024-12-19 | I31: 85 | J31: 18.54 | L31: 23.64 | M31: 0.05 | N31: closed | O31: 6.8 | P31: 0.29
A32: 2354 | B32: AJZ6348 | C32: TOS_Import | D32: QNTM | E32: stock | F32: long | G32: 2024-12-20 | I32: 300 | J32: 3.81 | L32: 17.14 | M32: 0.08 | N32: closed | O32: -243 | P32: -14.18
A33: 2351 | B33: AJZ6348 | C33: TOS_Import | D33: SOUN | E33: call | F33: long | G33: 2024-12-23 | I33: 3 | J33: 3.4 | L33: 15.3 | M33: 4.01 | N33: closed | O33: 258 | P33: 16.86
A34: 2352 | B34: AJZ6348 | C34: TOS_Import | D34: SOUN | E34: stock | F34: long | G34: 2024-12-23 | I34: 50 | J34: 21 | L34: 15.75 | M34: 0.04 | N34: closed | O34: -49.62 | P34: -3.15
A35: 2353 | B35: AJZ6348 | C35: TOS_Import | D35: SCHW | E35: call | F35: long | G35: 2024-12-23 | I35: 2 | J35: 3.14 | L35: 9.42 | M35: 2.66 | N35: closed | O35: -126 | P35: -13.38
A36: 2350 | B36: AJZ6348 | C36: TOS_Import | D36: QUBT | E36: stock | F36: long | G36: 2024-12-27 | I36: 80 | J36: 21.4922 | L36: 25.79 | M36: 0.05 | N36: closed | O36: -269.42 | P36: -10.45
A37: 2347 | B37: AJZ6348 | C37: TOS_Import | D37: ARQQ | E37: stock | F37: long | G37: 2024-12-30 | I37: 30 | J37: 44.98 | L37: 20.24 | M37: 0.02 | N37: closed | O37: -479.4 | P37: -23.69
... A56: 2333 | B56: AJZ6348 | C56: TOS_Import | D56: GRRR | E56: stock | F56: long | G56: 2025-01-27 | I56: 60 | J56: 14.11 | L56: 12.7 | M56: 0.03 | N56: closed | O56: -78 | P56: -6.14
A57: 2326 | B57: AJZ6348 | C57: TOS_Import | D57: OKLO | E57: stock | F57: long | G57: 2025-01-28 | I57: 40 | J57: 33.9999 | L57: 20.4 | M57: 0 | N57: closed | O57: 0 | P57: 0 | R57: Administratively closed 2026-09-02 -- pre-2026 legacy trade, no relevance to 2026 strategy tracking (Tony's directive).
A58: 2327 | B58: AJZ6348 | C58: TOS_Import | D58: HOOD | E58: call | F58: long | G58: 2025-01-28 | I58: 2 | J58: 5.6 | L58: 16.8 | M58: 2.69 | N58: closed | O58: 480 | P58: 28.57
A59: 2328 | B59: AJZ6348 | C59: TOS_Import | D59: BAC | E59: call | F59: long | G59: 2025-01-28 | I59: 5 | J59: 1.02 | L59: 7.65 | M59: 6.62 | N59: closed | O59: -100 | P59: -13.07
A60: 2329 | B60: AJZ6348 | C60: TOS_Import | D60: ETON | E60: stock | F60: long | G60: 2025-01-28 | I60: 70 | J60: 17.52 | L60: 18.4 | M60: 0.04 | N60: closed | O60: -59.85 | P60: -3.25
A61: 2322 | B61: AJZ6348 | C61: TOS_Import | D61: OKLO | E61: stock | F61: long | G61: 2025-01-29 | I61: 40 | J61: 34.925 | L61: 20.95 | M61: 0.12 | N61: closed | O61: 1114.8 | P61: 53.21
A62: 2323 | B62: AJZ6348 | C62: TOS_Import | D62: DCTH | E62: stock | F62: long | G62: 2025-01-29 | I62: 80 | J62: 15.51 | L62: 18.61 | M62: 0.04 | N62: closed | O62: -39.2 | P62: -2.11
A63: 2324 | B63: AJZ6348 | C63: TOS_Import | D63: BOWFF | E63: stock | F63: long | G63: 2025-01-29 | I63: 30 | J63: 42.7646 | L63: 19.24 | M63: 13.94 | N63: closed | O63: 102.09 | P63: 5.31
A64: 2325 | B64: AJZ6348 | C64: TOS_Import | D64: YELP | E64: stock | F64: long | G64: 2025-01-29 | I64: 30 | J64: 41.265 | L64: 18.57 | M64: 0.04 | N64: closed | O64: -58.72 | P64: -3.16
A65: 2321 | B65: AJZ6348 | C65: TOS_Import | D65: CCSI | E65: stock | F65: long | G65: 2025-01-30 | I65: 40 | J65: 30.17 | L65: 18.1 | M65: 0.03 | N65: closed | O65: -118.76 | P65: -6.56
A66: 2319 | B66: AJZ6348 | C66: TOS_Import | D66: AG | E66: stock | F66: long | G66: 2025-01-31 | I66: 200 | J66: 5.7988 | L66: 17.4 | M66: 0.06 | N66: closed | O66: -39.76 | P66: -2.29
A67: 2320 | B67: AJZ6348 | C67: TOS_Import | D67: DSP | E67: stock | F67: long | G67: 2025-01-31 | I67: 55 | J67: 22.4 | L67: 18.48 | M67: 0.05 | N67: closed | O67: 32.18 | P67: 1.74
A68: 2318 | B68: AJZ6348 | C68: TOS_Import | D68: CAH | E68: call | F68: long | G68: 2025-02-03 | I68: 1 | J68: 9.7 | L68: 14.55 | M68: 1.35 | N68: closed | O68: 250 | P68: 17.18
...

Sheet Market_Data
A1: Date | B1: AA | C1: AADX | D1: AAL | E1: AAOI | F1: AAP | G1: AAPL | H1: AB | I1: ABNB | J1: ABT | K1: ACAD | L1: ACHR | M1: ADM | N1: AEO | O1: AFL | P1: AFRM | Q1: AG | R1: AGCO | S1: AIFF | T1: AKAM | U1: ALGS | V1: AMD | W1: AMG | X1: AMIX | Y1: AMKR | Z1: AMSC | AA1: AMZN | AB1: ANET | AC1: ANGI | AD1: ANRO | AE1: APH | AF1: APPS | AG1: APVO | AH1: ARQQ | AI1: ARR | AJ1: ASX | AK1: ATEC | AL1: AXGN | AM1: BAC | AN1: BANC | AO1: BBY | AP1: BEAM | AQ1: BEKE | AR1: BGC | AS1: BITQ | AT1: BITX | AU1: BMY | AV1: BOWFF | AW1: BTAI | AX1: BTDR | AY1: C | AZ1: CAH | BA1: CAL | BB1: CCI | BC1: CCJ | BD1: CCL | BE1: CCSI | BF1: CF | BG1: CLSK | BH1: CMCL | BI1: CMCSA | BJ1: CME | BK1: COHR | BL1: COIN | BM1: COMP | BN1: COP | BO1: COST | BP1: CPIX | BQ1: CRDO | BR1: CRML | BS1: CRNC | BT1: CSCO | BU1: CSV | BV1: CSX | BW1: CVNA | BX1: CVS | BY1: CW | BZ1: DAL | CA1: DASH | CB1: DCTH | CC1: DDOG | CD1: DELL | CE1: DG | CF1: DGICA | CG1: DINO | CH1: DIS | CI1: DJT | CJ1: DLR | CK1: DMRA | CL1: DOCU | CM1: DOMH | CN1: DOW | CO1: DOX | CP1: DSP | CQ1: DUK | CR1: DYNF | CS1: EBAY | CT1: EDN | CU1: ETON | CV1: ETSY | CW1: EWZ | CX1: F | CY1: FEIM | CZ1: FLR | DA1: FLWS | DB1: FSM | DC1: FTNT | DD1: FUTU | DE1: GDX | DF1: GE | DG1: GLD | DH1: GLXY | DI1: GM | DJ1: GOOG | DK1: GOOGL | DL1: GRPN | DM1: GRRR | DN1: HIG | DO1: HIMS | DP1: HOOD | DQ1: HWM | DR1: IAU | DS1: IBEX | DT1: IBM | DU1: ILMN | DV1: IMDX | DW1: INBS | DX1: INSG | DY1: INTC | DZ1: IONQ | EA1: IRDM | EB1: IRM | EC1: ISPC | ED1: IWM | EE1: JCI | EF1: JNJ | EG1: KC | EH1: KINS | EI1: KO | EJ1: KR | EK1: KTTA | EL1: LEVI | EM1: LION | EN1: LMND | EO1: LNG | EP1: LOW | EQ1: LQDA | ER1: LRCX | ES1: LSAK | ET1: LUNR | EU1: M | EV1: MA | EW1: MAIA | EX1: MARA | EY1: MCB | EZ1: MCHP | FA1: MDT | FB1: META | FC1: MO | FD1: MOMO | FE1: MOS | FF1: MRK | FG1: MRNA | FH1: MRVL | FI1: MS | FJ1: MSFT | FK1: MSTR | FL1: NCTY | FM1: NEE | FN1: NEM | FO1: NEXA | FP1: NFLX | FQ1: NG | FR1: NNDM | FS1: NTAP | FT1: NU | FU1: NVDA | FV1: NXT | FW1: OKLO | FX1: OPEN | FY1: OPFI | FZ1: ORMP | GA1: P | GB1: PANW | GC1: PENG | GD1: PLTR | GE1: PM | GF1: PNC | GG1: PPC | GH1: PPTA | GI1: QBTS | GJ1: QNTM | GK1: QQQ | GL1: QUBT | GM1: RAND | GN1: RBLX | GO1: RDDT | GP1: RDW | GQ1: REAL | GR1: RGLD | GS1: RGTI | GT1: RIG | GU1: RIOT | GV1: RKLB | GW1: ROKU | GX1: ROOT | GY1: ROST | GZ1: RTX | HA1: RXRX | HB1: SBH | HC1: SBUX | HD1: SCHW | HE1: SEGG | HF1: SGML | HG1: SHEL | HH1: SMTC | HI1: SNAP | HJ1: SOFI | HK1: SONY | HL1: SOUN | HM1: SPY | HN1: SSYS | HO1: SU | HP1: SUPN | HQ1: SUPV | HR1: SWAG | HS1: SWPPX | HT1: TCBX | HU1: TDOC | HV1: TIGO | HW1: TILE | HX1: TME | HY1: TMUS | HZ1: TPR | IA1: TSLA | IB1: TTD | IC1: TWLO | ID1: UAL | IE1: UBER | IF1: UBS | IG1: UPRO | IH1: UPXI | II1: URBN | IJ1: USAR | IK1: UUU | IL1: VATE | IM1: VLO | IN1: VOD | IO1: VYX | IP1: VZ | IQ1: WBD | IR1: WFC | IS1: WMG | IT1: WMT | IU1: WRAP | IV1: WT | IW1: WULF | IX1: XLE | IY1: XLK | IZ1: XLV | JA1: XMTR | JB1: XPEV | JC1: XYZ | JD1: YELP | JE1: YUM | JF1: ZION | JG1: ZM | JH1: ZSPC | JI1: ZTS
A2: 2025-09-22 | B2: 32.374348 | D2: 12.33 | E2: 30.540001 | F2: 58.975525 | G2: 255.13751 | H2: 35.537224 | I2: 125.44 | J2: 133.53354 | K2: 24.530001 | L2: 9.5500002 | M2: 58.160679 | N2: 17.470316 | O2: 105.20063 | P2: 90.120003 | Q2: 12.116218 | R2: 108.32666 | S2: 2.9400001 | T2: 76.68 | U2: 9.5299997 | V2: 159.78999 | W2: 243.97763 | X2: 23.309999 | Y2: 29.325592 | Z2: 64.629997 | AA2: 227.63 | AB2: 145.39999 | AC2: 17.08 | AD2: 3.98 | AE2: 61.511417 | AF2: 5.46 | AG2: 30.42 | AH2: 41.27 | AI2: 11.851522 | AJ2: 11.593375 | AK2: 15.6 | AL2: 17.6 | AM2: 50.836372 | AN2: 16.097094 | AO2: 68.672638 | AP2: 24.41 | AQ2: 18.988596 | AR2: 9.5721178 | AS2: 25.09 | AT2: 50.080688 | AU2: 42.919907 | AV2: 50.284149 | AW2: 2.78 | AX2: 17.959999 | AY2: 101.34604 | AZ2: 145.9521 | BA2: 13.949263 | BB2: 89.662743 | BC2: 86.142273 | BD2: 30.224304 | BE2: 28.959999 | BF2: 83.903549 | BG2: 13.74 | BH2: 33.795559 | BI2: 28.149002 | BJ2: 251.32535 | BK2: 114.6 | BL2: 331.95001 | BM2: 7.9200001 | BN2: 89.197906 | BO2: 937.78845 | BP2: 2.5047007 | BQ2: 164.10001 | BR2: 6.9099998 | BS2: 12.5 | BT2: 66.375603 | BU2: 44.856907 | BV2: 32.77866 | BW2: 78.169998 | BX2: 72.818733 | BY2: 517.31409 | BZ2: 58.252712 | CA2: 262.75 | CB2: 11.55 | CC2: 138.35001 | CD2: 133.98265 | CE2: 99.832603 | CF2: 18.58465 | CG2: 50.754372 | CH2: 110.95337 | CI2: 17.6 | CJ2: 169.8262 | CK2: 3 | CL2: 84.860001 | CM2: 5.8222656 | CN2: 22.080215 | CO2: 81.877861 | CP2: 9.4099998 | CQ2: 117.45779 | CR2: 58.797916 | CS2: 89.450043 | CT2: 18.209999 | CU2: 18.370001 | CV2: 61.669998 | CW2: 29.467108 | CX2: 11.140587 | CY2: 29.889999 | CZ2: 44.75 | DA2: 5.4000001 | DB2: 8.5100002 | DC2: 85.010002 | DD2: 165.07265 | DE2: 73.794052 | DF2: 299.49902 | DG2: 345.04999 | DH2: 33.689999 | DI2: 58.376362 | DJ2: 252.22159 | DK2: 251.87495 | DL2: 22.790001 | DM2: 20.860001 | DN2: 128.40837 | DO2: 57.700001 | DP2: 124.89 | DQ2: 191.75079 | DR2: 70.629997 | DS2: 41.959999 | DT2: 264.49396 | DU2: 101.49 | DV2: 3.27 | DW2: 13.45 | DX2: 13.41 | DY2: 28.76 | DZ2: 71.940002 | EA2: 17.76174 | EB2: 101.05965 | EC2: 65.599998 | ED2: 241.93198 | EE2: 108.65349 | EF2: 170.37057 | EG2: 16.77 | EH2: 13.71306 | EI2: 64.495461 | EJ2: 63.089924 | EK2: 0.73000002 | EL2: 22.315327 | EM2: 6.8600001 | EN2: 59.68 | EO2: 228.55049 | EP2: 255.14835 | EQ2: 22.9 | ER2: 131.47235 | ES2: 4.0999999 | ET2: 10.13 | EU2: 16.30995 | EV2: 580.8703 | EW2: 1.52 | EX2: 18.35 | EY2: 76.643494 | EZ2: 63.730747 | FA2: 91.640358 | FB2: 763.17511 | FC2: 59.749107 | FD2: 7.1978278 | FE2: 32.24567 | FF2: 78.106491 | FG2: 26.559999 | FH2: 75.369423 | FI2: 157.14757 | FJ2: 510.25189 | FK2: 335.92999 | FL2: 10.29 | FM2: 70.328819 | FN2: 82.942062 | FO2: 4.9487977 | FP2: 122.737 | FQ2: 7.6399999 | FR2: 1.47 | FS2: 122.46673 | FT2: 16.299999 | FU2: 183.17116 | FV2: 73.139999 | FW2: 140.3 | FX2: 8.3800001 | FY2: 11.63 | FZ2: 2.3026559 | GA2: 87.849998 | GB2: 208.17999 | GC2: 27.9 | GD2: 179.33 | GE2: 156.31873 | GF2: 196.64906 | GG2: 41.189999 | GH2: 18.860001 | GI2: 25.67 | GJ2: 18.49 | GK2: 600.00836 | GL2: 20.209999 | GM2: 12.981513 | GN2: 136.84 | GO2: 257.56 | GP2: 8.1099997 | GQ2: 10.74 | GR2: 189.88124 | GS2: 28.370001 | GT2: 3.3900001 | GU2: 17.5 | GV2: 49.810001 | GW2: 99.050003 | GX2: 102.88 | GY2: 143.47595 | GZ2: 157.09822 | HA2: 4.98 | HB2: 15.03 | HC2: 83.167648 | HD2: 93.238297 | HE2: 38.150002 | HF2: 6.27 | HG2: 68.501541 | HH2: 61.529999 | HI2: 8.5299997 | HJ2: 29.809999 | HK2: 29.73 | HL2: 17.309999 | HM2: 659.72247 | HN2: 10.37 | HO2: 40.923199 | HP2: 46.98 | HQ2: 6.2199998 | HR2: 1.79 | HS2: 17.091333 | HT2: 40.040001 | HU2: 8.1899996 | HV2: 44.470009 | HW2: 29.618856 | HX2: 23.665396 | HY2: 232.52783 | HZ2: 112.43216 | IA2: 434.20999 | IB2: 46.150002 | IC2: 105.19 | ID2: 104.18 | IE2: 99.389999 | IF2: 41.314217 | IG2: 111.35452 | IH2: 6.0700002 | II2: 72.120003 | IJ2: 16.08 | IK2: 6.1804423 | IL2: 5.1399999 | IM2: 162.98442 | IN2: 10.943772 | IO2: 13.03 | IP2: 40.400299 | IQ2: 19.610001 | IR2: 83.342575 | IS2: 32.31937 | IT2: 101.96153 | IU2: 2.5599999 | IV2: 14.562538 | IW2: 11.49 | IX2: 42.873158 | IY2: 140.77286 | IZ2: 134.8987 | JA2: 55.029999 | JB2: 21.360001 | JC2: 77.410004 | JD2: 31.74 | JE2: 146.42647 | JF2: 55.399086 | JG2: 83.529999 | JH2: 39 | JI2: 141.92424
A3: 2025-09-23 | B3: 31.282961 | D3: 12.19 | E3: 28.059999 | F3: 58.92651 | G3: 253.49361 | H3: 34.942493 | I3: 123.5 | J3: 132.82002 | K3: 23.6 | L3: 10 | M3: 58.976833 | N3: 17.489779 | O3: 106.01365 | P3: 82.730003 | Q3: 11.776882 | R3: 108.53448 | S3: 2.8499999 | T3: 75.269997 | U3: 10.25 | V3: 160.89999 | W3: 241.81793 | X3: 22.26 | Y3: 29.375248 | Z3: 61.34 | AA3: 220.71001 | AB3: 144.09 | AC3: 16.6 | AD3: 4.1100001 | AE3: 62.361805 | AF3: 5.4899998 | AG3: 29.52 | AH3: 40.59 | AI3: 12.003358 | AJ3: 11.583475 | AK3: 15.49 | AL3: 17.299999 | AM3: 50.620964 | AN3: 16.106852 | AO3: 69.31826 | AP3: 23.73 | AQ3: 18.389679 | AR3: 9.522521 | AS3: 24.76 | AT3: 49.58889 | AU3: 42.853115 | AV3: 50.157234 | AW3: 2.47 | AX3: 16.57 | AY3: 100.8662 | AZ3: 153.02852 | BA3: 13.607129 | BB3: 89.729317 | BC3: 86.721146 | BD3: 30.224304 | BE3: 29.18 | BF3: 85.373123 | BG3: 13.91 | BH3: 34.230488 | BI3: 28.265209 | BJ3: 252.17244 | BK3: 109.29 | BL3: 320.07001 | BM3: 7.9400001 | BN3: 90.613281 | BO3: 938.1264 | BP3: 2.3108382 | BQ3: 162.25999 | BR3: 6.6999998 | BS3: 11.95 | BT3: 66.169861 | BU3: 44.431301 | BV3: 33.637623 | BW3: 75.620003 | BX3: 74.146591 | BY3: 517.38409 | BZ3: 58.114227 | CA3: 265.75 | CB3: 11 | CC3: 137.49001 | CD3: 132.64964 | CE3: 101.60658 | CF3: 18.479057 | CG3: 51.141739 | CH3: 110.6478 | CI3: 17.469999 | CJ3: 169.27206 | CK3: 4.2199998 | CL3: 84.82 | CM3: 6.0987191 | CN3: 21.784798 | CO3: 80.513542 | CP3: 9.04 | CQ3: 118.92626 | CR3: 58.451004 | CS3: 89.914124 | CT3: 18.68 | CU3: 19.83 | CV3: 62.634998 | CW3: 29.974335 | CX3: 11.207469 | CY3: 29.84 | CZ3: 44.029999 | DA3: 5.04 | DB3: 8.5299997 | DC3: 85.269997 | DD3: 164.45259 | DE3: 73.694778 | DF3: 304.08575 | DG3: 346.45999 | DH3: 33.139999 | DI3: 58.078934 | DJ3: 251.68297 | DK3: 251.00723 | DL3: 22.33 | DM3: 20.27 | DN3: 129.489 | DO3: 56 | DP3: 126.2 | DQ3: 193.17781 | DR3: 70.940002 | DS3: 41.259998 | DT3: 265.34192 | DU3: 99.370003 | DV3: 3.01 | DW3: 13.2 | DX3: 13.81 | DY3: 29.34 | DZ3: 75.139999 | EA3: 17.369867 | EB3: 100.70169 | EC3: 62.400002 | ED3: 241.38751 | EE3: 107.65932 | EF3: 172.68834 | EG3: 16.059999 | EH3: 13.64395 | EI3: 64.982506 | EJ3: 63.901531 | EK3: 0.73000002 | EL3: 22.500477 | EM3: 6.6799998 | EN3: 57.52 | EO3: 232.62045 | EP3: 254.58 | EQ3: 22.450001 | ER3: 131.20386 | ES3: 4.21 | ET3: 10.36 | EU3: 16.541708 | EV3: 566.44012 | EW3: 1.53 | EX3: 17.709999 | EY3: 76.47538 | EZ3: 63.058361 | FA3: 91.969635 | FB3: 753.44043 | FC3: 60.760696 | FD3: 6.9973578 | FE3: 32.766541 | FF3: 77.679047 | FG3: 25.790001 | FH3: 74.461357 | FI3: 157.19644 | FJ3: 505.07443 | FK3: 327.78 | FL3: 10.63 | FM3: 70.29966 | FN3: 83.88324 | FO3: 4.9290023 | FP3: 121.847 | FQ3: 7.73 | FR3: 1.5599999 | FS3: 121.31686 | FT3: 16.15 | FU3: 178.00352 | FV3: 70.559998 | FW3: 142.64999 | FX3: 7.0900002 | FY3: 11.74 | FZ3: 2.3213007 | GA3: 88.290001 | GB3: 203.25 | GC3: 27.57 | GD3: 182.55 | GE3: 158.04614 | GF3: 197.42357 | GG3: 40.639999 | GH3: 18.950001 | GI3: 27.52 | GJ3: 18.360001 | GK3: 596.02289 | GL3: 21.405001 | GM3: 12.910962 | GN3: 132.22 | GO3: 237.45 | GP3: 9.2200003 | GQ3: 10.53 | GR3: 190.2778 | GS3: 31.459999 | GT3: 3.54 | GU3: 17.07 | GV3: 52.91 | GW3: 99 | GX3: 98.510002 | GY3: 144.4776 | GZ3: 158.19199 | HA3: 4.8099999 | HB3: 15.67 | HC3: 83.557693 | HD3: 92.724861 | HE3: 35.419998 | HF3: 6.0999999 | HG3: 68.973953 | HH3: 61.290001 | HI3: 8.4200001 | HJ3: 29.09 | HK3: 29.76 | HL3: 18.049999 | HM3: 656.13129 | HN3: 11.69 | HO3: 41.452122 | HP3: 46.830002 | HQ3: 6.1199999 | HR3: 1.76 | HS3: 17.002316 | HT3: 39.75 | HU3: 8.3699999 | HV3: 45.959957 | HW3: 29.419605 | HX3: 22.672035 | HY3: 234.53543 | HZ3: 114.66342 | IA3: 425.85001 | IB3: 46.860001 | IC3: 103.43 | ID3: 104.13 | IE3: 97.800003 | IF3: 41.021759 | IG3: 109.58101 | IH3: 6.1700001 | II3: 72.050003 | IJ3: 17.85 | IK3: 5.7678514 | IL3: 4.9000001 | IM3: 166.85239 | IN3: 10.914948 | IO3: 12.91 | IP3: 40.578152 | IQ3: 19.559999 | IR3: 82.569443 | IS3: 32.465569 | IT3: 101.66403 | IU3: 2.5599999 | IV3: 14.562538 | IW3: 11.24 | IX3: 43.611591 | IY3: 139.55768 | IZ3: 135.20477 | JA3: 54.209999 | JB3: 21.190001 | JC3: 76.540001 | JD3: 31.379999 | JE3: 146.59323 | JF3: 55.593163 | JG3: 82.580002 | JH3: 41 | JI3: 139.92265
A4: 2025-09-24 | B4: 30.98531 | D4: 11.94 | E4: 26.690001 | F4: 59.848003 | G4: 251.38139 | H4: 34.622257 | I4: 123.08 | J4: 130.86522 | K4: 21.26 | L4: 9.71 | M4: 59.734684 | N4: 17.421652 | O4: 107.07152 | P4: 81.529999 | Q4: 11.387647 | R4: 106.14944 | S4: 2.95 | T4: 76.230003 | U4: 10.75 | V4: 160.88 | W4: 237.20854 | X4: 22.26 | Y4: 29.156767 | Z4: 59.610001 | AA4: 220.21001 | AB4: 142.64 | AC4: 16.59 | AD4: 3.8800001 | AE4: 61.232925 | AF4: 5.3400002 | AG4: 32.040001 | AH4: 42.119999 | AI4: 11.919006 | AJ4: 11.425069 | AK4: 15.21 | AL4: 17.389999 | AM4: 50.620964 | AN4: 16.301964 | AO4: 70.419586 | AP4: 23.59 | AQ4: 18.870775 | AR4: 9.4332466 | AS4: 25.139999 | AT4: 51.14782 | AU4: 42.137459 | AV4: 49.181049 | AW4: 2.5799999 | AX4: 17.52 | AY4: 99.544167 | AZ4: 152.98892 | BA4: 13.626678 | BB4: 89.120659 | BC4: 82.928528 | BD4: 29.889683 | BE4: 29.459999 | BF4: 89.791687 | BG4: 14.45 | BH4: 33.281559 | BI4: 28.256269 | BJ4: 254.55019 | BK4: 106.52 | BL4: 321.76999 | BM4: 7.9299998 | BN4: 92.70726 | BO4: 939.7868 | BP4: 2.3728743 | BQ4: 149.38 | BR4: 6.6999998 | BS4: 11.66 | BT4: 65.954323 | BU4: 44.312519 | BV4: 33.390793 | BW4: 74.961998 | BX4: 74.030289 | BY4: 510.53482 | BZ4: 57.085484 | CA4: 260.73999 | CB4: 11.03 | CC4: 136.57001 | CD4: 130.42795 | CE4: 102.42005 | CF4: 18.354261 | CG4: 51.529095 | CH4: 111.81096 | CI4: 17 | CJ4: 167.21109 | CK4: 4.2600002 | CL4: 84.010002 | CM4: 5.6798506 | CN4: 22.042099 | CO4: 80.310349 | CP4: 8.7399998 | CQ4: 119.44794 | CR4: 58.322144 | CS4: 92.185181 | CT4: 19.129999 | CU4: 19.93 | CV4: 64.050003 | CW4: 29.715935 | CX4: 11.111923 | CY4: 29.25 | CZ4: 43.75 | DA4: 4.8499999 | DB4: 8.4200001 | DC4: 83.599998 | DD4: 173.6747 | DE4: 71.798546 | DF4: 298.78265 | DG4: 343.32001 | DH4: 34.290001 | DI4: 59.407463 | DJ4: 247.18471 | DK4: 246.49895 | DL4: 22.66 | DM4: 19.200001 | DN4: 129.52831 | DO4: 53.25 | DP4: 126.8 | DQ4: 189.8248 | DR4: 70.290001 | DS4: 41.82 | DT4: 260.75128 | DU4: 94.410004 | DV4: 3.2750001 | DW4: 13.6 | DX4: 14.19 | DY4: 31.219999 | DZ4: 73.860001 | EA4: 17.066164 | EB4: 97.934799 | EC4: 57 | ED4: 239.17006 | EE4: 105.91951 | EF4: 172.79593 | EG4: 16.469999 | EH4: 14.423886 | EI4: 64.72924 | EJ4: 64.097099 | EK4: 0.74000001 | EL4: 22.617413 | EM4: 6.8299999 | EN4: 53.43 | EO4: 234.30388 | EP4: 252.14992 | EQ4: 21.940001 | ER4: 127.86572 | ES4: 4.25 | ET4: 9.9899998 | EU4: 16.783123 | EV4: 565.28735 | EW4: 1.6 | EX4: 17.639999 | EY4: 75.990784 | EZ4: 64.169258 | FA4: 92.725067 | FB4: 758.68677 | FC4: 61.004219 | FD4: 7.2360129 | FE4: 34.657101 | FF4: 77.397316 | FG4: 25.879999 | FH4: 79.919724 | FI4: 154.38031 | FJ4: 505.98688 | FK4: 323.31 | FL4: 10.21 | FM4: 71.767487 | FN4: 82.694389 | FO4: 4.9883881 | FP4: 120.395 | FQ4: 7.6799998 | FR4: 1.59 | FS4: 121.13012 | FT4: 16.01 | FU4: 176.54703 | FV4: 72.760002 | FW4: 131.17 | FX4: 8.2299995 | FY4: 11.51 | FZ4: 2.2373984 | GA4: 84.849998 | GB4: 200.7 | GC4: 27.1 | GD4: 179.56 | GE4: 157.30307 | GF4: 197.57848 | GG4: 41.310001 | GH4: 18.860001 | GI4: 27.719999 | GJ4: 17.129999 | GK4: 593.93054 | GL4: 21.41 | GM4: 13.104979 | GN4: 133.13 | GO4: 235.69 | GP4: 9.3500004 | GQ4: 10.09 | GR4: 187.83888 | GS4: 31.639999 | GT4: 3.6400001 | GU4: 17.99 | GV4: 48.689999 | GW4: 98.209999 | GX4: 93.370003 | GY4: 148.19664 | GZ4: 159.0197 | HA4: 4.8800001 | HB4: 15.51 | HC4: 82.173027 | HD4: 91.204292 | HE4: 35 | HF4: 6.5500002 | HG4: 69.533157 | HH4: 59.830002 | HI4: 8.2200003 | HJ4: 28.440001 | HK4: 29.34 | HL4: 17.780001 | HM4: 654.0437 | HN4: 11.66 | HO4: 41.540279 | HP4: 47.099998 | HQ4: 6.3099999 | HR4: 1.795 | HS4: 16.95286 | HT4: 39.48 | HU4: 8.3999996 | HV4: 43.162872 | HW4: 28.552858 | HX4: 23.081066 | HY4: 233.46799 | HZ4: 111.97801 | IA4: 442.79001 | IB4: 46.869999 | IC4: 103.24 | ID4: 101.39 | IE4: 97.779999 | IF4: 40.485588 | IG4: 108.44533 | IH4: 6.1599998 | II4: 71.199997 | IJ4: 16.66 | IK4: 6.0036178 | IL4: 4.8099999 | IM4: 167.28328 | IN4: 10.886124 | IO4: 12.88 | IP4: 40.419022 | IQ4: 19.82 | IR4: 82.31498 | IS4: 32.587402 | IT4: 101.87228 | IU4: 2.3800001 | IV4: 14.244882 | IW4: 11.4 | IX4: 44.178867 | IY4: 138.69606 | IZ4: 134.66173 | JA4: 54.130001 | JB4: 21.27 | JC4: 76.489998 | JD4: 31.440001 | JE4: 146.60303 | JF4: 55.224419 | JG4: 83.010002 | JH4: 34.25 | JI4: 139.00038
A5: 2025-09-25 | B5: 31.203587 | D5: 11.39 | E5: 26.34 | F5: 58.652023 | G5: 255.92462 | H5: 34.832699 | I5: 121.75 | J5: 130.29831 | K5: 21.209999 | L5: 9.3299999 | M5: 59.33633 | N5: 17.324324 | O5: 107.23804 | P5: 77.940002 | Q5: 11.647138 | R5: 106.87187 | S5: 2.8900001 | T5: 75.379997 | U5: 9.3599997 | V5: 161.27 | W5: 237.62849 | X5: 21.629999 | Y5: 28.958153 | Z5: 57.959999 | AA5: 218.14999 | AB5: 143.06 | AC5: 16.65 | AD5: 3.8 | AE5: 60.835087 | AF5: 5.2600002 | AG5: 28.799999 | AH5: 38.450001 | AI5: 12.096147 | AJ5: 11.345865 | AK5: 15.39 | AL5: 16.92 | AM5: 50.767834 | AN5: 16.204407 | AO5: 70.438591 | AP5: 23.09 | AQ5: 18.998415 | AR5: 9.5126009 | AS5: 23.91 | AT5: 47.352554 | AU5: 41.42181 | AV5: 49.181049 | AW5: 2.8199999 | AX5: 16.57 | AY5: 99.994637 | AZ5: 147.42677 | BA5: 13.010839 | BB5: 89.377449 | BC5: 85.493538 | BD5: 29.997944 | BE5: 28.969999 | BF5: 87.891022 | BG5: 13.68 | BH5: 33.528675 | BI5: 28.265209 | BJ5: 258.68951 | BK5: 106.57 | BL5: 306.69 | BM5: 7.9499998 | BN5: 93.851196 | BO5: 937.8382 | BP5: 2.3496108 | BQ5: 144.94 | BR5: 7.02 | BS5: 11.1 | BT5: 66.473564 | BU5: 44.045284 | BV5: 33.351299 | BW5: 74.276001 | BX5: 72.314735 | BY5: 515.91632 | BZ5: 56.12598 | CA5: 262.07999 | CB5: 10.86 | CC5: 136.60001 | CD5: 129.31218 | CE5: 100.8029 | CF5: 18.21987 | CG5: 52.303825 | CH5: 111.37724 | CI5: 16.82 | CJ5: 166.58893 | CK5: 4.4499998 | CL5: 81.309998 | CM5: 5.6212096 | CN5: 21.15584 | CO5: 78.56868 | CP5: 8.6300001 | CQ5: 118.17271 | CR5: 58.153637 | CS5: 91.938332 | CT5: 17.530001 | CU5: 20.139999 | CV5: 63.599998 | CW5: 29.26613 | CX5: 11.102368 | CY5: 29.809999 | CZ5: 42.400002 | DA5: 4.7199998 | DB5: 8.5600004 | DC5: 83.209999 | DD5: 176.31238 | DE5: 72.602699 | DF5: 295.67844 | DG5: 344.75 | DH5: 32.115002 | DI5: 60.071732 | DJ5: 245.92799 | DK5: 245.15244 | DL5: 22.559999 | DM5: 18.780001 | DN5: 129.25322 | DO5: 54.869999 | DP5: 122.65 | DQ5: 189.45557 | DR5: 70.580002 | DS5: 41.259998 | DT5: 274.30881 | DU5: 92.190002 | DV5: 3.26 | DW5: 12.8 | DX5: 14.09 | DY5: 33.990002 | DZ5: 69.43 | EA5: 17.075962 | EB5: 97.518791 | EC5: 53.200001 | ED5: 236.88327 | EE5: 105.15398 | EF5: 173.81299 | EG5: 17.469999 | EH5: 14.66083 | EI5: 64.271423 | EJ5: 64.038422 | EK5: 0.70999998 | EL5: 22.227625 | EM5: 6.9699998 | EN5: 52.459999 | EO5: 235.30403 | EP5: 250.38615 | EQ5: 22.450001 | ER5: 127.67639 | ES5: 4.1599998 | ET5: 10.1 | EU5: 16.493425 | EV5: 563.78668 | EW5: 1.5700001 | EX5: 16.07 | EY5: 75.179855 | EZ5: 63.185043 | FA5: 91.330421 | FB5: 746.96722 | FC5: 61.060429 | FD5: 7.0641813 | FE5: 33.557491 | FF5: 75.38636 | FG5: 24.610001 | FH5: 83.631821 | FI5: 155.42657 | FJ5: 502.89236 | FK5: 300.70001 | FL5: 10.01 | FM5: 72.564575 | FN5: 82.892532 | FO5: 4.9487977 | FP5: 120.824 | FQ5: 7.9400001 | FR5: 1.58 | FS5: 118.7026 | FT5: 15.78 | FU5: 177.2653 | FV5: 73.510002 | FW5: 119.13 | FX5: 9.0900002 | FY5: 12.24 | FZ5: 2.2373984 | GA5: 83.470001 | GB5: 202.21001 | GC5: 26.540001 | GD5: 179.12 | GE5: 158.26811 | GF5: 196.28119 | GG5: 40.84 | GH5: 19 | GI5: 26.34 | GJ5: 17.07 | GK5: 591.37 | GL5: 20.58 | GM5: 12.972693 | GN5: 132.03999 | GO5: 232.75 | GP5: 8.96 | GQ5: 10.09 | GR5: 191.45764 | GS5: 32.099998 | GT5: 3.1600001 | GU5: 16.74 | GV5: 46.630001 | GW5: 98.010002 | GX5: 91.269997 | GY5: 148.22643 | GZ5: 158.16241 | HA5: 4.6300001 | HB5: 15.51 | HC5: 81.74398 | HD5: 93.583878 | HE5: 35 | HF5: 7.1999998 | HG5: 70.275543 | HH5: 61.630001 | HI5: 8.3299999 | HJ5: 28.120001 | HK5: 29.83 | HL5: 16.35 | HM5: 651.02631 | HN5: 11.59 | HO5: 41.824333 | HP5: 47.18 | HQ5: 5.8200002 | HR5: 1.71 | HS5: 16.863842 | HT5: 39.009998 | HU5: 7.9499998 | HV5: 43.693035 | HW5: 28.244017 | HX5: 22.944721 | HY5: 233.01749 | HZ5: 106.42947 | IA5: 423.39001 | IB5: 46.759998 | IC5: 101.33 | ID5: 99.150002 | IE5: 97.599998 | IF5: 39.461994 | IG5: 106.89668 | IH5: 5.2800002 | II5: 71.260002 | IJ5: 18.190001 | IK5: 5.3299999 | IL5: 4.75 | IM5: 170.79871 | IN5: 10.828474 | IO5: 12.59 | IP5: 40.578152 | IQ5: 19.780001 | IR5: 82.5205 | IS5: 32.446075 | IT5: 102.18961 | IU5: 2.28 | IV5: 14.036421 | IW5: 10.97 | IX5: 44.574986 | IY5: 138.45204 | IZ5: 132.43039 | JA5: 55.02 | JB5: 22.25 | JC5: 73.68 | JD5: 31.299999 | JE5: 147.54477 | JF5: 55.602871 | JG5: 83.989998 | JH5: 28.25 | JI5: 138.47057
A6: 2025-09-26 | B6: 32.453712 | D6: 11.31 | E6: 25.77 | F6: 59.798985 | G6: 254.51981 | H6: 34.677155 | I6: 123.7 | J6: 130.5329 | K6: 21.049999 | L6: 9.2799997 | M6: 58.879665 | N6: 17.470316 | O6: 109.07954 | P6: 76.029999 | Q6: 12.116218 | R6: 108.64334 | S6: 2.8599999 | T6: 76.050003 | U6: 9.79 | V6: 159.46001 | W6: 239.0083 | X6: 22.049999 | Y6: 28.829052 | Z6: 58.57 | AA6: 219.78 | AB6: 142.5 | AC6: 16.74 | AD6: 3.95 | AE6: 60.969353 | AF6: 5.4000001 | AG6: 27 | AH6: 36.450001 | AI6: 12.290156 | AJ6: 11.058754 | AK6: 15.02 | AL6: 17.16 | AM6: 51.120319 | AN6: 16.272697 | AO6: 72.299469 | AP6: 22.969999 | AQ6: 19.096598 | AR6: 9.3935709 | AS6: 23.48 | AT6: 47.084873 | AU6: 42.099293 | AV6: 48.214603 | AW6: 2.7 | AX6: 16.25 | AY6: 101.27749 | AZ6: 152.12788 | BA6: 13.343196 | BB6: 90.642296 | BC6: 85.413696 | BD6: 30.135729 | BE6: 29.389999 | BF6: 90.261963 | BG6: 12.96 | BH6: 36.177757 | BI6: 28.354603 | BJ6: 260.18158 | BK6: 106.99 | BL6: 312.59 | BM6: 7.9499998 | BN6: 95.470161 | BO6: 910.63684 | BP6: 2.3961377 | BQ6: 142.92999 | BR6: 6.4899998 | BS6: 11.92 | BT6: 65.856354 | BU6: 44.649052 | BV6: 33.578381 | BW6: 73.858002 | BX6: 73.439049 | BY6: 525.57562 | BZ6: 56.581005 | CA6: 262.47 | CB6: 10.745 | CC6: 139.07001 | CD6: 129.11469 | CE6: 100.08744 | CF6: 18.661448 | CG6: 51.577518 | CH6: 111.85039 | CI6: 16.93 | CJ6: 166.68613 | CK6: 4.4099998 | CL6: 81.519997 | CM6: 5.7301149 | CN6: 21.880093 | CO6: 78.984741 | CP6: 8.4899998 | CQ6: 118.84898 | CR6: 58.41135 | CS6: 89.993118 | CT6: 16.6 | CU6: 21.27 | CV6: 64.18 | CW6: 29.409683 | CX6: 11.474997 | CY6: 30.110001 | CZ6: 42.169998 | DA6: 4.77 | DB6: 8.6700001 | DC6: 84.32 | DD6: 170.12167 | DE6: 74.141533 | DF6: 293.48953 | DG6: 346.73999 | DH6: 30.9 | DI6: 60.716175 | DJ6: 246.53639 | DK6: 245.90048 | DL6: 22.74 | DM6: 19.9 | DN6: 130.7661 | DO6: 58.400002 | DP6: 121.78 | DQ6: 192.7487 | DR6: 70.989998 | DS6: 41.009998 | DT6: 277.10611 | DU6: 91.690002 | DV6: 3.3299999 | DW6: 11.2 | DX6: 14.41 | DY6: 35.5 | DZ6: 67.279999 | EA6: 17.291491 | EB6: 97.644554 | EC6: 46.799999 | ED6: 238.91264 | EE6: 106.38677 | EF6: 175.74936 | EG6: 15.64 | EH6: 14.720065 | EI6: 63.969448 | EJ6: 64.009094 | EK6: 0.727 | EL6: 22.432264 | EM6: 7 | EN6: 51.43 | EO6: 236.10612 | EP6: 251.94417 | EQ6: 21.799999 | ER6: 127.87569 | ES6: 4.1599998 | ET6: 10.08 | EU6: 17.38183 | EV6: 561.63019 | EW6: 1.62 | EX6: 16.129999 | EY6: 75.486427 | EZ6: 62.775761 | FA6: 91.945213 | FB6: 741.82062 | FC6: 61.547482 | FD6: 7.035543 | FE6: 34.068718 | FF6: 76.318977 | FG6: 24.49 | FH6: 82.993172 | FI6: 156.56087 | FJ6: 507.28619 | FK6: 309.06 | FL6: 10.1 | FM6: 73.731041 | FN6: 84.457848 | FO6: 4.9487977 | FP6: 121.061 | FQ6: 8.3000002 | FR6: 1.59 | FS6: 117.81808 | FT6: 15.78 | FU6: 177.7641 | FV6: 73.07 | FW6: 110.53 | FX6: 8.8100004 | FY6: 12.1 | FZ6: 2.246721 | GA6: 82.400002 | GB6: 202.37 | GC6: 26.200001 | GD6: 177.57001 | GE6: 159.12701 | GF6: 196.84268 | GG6: 40.529999 | GH6: 21.16 | GI6: 26.76 | GJ6: 16.32 | GK6: 593.80096 | GL6: 20.145 | GM6: 13.422461 | GN6: 135.06 | GO6: 240.11 | GP6: 8.8299999 | GQ6: 10.37 | GR6: 195.02684 | GS6: 31.18 | GT6: 3.1900001 | GU6: 17.690001 | GV6: 46.259998 | GW6: 99.599998 | GX6: 92.57 | GY6: 150.26942 | GZ6: 160.96089 | HA6: 4.7199998 | HB6: 15.98 | HC6: 81.314919 | HD6: 94.255302 | HE6: 33.669998 | HF6: 7.0300002 | HG6: 70.76725 | HH6: 62.970001 | HI6: 8.2700005 | HJ6: 27.98 | HK6: 29.780001 | HL6: 15.94 | HM6: 654.7561 | HN6: 11.62 | HO6: 41.745972 | HP6: 47.029999 | HQ6: 5.4000001 | HR6: 1.6799999 | HS6: 16.972643 | HT6: 39.41 | HU6: 8.1599998 | HV6: 44.08609 | HW6: 28.283867 | HX6: 23.012894 | HY6: 232.55721 | HZ6: 107.66358 | IA6: 440.39999 | IB6: 47.139999 | IC6: 102.34 | ID6: 97.910004 | IE6: 98.449997 | IF6: 39.744701 | IG6: 108.62402 | IH6: 5.2150002 | II6: 73 | IJ6: 17.325001 | IK6: 4.23 | IL6: 4.79 | IM6: 171.98361 | IN6: 10.991814 | IO6: 12.6 | IP6: 40.821526 | IQ6: 19.51 | IR6: 83.195786 | IS6: 32.455822 | IT6: 102.2987 | IU6: 2.3499999 | IV6: 13.798178 | IW6: 10.83 | IX6: 44.985764 | IY6: 138.87039 | IZ6: 133.78302 | JA6: 55.860001 | JB6: 22.790001 | JC6: 73.669998 | JD6: 31.48 | JE6: 149.79112 | JF6: 55.835762 | JG6: 84.510002 | JH6: 25 | JI6: 140.79588
A7: 2025-09-29 | B7: 33.584782 | D7: 11.38 | E7: 25.940001 | F7: 61.710598 | G7: 253.49361 | H7: 34.658859 | I7: 122.92 | J7: 130.10281 | K7: 21.32 | L7: 9.6499996 | M7: 58.5979 | N7: 16.779287 | O7: 109.06975 | P7: 76.559998 | Q7: 12.385688 | R7: 106.78281 | S7: 2.9000001 | T7: 76.230003 | U7: 9.6199999 | V7: 161.36 | W7: 238.69833 | X7: 22.26 | Y7: 28.322582 | Z7: 60.84 | AA7: 222.17 | AB7: 143.37 | AC7: 16.52 | AD7: 4.0100002 | AE7: 60.178642 | AF7: 5.9400001 | AG7: 25.92 | AH7: 35.299999 | AI7: 12.374511 | AJ7: 11.019152 | AK7: 14.75 | AL7: 17.26 | AM7: 51.325935 | AN7: 16.262943 | AO7: 71.834251 | AP7: 23.91 | AQ7: 19.842787 | AR7: 9.5126009 | AS7: 25.120001 | AT7: 51.74358 | AU7: 42.127926 | AV7: 48.309483 | AW7: 2.6199999 | AX7: 17.309999 | AY7: 101.02288 | AZ7: 152.97903 | BA7: 12.756683 | BB7: 91.47921 | BC7: 84.295868 | BD7: 28.935022 | BE7: 29.459999 | BF7: 88.674805 | BG7: 14.87 | BH7: 36.11845 | BI7: 28.149002 | BJ7: 262.06839 | BK7: 107.97 | BL7: 333.98999 | BM7: 8.2200003 | BN7: 92.920532 | BO7: 911.55151 | BP7: 2.4504192 | BQ7: 146.00999 | BR7: 6.5 | BS7: 12.04 | BT7: 66.346214 | BU7: 44.658947 | BV7: 35.375282 | BW7: 78.531998 | BX7: 73.245201 | BY7: 530.09058 | BZ7: 57.036018 | CA7: 272.5 | CB7: 10.9 | CC7: 145.25999 | CD7: 132.21518 | CE7: 100.89111 | CF7: 18.450256 | CG7: 50.822163 | CH7: 113.14169 | CI7: 16.91 | CJ7: 165.37372 | CK7: 3.8 | CL7: 82.139999 | CM7: 6.0735869 | CN7: 21.813387 | CO7: 78.820244 | CP7: 8.6300001 | CQ7: 118.63644 | CR7: 58.510468 | CS7: 90.022736 | CT7: 16.16 | CU7: 22.48 | CV7: 74.339996 | CW7: 29.658512 | CX7: 11.551432 | CY7: 32.09 | CZ7: 42.639999 | DA7: 4.8600001 | DB7: 8.6800003 | DC7: 84.650002 | DD7: 170.90904 | DE7: 75.174034 | DF7: 292.50333 | DG7: 352.45999 | DH7: 34.290001 | DI7: 60.597202 | DJ7: 243.72375 | DK7: 243.41695 | DL7: 23.25 | DM7: 19.469999 | DN7: 129.92125 | DO7: 59.119999 | DP7: 136.72 | DQ7: 191.52126 | DR7: 72.160004 | DS7: 40.900002 | DT7: 272.71036 | DU7: 91.870003 | DV7: 3.23 | DW7: 11.4 | DX7: 14.81 | DY7: 34.48 | DZ7: 64.260002 | EA7: 16.92901 | EB7: 97.083427 | EC7: 47.599998 | ED7: 239.18982 | EE7: 107.53008 | EF7: 177.61726 | EG7: 15.24 | EH7: 14.344906 | EI7: 64.329865 | EJ7: 64.957596 | EK7: 0.72000003 | EL7: 22.69537 | EM7: 6.96 | EN7: 54.369999 | EO7: 233.16508 | EP7: 248.22066 | EQ7: 22.799999 | ER7: 130.6259 | ES7: 4.0999999 | ET7: 10.26 | EU7: 17.545992 | EV7: 564.62158 | EW7: 1.6 | EX7: 18.66 | EY7: 74.60627 | EZ7: 62.434696 | FA7: 91.701248 | FB7: 741.47156 | FC7: 61.510017 | FD7: 7.1214585 | FE7: 33.470676 | FF7: 76.338409 | FG7: 25.33 | FH7: 82.214836 | FI7: 157.58759 | FJ7: 510.40054 | FK7: 326.42001 | FL7: 10.28 | FM7: 74.080986 | FN7: 83.754448 | FO7: 4.9487977 | FP7: 120.641 | FQ7: 8.4799995 | FR7: 1.59 | FS7: 116.53062 | FT7: 15.95 | FU7: 181.41537 | FV7: 76.129997 | FW7: 116.51 | FX7: 8.1999998 | FY7: 11.91 | FZ7: 2.5170732 | GA7: 82.910004 | GB7: 203.96001 | GC7: 26.139999 | GD7: 178.86 | GE7: 157.29343 | GF7: 195.41953 | GG7: 40.220001 | GH7: 20.6 | GI7: 25.309999 | GJ7: 16.190001 | GK7: 596.55096 | GL7: 18.85 | GM7: 12.840409 | GN7: 141.56 | GO7: 241.98 | GP7: 8.9300003 | GQ7: 10.74 | GR7: 196.80151 | GS7: 29.65 | GT7: 3.1099999 | GU7: 19.780001 | GV7: 47.009998 | GW7: 100.08 | GX7: 91.5 | GY7: 150.6066 | GZ7: 161.23679 | HA7: 4.9099998 | HB7: 16.35 | HC7: 83.508934 | HD7: 95.667244 | HE7: 31.219999 | HF7: 6.8000002 | HG7: 69.851311 | HH7: 61.98 | HI7: 8.3999996 | HJ7: 27.549999 | HK7: 29.1 | HL7: 15.68 | HM7: 656.59625 | HN7: 11.31 | HO7: 41.109303 | HP7: 47.599998 | HQ7: 5.3499999 | HR7: 1.58 | HS7: 17.012207 | HT7: 38.349998 | HU7: 8.1999998 | HV7: 43.976398 | HW7: 28.622597 | HX7: 23.110283 | HY7: 233.03708 | HZ7: 110.04294 | IA7: 443.20999 | IB7: 49.639999 | IC7: 104.29 | ID7: 98.639999 | IE7: 99.57 | IF7: 40.290623 | IG7: 109.51748 | IH7: 5.6199999 | II7: 72.25 | IJ7: 17.540001 | IK7: 4.2800002 | IL7: 4.5900002 | IM7: 168.56607 | IN7: 11.039854 | IO7: 12.87 | IP7: 40.484547 | IQ7: 18.860001 | IR7: 82.84346 | IS7: 32.933399 | IT7: 102.21936 | IU7: 2.28 | IV7: 13.778326 | IW7: 11.6 | IX7: 44.159309 | IY7: 139.61246 | IZ7: 134.17793 | JA7: 55.91 | JB7: 23.190001 | JC7: 75.389999 | JD7: 31.370001 | JE7: 151.00751 | JF7: 55.311756 | JG7: 83.599998 | JH7: 27.5 | JI7: 140.3642
A8: 2025-09-30 | B8: 32.632305 | D8: 11.24 | E8: 25.93 | F8: 60.191113 | G8: 253.69289 | H8: 34.969948 | I8: 121.42 | J8: 130.91409 | K8: 21.34 | L8: 9.5799999 | M8: 58.044083 | N8: 16.652761 | O8: 109.41257 | P8: 73.080002 | Q8: 12.265923 | R8: 105.9614 | S8: 2.9100001 | T8: 75.760002 | U8: 9.8000002 | V8: 161.78999 | W8: 238.39838 | X8: 22.68 | Y8: 28.203413 | Z8: 59.389999 | AA8: 219.57001 | AB8: 145.71001 | AC8: 16.26 | AD8: 4.02 | AE8: 61.541256 | AF8: 6.4000001 | AG8: 26.1 | AH8: 38.75 | AI8: 12.60226 | AJ8: 10.97955 | AK8: 14.54 | AL8: 17.84 | AM8: 50.51326 | AN8: 16.145872 | AO8: 71.796272 | AP8: 24.27 | AQ8: 18.654774 | AR8: 9.3836498 | AS8: 25.07 | AT8: 51.734192 | AU8: 43.034409 | AV8: 48.583351 | AW8: 2.5599999 | AX8: 17.09 | AY8: 99.397263 | AZ8: 155.34442 | BA8: 12.746907 | BB8: 91.764519 | BC8: 83.697037 | BD8: 28.452774 | BE8: 29.370001 | BF8: 87.881233 | BG8: 14.5 | BH8: 35.792259 | BI8: 28.08643 | BJ8: 260.095 | BK8: 107.72 | BL8: 337.48999 | BM8: 8.0299997 | BN8: 91.699043 | BO8: 920.26068 | BP8: 2.4194012 | BQ8: 145.61 | BR8: 6.2199998 | BS8: 12.46 | BT8: 67.032005 | BU8: 44.084877 | BV8: 35.059345 | BW8: 75.447998 | BX8: 73.070747 | BY8: 542.33698 | BZ8: 56.135868 | CA8: 271.98999 | CB8: 10.75 | CC8: 142.39999 | CD8: 139.98616 | CE8: 101.29295 | CF8: 18.613449 | CG8: 50.686584 | CH8: 112.86568 | CI8: 16.42 | CJ8: 168.06659 | CK8: 3.72 | CL8: 72.089996 | CM8: 5.9395494 | CN8: 21.851507 | CO8: 79.908096 | CP8: 8.6300001 | CQ8: 119.55422 | CR8: 58.678974 | CS8: 89.805511 | CT8: 15.56 | CU8: 21.73 | CV8: 66.389999 | CW8: 29.668083 | CX8: 11.427223 | CY8: 33.91 | CZ8: 42.07 | DA8: 4.5999999 | DB8: 8.96 | DC8: 84.080002 | DD8: 171.16495 | DE8: 75.849129 | DF8: 299.66577 | DG8: 355.47 | DH8: 33.810001 | DI8: 60.448483 | DJ8: 242.91586 | DK8: 242.46942 | DL8: 23.35 | DM8: 18.459999 | DN8: 131.04117 | DO8: 56.720001 | DP8: 143.17999 | DQ8: 195.82231 | DR8: 72.769997 | DS8: 40.52 | DT8: 275.01059 | DU8: 94.970001 | DV8: 3.3199999 | DW8: 10.2 | DX8: 14.97 | DY8: 33.549999 | DZ8: 61.5 | EA8: 17.10535 | EB8: 98.621681 | EC8: 51.599998 | ED8: 239.52643 | EE8: 109.30964 | EF8: 181.33351 | EG8: 14.92 | EH8: 14.512741 | EI8: 64.602615 | EJ8: 65.915871 | EK8: 0.73199999 | EL8: 22.705114 | EM8: 6.9000001 | EN8: 53.529999 | EO8: 232.68976 | EP8: 246.25111 | EQ8: 22.74 | ER8: 133.42595 | ES8: 4.1500001 | ET8: 10.52 | EU8: 17.314236 | EV8: 565.28735 | EW8: 1.54 | EX8: 18.26 | EY8: 73.993118 | EZ8: 62.580872 | FA8: 92.940575 | FB8: 732.47498 | FC8: 61.875305 | FD8: 7.0832739 | FE8: 33.451385 | FF8: 81.535789 | FG8: 25.83 | FH8: 83.891258 | FI8: 155.43636 | FJ8: 513.72327 | FK8: 322.20999 | FL8: 10.63 | FM8: 73.381104 | FN8: 83.526588 | FO8: 4.9388995 | FP8: 119.892 | FQ8: 8.8000002 | FR8: 1.5700001 | FS8: 116.42251 | FT8: 16.01 | FU8: 186.13406 | FV8: 73.989998 | FW8: 111.63 | FX8: 7.9699998 | FY8: 11.33 | FZ8: 2.4611382 | GA8: 83.809998 | GB8: 203.62 | GC8: 26.280001 | GD8: 182.42 | GE8: 156.53102 | GF8: 194.52882 | GG8: 40.720001 | GH8: 20.23 | GI8: 24.709999 | GJ8: 16.4 | GK8: 598.18506 | GL8: 18.41 | GM8: 12.787495 | GN8: 138.52 | GO8: 229.99001 | GP8: 8.9899998 | GQ8: 10.63 | GR8: 198.86372 | GS8: 29.790001 | GT8: 3.1199999 | GU8: 19.030001 | GV8: 47.91 | GW8: 100.13 | GX8: 89.510002 | GY8: 151.13223 | GZ8: 164.88268 | HA8: 4.8800001 | HB8: 16.280001 | HC8: 82.494812 | HD8: 94.265167 | HE8: 30.870001 | HF8: 6.4099998 | HG8: 68.964317 | HH8: 71.449997 | HI8: 7.71 | HJ8: 26.42 | HK8: 28.790001 | HL8: 16.08 | HM8: 659.06952 | HN8: 11.2 | HO8: 40.952587 | HP8: 47.790001 | HQ8: 4.9499998 | HR8: 1.66 | HS8: 17.081442 | HT8: 37.970001 | HU8: 7.73 | HV8: 44.369453 | HW8: 28.831812 | HX8: 22.730467 | HY8: 234.4277 | HZ8: 111.78056 | IA8: 444.72 | IB8: 49.009998 | IC8: 100.09 | ID8: 96.5 | IE8: 97.970001 | IF8: 39.968918 | IG8: 110.67896 | IH8: 5.77 | II8: 71.43 | IJ8: 17.190001 | IK8: 3.99 | IL8: 4.8899999 | IM8: 166.72508 | IN8: 11.145545 | IO8: 12.55 | IP8: 41.139786 | IQ8: 19.530001 | IR8: 82.031174 | IS8: 33.196552 | IT8: 102.19952 | IU8: 2.1700001 | IV8: 13.798178 | IW8: 11.42 | IX8: 43.689838 | IY8: 140.37444 | IZ8: 137.40651 | JA8: 54.470001 | JB8: 23.42 | JC8: 72.269997 | JD8: 31.200001 | JE8: 149.10448 | JF8: 54.904198 | JG8: 82.5 | JH8: 24.5 | JI8: 143.56276
A9: 2025-10-01 | B9: 33.584782 | D9: 11.27 | E9: 28.42 | F9: 60.681267 | G9: 254.50984 | H9: 34.091579 | I9: 122.32 | J9: 130.45471 | K9: 21.24 | L9: 9.8100004 | M9: 57.567993 | N9: 16.526237 | O9: 108.48204 | P9: 74.419998 | Q9: 12.235982 | R9: 103.78419 | S9: 2.9400001 | T9: 75.839996 | U9: 10.29 | V9: 164.00999 | W9: 230.97935 | X9: 24.57 | Y9: 29.266006 | Z9: 59.169998 | AA9: 220.63 | AB9: 149.27 | AC9: 15.84 | AD9: 4.0700002 | AE9: 61.993805 | AF9: 6.5300002 | AG9: 25.02 | AH9: 41.200001 | AI9: 13.007154 | AJ9: 11.019152 | AK9: 13.97 | AL9: 17.870001 | AM9: 49.622253 | AN9: 16.204407 | AO9: 73.438797 | AP9: 24.129999 | AQ9: 18.949322 | AR9: 9.1852646 | AS9: 25.459999 | AT9: 54.523773 | AU9: 45.257698 | AV9: 48.583351 | AW9: 2.5699999 | AX9: 18 | AY9: 96.66507 | AZ9: 156.81496 | BA9: 12.952188 | BB9: 91.022713 | BC9: 83.327751 | BD9: 27.911472 | BE9: 28.83 | BF9: 84.677536 | BG9: 14.59 | BH9: 36.88945 | BI9: 27.95092 | BJ9: 255.90752 | BK9: 114.65 | BL9: 346.17001 | BM9: 7.6300001 | BN9: 92.542458 | BO9: 912.0188 | BP9: 2.4194012 | BQ9: 144.91 | BR9: 7.0900002 | BS9: 12.7 | BT9: 67.355309 | BU9: 43.916611 | BV9: 34.555817 | BW9: 79.082001 | BX9: 74.505211 | BY9: 541.72766 | BZ9: 55.5028 | CA9: 267.64001 | CB9: 10.75 | CC9: 152.7 | CD9: 147.79662 | CE9: 97.695999 | CF9: 18.479057 | CG9: 50.347641 | CH9: 111.33781 | CI9: 16.620001 | CJ9: 166.67639 | CK9: 3.52 | CL9: 68.970001 | CM9: 5.7636247 | CN9: 21.96586 | CO9: 79.148453 | CP9: 8.3500004 | CQ9: 118.24033 | CR9: 58.688885 | CS9: 86.477928 | CT9: 15.01 | CU9: 20.26 | CV9: 70.489998 | CW9: 29.26613 | CX9: 11.723413 | CY9: 34.25 | CZ9: 42.860001 | DA9: 4.5500002 | DB9: 8.8900003 | DC9: 85.18 | DD9: 173.64516 | DE9: 76.57386 | DF9: 299.72552 | DG9: 356.03 | DH9: 35.830002 | DI9: 60.815319 | DJ9: 244.90068 | DK9: 244.26474 | DL9: 22.290001 | DM9: 18.549999 | DN9: 130.55978 | DO9: 56.310001 | DP9: 139.14 | DQ9: 194.44518 | DR9: 72.879997 | DS9: 40.73 | DT9: 279.23087 | DU9: 102.26 | DV9: 3.29 | DW9: 10.4 | DX9: 15.76 | DY9: 35.939999 | DZ9: 63.09 | EA9: 17.281694 | EB9: 98.931267 | EC9: 49.200001 | ED9: 240.0511 | EE9: 108.25582 | EF9: 181.94963 | EG9: 15.09 | EH9: 14.295543 | EI9: 65.050697 | EJ9: 65.03582 | EK9: 0.76999998 | EL9: 23.777029 | EM9: 6.7800002 | EN9: 52.41 | EO9: 229.84773 | EP9: 242.99796 | EQ9: 22.049999 | ER9: 142.28448 | ES9: 4.1799998 | ET9: 10.61 | EU9: 17.343204 | EV9: 570.21674 | EW9: 1.66 | EX9: 18.610001 | EY9: 73.528313 | EZ9: 62.473679 | FA9: 92.520966 | FB9: 715.47913 | FC9: 62.09074 | FD9: 7.1310043 | FE9: 32.621853 | FF9: 87.558929 | FG9: 27.6 | FH9: 83.711647 | FI9: 153.41225 | FJ9: 515.46887 | FK9: 338.41 | FL9: 10.62 | FM9: 76.472267 | FN9: 85.151344 | FO9: 4.9487977 | FP9: 117.09 | FQ9: 10.12 | FR9: 1.53 | FS9: 116.46181 | FT9: 15.19 | FU9: 186.79248 | FV9: 75.620003 | FW9: 115.93 | FX9: 8.0600004 | FY9: 11.2 | FZ9: 2.3772357 | GA9: 85.690002 | GB9: 206.8 | GC9: 27.07 | GD9: 184.95 | GE9: 155.23785 | GF9: 192.11816 | GG9: 41.240002 | GH9: 20.67 | GI9: 25.629999 | GJ9: 16.530001 | GK9: 601.0545 | GL9: 18.969999 | GM9: 13.157892 | GN9: 134.07001 | GO9: 202.60001 | GP9: 9.1599998 | GQ9: 10.64 | GR9: 198.37791 | GS9: 29.85 | GT9: 3.23 | GU9: 18.93 | GV9: 47.970001 | GW9: 103.57 | GX9: 88.040001 | GY9: 151.93555 | GZ9: 164.75458 | HA9: 5.0999999 | HB9: 16.299999 | HC9: 82.299789 | HD9: 91.085815 | HE9: 31.024 | HF9: 6.8299999 | HG9: 69.832031 | HH9: 71.68 | HI9: 7.71 | HJ9: 25.76 | HK9: 28.74 | HL9: 16.15 | HM9: 661.31537 | HN9: 11.08 | HO9: 40.41386 | HP9: 48.040001 | HQ9: 4.6900001 | HR9: 1.7 | HS9: 17.140787 | HT9: 37.380001 | HU9: 7.8000002 | HV9: 43.555927 | HW9: 28.463194 | HX9: 22.516214 | HY9: 228.43431 | HZ9: 112.3828 | IA9: 459.45999 | IB9: 49.32 | IC9: 102.7 | ID9: 93.150002 | IE9: 96.610001 | IF9: 39.403503 | IG9: 111.88016 | IH9: 6.5300002 | II9: 73 | IJ9: 18.41 | IK9: 4.7800002 | IL9: 4.5700002 | IM9: 164.18887 | IN9: 11.078287 | IO9: 12.55 | IP9: 41.027458 | IQ9: 19.35 | IR9: 79.144127 | IS9: 33.37199 | IT9: 101.1087 | IU9: 2.3399999 | IV9: 13.470594 | IW9: 11.47 | IX9: 43.689838 | IY9: 141.74899 | IZ9: 141.65204 | JA9: 52.439999 | JB9: 23.700001 | JC9: 73.400002 | JD9: 31.459999 | JE9: 150.27179 | JF9: 54.807156 | JG9: 81.279999 | JH9: 22.424999 | JI9: 144.18089
A10: 2025-10-02 | B10: 34.557106 | D10: 11.43 | E10: 27.98 | F10: 60.916542 | G10: 256.18365 | H10: 34.375217 | I10: 121.49 | J10: 129.98557 | K10: 21.379999 | L10: 10.18 | M10: 57.431965 | N10: 16.497036 | O10: 108.33511 | P10: 77.43 | Q10: 12.036374 | R10: 106.30779 | S10: 3.03 | T10: 78.010002 | U10: 10.24 | V10: 169.73 | W10: 236.51863 | X10: 24.57 | Y10: 29.434832 | Z10: 59.25 | AA10: 222.41 | AB10: 144.46001 | AC10: 15.85 | AD10: 4.4099998 | AE10: 61.456715 | AF10: 6.4299998 | AG10: 26.1 | AH10: 48.59 | AI10: 13.091506 | AJ10: 11.038952 | AK10: 13.76 | AL10: 17.879999 | AM10: 49.42643 | AN10: 16.506838 | AO10: 72.745712 | AP10: 25.59 | AQ10: 18.605682 | AR10: 9.1654263 | AS10: 26.5 | AT10: 57.78299 | AU10: 43.635555 | AV10: 48.583351 | AW10: 2.6400001 | AX10: 17.610001 | AY10: 95.323448 | AZ10: 157.34123 | BA10: 13.225894 | BB10: 90.784958 | BC10: 84.036369 | BD10: 28.393723 | BE10: 28.43 | BF10: 88.018387 | BG10: 15.14 | BH10: 35.881218 | BI10: 27.463091 | BJ10: 255.5128 | BK10: 112.79 | BL10: 372.07001 | BM10: 7.5500002 | BN10: 90.526024 | BO10: 911.45209 | BP10: 2.512455 | BQ10: 149.63 | BR10: 8.1000004 | BS10: 13.3 | BT10: 66.924232 | BU10: 46.430656 | BV10: 35.118584 | BW10: 78.942001 | BX10: 75.06736 | BY10: 536.17383 | BZ10: 56.462303 | CA10: 270.09 | CB10: 10.65 | CC10: 151.57001 | CD10: 145.51569 | CE10: 99.38176 | CF10: 18.431061 | CG10: 50.202377 | CH10: 110.53938 | CI10: 17.200001 | CJ10: 168.91235 | CK10: 3.95 | CL10: 68.099998 | CM10: 5.6212096 | CN10: 22.575758 | CO10: 79.96653 | CP10: 8.3800001 | CQ10: 117.44814 | CR10: 58.74836 | CS10: 87.287598 | CT10: 15.62 | CU10: 19.799999 | CV10: 72.540001 | CW10: 28.940737 | CX10: 11.67564 | CY10: 35.689999 | CZ10: 43.470001 | DA10: 4.5799999 | DB10: 8.8900003 | DC10: 86.290001 | DD10: 163.62584 | DE10: 76.544075 | DF10: 298.30103 | DG10: 354.79001 | DH10: 36.52 | DI10: 58.852253 | DJ10: 245.78836 | DK10: 245.0527 | DL10: 22.5 | DM10: 18.709999 | DN10: 130.59911 | DO10: 57.869999 | DP10: 145.7 | DQ10: 190.68303 | DR10: 72.650002 | DS10: 39.509998 | DT10: 279.45505 | DU10: 99.300003 | DV10: 3.3399999 | DW10: 10.8 | DX10: 16.5 | DY10: 37.299999 | DZ10: 69.599998 | EA10: 18.261383 | EB10: 99.937416 | EC10: 51.200001 | ED10: 241.5657 | EE10: 108.02716 | EF10: 181.88118 | EG10: 15.61 | EH10: 14.611467 | EI10: 64.388306 | EJ10: 64.889137 | EK10: 0.78899997 | EL10: 23.757542 | EM10: 6.5100002 | EN10: 53.299999 | EO10: 229.53085 | EP10: 242.35123 | EQ10: 21.9 | ER10: 146.46962 | ES10: 4.25 | ET10: 11.22 | EU10: 17.565304 | EV10: 573.75464 | EW10: 1.8 | EX10: 18.790001 | EY10: 73.033836 | EZ10: 64.442116 | FA10: 93.174797 | FB10: 725.16394 | FC10: 61.584949 | FD10: 7.2169204 | FE10: 33.528553 | FF10: 86.956619 | FG10: 28.370001 | FH10: 86.016739 | FI10: 151.85748 | FJ10: 511.53125 | FK10: 352.32999 | FL10: 10.33 | FM10: 75.995964 | FN10: 85.626877 | FO10: 4.9586954 | FP10: 116.253 | FQ10: 9.6499996 | FR10: 1.5700001 | FS10: 118.00481 | FT10: 15.22 | FU10: 188.43854 | FV10: 79.360001 | FW10: 128.8 | FX10: 8.0100002 | FY10: 10.73 | FZ10: 2.3399458 | GA10: 88.25 | GB10: 209.3 | GC10: 27.459999 | GD10: 187.05 | GE10: 152.39096 | GF10: 191.84708 | GG10: 40.919998 | GH10: 21.01 | GI10: 29.209999 | GJ10: 18.1 | GK10: 603.52545 | GL10: 19.98 | GM10: 13.157892 | GN10: 133.5 | GO10: 200.92 | GP10: 10.36 | GQ10: 11.17 | GR10: 197.327 | GS10: 35.400002 | GT10: 3.3 | GU10: 19.25 | GV10: 52.470001 | GW10: 103.84 | GX10: 90.970001 | GY10: 154.88101 | GZ10: 164.19292 | HA10: 5.52 | HB10: 16.209999 | HC10: 84.562057 | HD10: 91.530128 | HE10: 31.219999 | HF10: 6.79 | HG10: 69.195702 | HH10: 72.93 | HI10: 8.2200003 | HJ10: 25.969999 | HK10: 28.08 | HL10: 17.84 | HM10: 662.07703 | HN10: 11.58 | HO10: 40.266937 | HP10: 47.959999 | HQ10: 4.9899998 | HR10: 1.72 | HS10: 17.150677 | HT10: 36.799999 | HU10: 8.4799995 | HV10: 43.610767 | HW10: 27.945139 | HX10: 22.350653 | HY10: 225.37886 | HZ10: 114.0908 | IA10: 436 | IB10: 50.880001 | IC10: 105.42 | ID10: 94.830002 | IE10: 96.610001 | IF10: 39.325516 | IG10: 112.18791 | IH10: 7.29 | II10: 73.129997 | IJ10: 22.709999 | IK10: 4.5999999 | IL10: 4.5900002 | IM10: 161.28053 | IN10: 10.972597 | IO10: 12.6 | IP10: 40.624954 | IQ10: 19.24 | IR10: 78.782028 | IS10: 33.323254 | IT10: 100.85087 | IU10: 2.6900001 | IV10: 13.24228 | IW10: 11.58 | IX10: 43.249718 | IY10: 142.51596 | IZ10: 141.37556 | JA10: 50.259998 | JB10: 23.809999 | JC10: 76.809998 | JD10: 31.719999 | JE10: 148.46684 | JF10: 54.719822 | JG10: 82.239998 | JH10: 24.6 | JI10: 143.72955
A11: 2025-10-03 | B11: 34.229691 | D11: 11.58 | E11: 27.93 | F11: 60.13229 | G11: 257.07037 | H11: 35.152935 | I11: 120.22 | J11: 131.54941 | K11: 21.799999 | L11: 11.57 | M11: 59.307178 | N11: 16.487305 | O11: 110.01988 | P11: 74.830002 | Q11: 12.086275 | R11: 107.51514 | S11: 2.95 | T11: 77.559998 | U11: 10.07 | V11: 164.67 | W11: 243.00777 | X11: 23.940001 | Y11: 29.17663 | Z11: 59.299999 | AA11: 219.50999 | AB11: 145.5 | AC11: 16.32 | AD11: 6.8899999 | AE11: 60.78038 | AF11: 6.3299999 | AG11: 25.74 | AH11: 49.919998 | AI11: 13.066197 | AJ11: 10.969649 | AK11: 13.96 | AL11: 17.879999 | AM11: 49.583088 | AN11: 16.682442 | AO11: 72.973572 | AP11: 25.75 | AQ11: 18.360226 | AR11: 9.1356688 | AS11: 26.91 | AT11: 59.501831 | AU11: 43.964443 | AV11: 48.260571 | AW11: 2.53 | AX11: 19.42 | AY11: 95.715157 | AZ11: 153.36946 | BA11: 13.978587 | BB11: 90.775444 | BC11: 84.006432 | BD11: 28.118149 | BE11: 27.809999 | BF11: 88.263321 | BG11: 15.94 | BH11: 36.474297 | BI11: 27.914785 | BJ11: 254.78123 | BK11: 113.58 | BL11: 380.01999 | BM11: 7.8299999 | BN11: 91.282196 | BO11: 910.07013 | BP11: 2.4271557 | BQ11: 143.87 | BR11: 7.98 | BS11: 12.55 | BT11: 66.943947 | BU11: 47.351151 | BV11: 35.553001 | BW11: 75.143997 | BX11: 75.106133 | BY11: 537.41241 | BZ11: 56.64035 | CA11: 271.22 | CB11: 11.1 | CC11: 151.82001 | CD11: 138.96912 | CE11: 98.215446 | CF11: 18.536654 | CG11: 50.057114 | CH11: 110.86466 | CI11: 17.34 | CJ11: 171.43999 | CK11: 3.79 | CL11: 69.730003 | CM11: 6.1070962 | CN11: 22.699644 | CO11: 80.171043 | CP11: 8.6899996 | CQ11: 119.35134 | CR11: 58.678974 | CS11: 91.010162 | CT11: 15.52 | CU11: 19.93 | CV11: 72.379997 | CW11: 29.026871 | CX11: 12.105596 | CY11: 34.91 | CZ11: 43.130001 | DA11: 4.5799999 | DB11: 8.9300003 | DC11: 85.790001 | DD11: 167.29697 | DE11: 76.524223 | DF11: 295.86041 | DG11: 357.64001 | DH11: 36.16 | DI11: 59.615673 | DJ11: 245.8083 | DK11: 244.71359 | DL11: 22.959999 | DM11: 18.41 | DN11: 131.10994 | DO11: 52.540001 | DP11: 148.67 | DQ11: 188.8568 | DR11: 73.220001 | DS11: 37.919998 | DT11: 281.0632 | DU11: 102.12 | DV11: 3.3499999 | DW11: 11.7 | DX11: 17.280001 | DY11: 36.830002 | DZ11: 73.279999 | EA11: 18.378944 | EB11: 101.38858 | EC11: 45.599998 | ED11: 243.3575 | EE11: 108.1564 | EF11: 184.48254 | EG11: 15.26 | EH11: 14.858282 | EI11: 64.924072 | EJ11: 64.830475 | EK11: 0.79100001 | EL11: 23.825754 | EM11: 6.5 | EN11: 54.52 | EO11: 230.01608 | EP11: 241.39098 | EQ11: 22.43 | ER11: 145.29379 | ES11: 4.2600002 | ET11: 11.44 | EU11: 17.584616 | EV11: 576.85535 | EW11: 1.73 | EX11: 18.82 | EY11: 73.666763 | EZ11: 64.841652 | FA11: 95.341187 | FB11: 708.71674 | FC11: 61.566219 | FD11: 7.1310043 | FE11: 33.306702 | FF11: 86.645744 | FG11: 28.49 | FH11: 86.036697 | FI11: 154.09671 | FJ11: 513.12811 | FK11: 351.63 | FL11: 10.29 | FM11: 77.823433 | FN11: 86.052887 | FO11: 4.9784904 | FP11: 115.332 | FQ11: 9.9899998 | FR11: 1.6 | FS11: 117.18555 | FT11: 15.31 | FU11: 187.17157 | FV11: 77.129997 | FW11: 127.36 | FX11: 8.1099997 | FY11: 10.84 | FZ11: 2.2746885 | GA11: 86.879997 | GB11: 207.19 | GC11: 27.75 | GD11: 173.07001 | GE11: 149.30301 | GF11: 192.13751 | GG11: 40.720001 | GH11: 21.84 | GI11: 32.700001 | GJ11: 18.450001 | GK11: 600.9848 | GL11: 24.620001 | GM11: 13.272538 | GN11: 122.69 | GO11: 207.2 | GP11: 10.73 | GQ11: 10.99 | GR11: 199.07588 | GS11: 40.060001 | GT11: 3.3699999 | GU11: 19.440001 | GV11: 56.16 | GW11: 103.85 | GX11: 86.760002 | GY11: 151.38016 | GZ11: 164.14365 | HA11: 5.4899998 | HB11: 16.6 | HC11: 84.269524 | HD11: 92.892715 | HE11: 29.889999 | HF11: 7.4899998 | HG11: 70.584053 | HH11: 72 | HI11: 8.54 | HJ11: 25.24 | HK11: 28.959999 | HL11: 17.85 | HM11: 662.0672 | HN11: 11.64 | HO11: 40.502014 | HP11: 48.349998 | HQ11: 4.9499998 | HR11: 1.75 | HS11: 17.160568 | HT11: 37.419998 | HU11: 9.0100002 | HV11: 44.012966 | HW11: 27.526707 | HX11: 22.301958 | HY11: 225.50616 | HZ11: 113.45894 | IA11: 429.82999 | IB11: 51.549999 | IC11: 102.94 | ID11: 95.330002 | IE11: 96.599998 | IF11: 40.066402 | IG11: 112.05885 | IH11: 7.4400001 | II11: 72.849998 | IJ11: 25.959999 | IK11: 4.7399998 | IL11: 4.6500001 | IM11: 157.06981 | IN11: 10.914948 | IO11: 12.77 | IP11: 40.877686 | IQ11: 18.99 | IR11: 78.948395 | IS11: 32.99675 | IT11: 101.2178 | IU11: 2.77 | IV11: 13.500376 | IW11: 11.92 | IX11: 43.479557 | IY11: 141.79881 | IZ11: 142.98492 | JA11: 51.52 | JB11: 23.07 | JC11: 76.949997 | JD11: 31.809999 | JE11: 147.81941 | JF11: 55.243828 | JG11: 80.959999 | JH11: 25.5 | JI11: 143.66089
A12: 2025-10-06 | B12: 33.525257 | D12: 11.83 | E12: 33.790001 | F12: 57.161953 | G12: 255.74527 | H12: 35.180386 | I12: 120.35 | J12: 130.71861 | K12: 21.59 | L12: 13.64 | M12: 60.677151 | N12: 15.338839 | O12: 110.75452 | P12: 75.860001 | Q12: 12.814845 | R12: 108.62355 | S12: 3.04 | T12: 78.440002 | U12: 10.22 | V12: 203.71001 | W12: 244.86752 | X12: 24.99 | Y12: 30.358393 | Z12: 60.98 | AA12: 220.89999 | AB12: 149.5 | AC12: 15.87 | AD12: 6.54 | AE12: 61.367199 | AF12: 6.54 | AG12: 25.379999 | AH12: 53.860001 | AI12: 13.040894 | AJ12: 11.276563 | AK12: 13.6 | AL12: 17.16 | AM12: 49.33831 | AN12: 17.375107 | AO12: 71.77729 | AP12: 25.889999 | AQ12: 18.625319 | AR12: 8.9174452 | AS12: 28.34 | AT12: 62.065994 | AU12: 43.664577 | AV12: 48.338818 | AW12: 2.55 | AX12: 20.889999 | AY12: 96.018745 | AZ12: 154.0943 | BA12: 13.616903 | BB12: 89.386948 | BC12: 85.144218 | BD12: 28.629927 | BE12: 27.85 | BF12: 90.193375 | BG12: 17.43 | BH12: 37.057491 | BI12: 28.086432 | BJ12: 252.25911 | BK12: 114.77 | BL12: 386.07001 | BM12: 7.6399999 | BN12: 92.009277 | BO12: 905.65588 | BP12: 2.3961377 | BQ12: 147.42 | BR12: 11.59 | BS12: 12.61 | BT12: 67.919731 | BU12: 46.786983 | BV12: 35.789951 | BW12: 73.919998 | BX12: 74.476135 | BY12: 553.44464 | BZ12: 57.629528 | CA12: 281.73999 | CB12: 10.8 | CC12: 157.36 | CD12: 143.92593 | CE12: 96.176842 | CF12: 18.680645 | CG12: 50.50259 | CH12: 111.14066 | CI12: 17.620001 | CJ12: 172.03299 | CK12: 3.71 | CL12: 72.169998 | CM12: 6.216002 | CN12: 22.318457 | CO12: 80.278168 | CP12: 8.6199999 | CQ12: 120.16286 | CR12: 58.956509 | CS12: 90.615189 | CT12: 15.52 | CU12: 20.73 | CV12: 70 | CW12: 29.007729 | CX12: 12.134258 | CY12: 38.27 | CZ12: 43.93 | DA12: 4.4099998 | DB12: 8.9700003 | DC12: 86.379997 | DD12: 170.35788 | DE12: 78.04319 | DF12: 297.07574 | DG12: 364.38 | DH12: 38.84 | DI12: 57.692265 | DJ12: 250.85513 | DK12: 249.78038 | DL12: 22.57 | DM12: 20.67 | DN12: 130.20613 | DO12: 54.759998 | DP12: 144.25999 | DQ12: 190.08426 | DR12: 74.620003 | DS12: 37.610001 | DT12: 282.08664 | DU12: 101.02 | DV12: 3.28 | DW12: 11.4 | DX12: 16.540001 | DY12: 36.59 | DZ12: 78.989998 | EA12: 19.613354 | EB12: 102.90749 | EC12: 44.400002 | ED12: 244.32764 | EE12: 108.9418 | EF12: 184.01312 | EG12: 15.32 | EH12: 14.117836 | EI12: 64.388306 | EJ12: 63.363724 | EK12: 0.82300001 | EL12: 23.679583 | EM12: 6.4299998 | EN12: 56.099998 | EO12: 230.98651 | EP12: 236.80518 | EQ12: 22.860001 | ER12: 148.62196 | ES12: 4.29 | ET12: 11.98 | EU12: 17.671528 | EV12: 575.22546 | EW12: 1.73 | EX12: 20.57 | EY12: 75.832565 | EZ12: 64.890373 | FA12: 96.053558 | FB12: 713.80353 | FC12: 61.229027 | FD12: 7.0641813 | FE12: 34.088005 | FF12: 86.266869 | FG12: 27.540001 | FH12: 88.730957 | FI12: 154.58563 | FJ12: 524.25659 | FK12: 359.69 | FL12: 10.43 | FM12: 79.81617 | FN12: 87.687553 | FO12: 5.0180807 | FP12: 116.331 | FQ12: 9.6599998 | FR12: 1.6799999 | FS12: 118.86357 | FT12: 15.38 | FU12: 185.09654 | FV12: 78.339996 | FW12: 138.56 | FX12: 9.2799997 | FY12: 10.51 | FZ12: 2.2840109 | GA12: 90.330002 | GB12: 212.58 | GC12: 29.299999 | GD12: 179.53 | GE12: 149.56601 | GF12: 189.388 | GG12: 38.52 | GH12: 23.58 | GI12: 35.02 | GJ12: 17.875 | GK12: 605.49829 | GL12: 22.16 | GM12: 13.016788 | GN12: 126.27 | GO12: 203.63 | GP12: 11.22 | GQ12: 10.185 | GR12: 202.28549 | GS12: 41.709999 | GT12: 3.4300001 | GU12: 21.559999 | GV12: 58.5 | GW12: 104.84 | GX12: 83.239998 | GY12: 151.0033 | GZ12: 166.33118 | HA12: 5.5300002 | HB12: 16.49 | HC12: 80.06678 | HD12: 92.813728 | HE12: 28.07 | HF12: 7.5700002 | HG12: 71.606033 | HH12: 68.169998 | HI12: 8.5200005 | HJ12: 26.360001 | HK12: 30.1 | HL12: 18.25 | HM12: 664.44153 | HN12: 11.88 | HO12: 40.678322 | HP12: 48.310001 | HQ12: 5.0500002 | HR12: 1.83 | HS12: 17.219913 | HT12: 38.450001 | HU12: 8.5699997 | HV12: 44.305473 | HW12: 27.128202 | HX12: 22.301958 | HY12: 220.30603 | HZ12: 114.02169 | IA12: 453.25 | IB12: 53.139999 | IC12: 109.7 | ID12: 97.07 | IE12: 100.1 | IF12: 40.007912 | IG12: 113.27991 | IH12: 7.6999998 | II12: 73.059998 | IJ12: 26.32 | IK12: 4.9899998 | IL12: 4.4699998 | IM12: 160.02711 | IN12: 10.847691 | IO12: 12.52 | IP12: 38.790276 | IQ12: 19.08 | IR12: 78.967972 | IS12: 32.796951 | IT12: 101.84253 | IU12: 2.8199999 | IV12: 13.758471 | IW12: 11.97 | IX12: 43.694729 | IY12: 143.23312 | IZ12: 142.29379 | JA12: 52.75 | JB12: 23.629999 | JC12: 77.779999 | JD12: 32.82 | JE12: 145.9458 | JF12: 55.185604 | JG12: 81.029999 | JH12: 24.549999 | JI12: 142.62085
