Workbook

Sheet Claude Log
A1: Tur+A1:A53 | B1: Date | C1: User Request | D1: Action Taken | E1: Details | F1: Outcome
A2: 1 | B2: 46075 | C2: User asked to identify and fix errors in the Dashboard of their Options Trading Log. | D2: Found and fixed 5 formula errors (#VALUE! and #DIV/0!) across the Dashboard, plus 4 proactive fixes to prevent future errors. | E2: Errors fixed: (1) L14 & O14 Breakeven % — #DIV/0! from dividing text "0" by "0"; wrapped in IF(OR(...)). (2) I25 Loss-to-Risk Ratio — #VALUE! from dividing by empty I24 (no Beginning Equity entered); added OR check for empty/zero. (3) C25 Cumulative Loss-to-Risk — #VALUE! cascading from I25; wrapped in IFERROR. (4) I29 Net Return % — #DIV/0! from empty I22 equity; added OR check. Proactive fixes: L25, L29, O25, O29 to prevent same issues in Trades 51-75 and 76-100 sections. | F2: All 5 error cells now return valid values. 4 additional cells proactively hardened. Dashboard is error-free.
A3: 2 | B3: 46075 | C3: User asked how to interpret Breakeven % values greater than 100% (172.73%, 177.78%, 150%). | D3: Explained the Breakeven % formula (% Losers / % Winners) and what >100% means for their trading. | E3: Breakeven % = % Losers / % Winners. Values >100% mean you have more losers than winners. E.g., 172.73% means for every 1 winner there are ~1.73 losers. This is NOT a problem IF the R-to-R ratio compensates — and in this case it does (3.63x cumulative). The key insight: Breakeven % tells you the minimum R-to-R ratio needed to break even. | F3: Educational explanation provided. No spreadsheet changes made. User's trading system is profitable despite >100% breakeven because winners are much larger than losers.
A4: 3 | B4: 46075 | C4: User asked to save the entire session into a Claude Desktop project. | D4: Explained limitation: cannot export files or connect to external apps. Offered 3 workarounds. | E4: Suggested: (1) Copy Claude Log sheet contents into a Claude Desktop Project Knowledge file, (2) Copy chat text directly, (3) Save the workbook which already contains the Claude Log. | F4: Awaiting user decision on whether to expand the Claude Log for better standalone reference.
A5: 4 | B5: 46075 | C5: User confirmed they want the Claude Log expanded for standalone reference. | D5: Expanded Claude Log with full session summary: error table with root causes & fixes, Breakeven % interpretation with stats tables, R-to-R analysis, and copy-to-Claude-Desktop instructions. | E5: Added: Session Summary header (rows 6-9), Turn 1 detail with 5-row error table (rows 11-22), Turn 2 detail with win/loss stats + R-to-R comparison tables (rows 24-42), Turn 3-4 summary (rows 44-47), Copy instructions (rows 49-53). | F5: Claude Log is now a self-contained session reference. User can select A1:F53, copy, and paste into Claude Desktop Project Knowledge.
B6: SESSION SUMMARY — Feb 22, 2026
B7: File | C7: D_020_2026_AJZ_Strategies_Options_Log_V1.xlsx
B8: Sheets | C8: Trade Log 2026 (30 trades, rows 2-31) | Dashboard (summary stats in 5 sections: Cumulative, Trades 1-25, 26-50, 51-75, 76-100)
B9: Turns | C9: 4 turns total
B11: TURN 1: ERROR IDENTIFICATION & FIXES
B12: Request: | C12: User asked to identify and fix all errors in the Dashboard.
B14: Error # | C14: Cell | D14: Error Type | E14: Root Cause | F14: Fix Applied
B15: 1 | C15: Dashboard!L14 (Breakeven %, Trades 51-75) | D15: #DIV/0! | E15: % Winners (L7) and % Losers (L8) return text "0" not numeric 0. "0"/"0" = #DIV/0! | F15: =IF(OR(L7=0,L7="0"),0,L8/L7) -> 0
B16: 2 | C16: Dashboard!O14 (Breakeven %, Trades 76-100) | D16: #DIV/0! | E16: Same as L14 — text "0" division | F16: =IF(OR(O7=0,O7="0"),0,O8/O7) -> 0
B17: 3 | C17: Dashboard!I25 (Loss-to-Risk, Trades 26-50) | D17: #VALUE! | E17: I22 (Beginning Equity) empty → I24="" → I10/"" = #VALUE! | F17: =IF(OR(I6=0,I24="",I24=0),0,I10/I24*-1) -> 0
B18: 4 | C18: Dashboard!C25 (Cumulative Loss-to-Risk) | D18: #VALUE! | E18: Cascading: formula compared I25=0% but I25 was #VALUE! | F18: Wrapped in IFERROR(...,0)
B19: 5 | C19: Dashboard!I29 (Net Return %, Trades 26-50) | D19: #DIV/0! | E19: I22 (Beginning Equity) empty → I18/"" = #DIV/0! | F19: =IF(OR(I4=0,I22="",I22=0),0,I18/I22) -> 0
B21: Proactive Fixes: | C21: L25, L29, O25, O29 — Same empty-equity vulnerability in Trades 51-75 and 76-100. Applied identical OR() guards to prevent future #VALUE! and #DIV/0! when those sections populate.
B22: User Action: | C22: User filled in Beginning Equity ($35,000) and Trade Risk % (1.5%) for I22:I23, L22:L23, O22:O23 after the fix.
B24: TURN 2: BREAKEVEN % INTERPRETATION
B25: Request: | C25: User asked how to interpret Breakeven % values > 100% (displayed as 172.73%, 177.78%, 150%).
B27: Formula: | C27: Breakeven % = % Losers / % Winners (e.g. C14 = C8/C7)
B29: Interpretation: | C29: Breakeven % > 100% means you have MORE losing trades than winning trades. Specifically:
B30: Section | C30: Win Rate | D30: Loss Rate | E30: Breakeven % | F30: Meaning
B31: Cumulative (30 trades) | C31: 36.7% (11W) | D31: 63.3% (19L) | E31: 1.7273 | F31: For every 1 winner, ~1.73 losers
B32: Trades 1-25 | C32: 36.0% (9W) | D32: 64.0% (16L) | E32: 1.7778 | F32: For every 1 winner, ~1.78 losers
B33: Trades 26-50 (5 trades) | C33: 40.0% (2W) | D33: 60.0% (3L) | E33: 1.5 | F33: For every 1 winner, 1.5 losers
B35: Key Insight: | C35: A high Breakeven % is ONLY a problem if your R-to-R Ratio doesn't compensate. The rule: R-to-R Ratio must exceed Breakeven % for profitability.
B37: Section | C37: Avg. Win | D37: Avg. Loss | E37: R-to-R Ratio | F37: vs. Breakeven % → Verdict
B38: Cumulative | C38: 472.7 | D38: -130.32 | E38: 3.63x | F38: 3.63x > 1.73x → PROFITABLE ✓
B39: Trades 1-25 | C39: 507.64 | D39: -147.03 | E39: 3.45x | F39: 3.45x > 1.78x → PROFITABLE ✓
B40: Trades 26-50 | C40: 315.5 | D40: -41.22 | E40: 7.65x | F40: 7.65x > 1.50x → VERY PROFITABLE ✓
B42: Conclusion: | C42: The trading system wins only ~37% of the time but winners are 3.6x larger than losers. This is a classic "let winners run, cut losers fast" profile. The system has a ~2x safety margin above breakeven.
B44: TURN 3-4: SESSION EXPORT REQUEST
B45: Request: | C45: User wanted to save the session to a Claude Desktop project.
B46: Limitation: | C46: Excel add-in cannot export files or connect to external apps.
B47: Solution: | C47: Expanded this Claude Log sheet with full session details so user can copy/paste into Claude Desktop project. The log is self-contained and readable as a standalone reference.
B49: HOW TO COPY TO CLAUDE DESKTOP
B50: Step 1: | C50: Select cells A1:F47 on this sheet (or the range you want)
B51: Step 2: | C51: Press Ctrl+C (or Cmd+C on Mac) to copy
...

Sheet Trade Log 2026
A1: Symbol | B1: System | C1: Trade Type | D1: Long/Short | E1: Strike | F1: Cur Stock $ | G1: Trade Date | H1: Entry $$ | I1: Contracts | J1: Exit #1 $ | K1: # Exited | L1: Exit Date | M1: # of Days | N1: Exit #2 $ | O1: # Exited2 | P1: Exit Date3 | Q1: # of Days4 | R1: Exit #3 $ | S1: # Exited5 | T1: Exit Date6 | U1: # of Days7 | V1: Comm. | W1: Gain/Loss | X1: Trade Comments | Y1: Exit #1 | Z1: Exit #2 | AA1: Exit #3
A2: AAPL | B2: Day | C2: CALL | D2: Long | E2: 260 | F2: 10.75 | G2: 46071 | H2: 10.75 | I2: 1 | J2: 11.3 | K2: 1 | L2: 46071 | M2: =IF(L2="","",L2-G2) -> 0 | Q2: =IF(P2="",M2,P2-G2) -> 0 | U2: =IF(P2="",M2,IF(AND(P2="",T2=""),M2,IF(T2="",Q2,T2-G2))) -> 0 | V2: 1.34 | W2: =IF(A2="","",SUM(Y2:AA2)-V2) -> 53.66 | Y2: =IF(D2="Long",((J2-H2)*K2),((H2-J2)*K2))*100 -> 55 | Z2: =IF(D2="Long",((N2-H2)*O2),((H2-N2)*O2))*100 -> 0 | AA2: =IF(D2="long",((R2-H2)*S2),((H2-R2)*S2))*100 -> 0 | AC2: Long
A3: ADI | B3: P_118 | C3: CALL | D3: Long | E3: 300 | F3: 13.35 | G3: 46037 | H3: 13.35 | I3: 1 | J3: 19.1 | K3: 1 | L3: 46044 | M3: =IF(L3="","",L3-G3) -> 7 | Q3: =IF(P3="",M3,P3-G3) -> 7 | U3: =IF(P3="",M3,IF(AND(P3="",T3=""),M3,IF(T3="",Q3,T3-G3))) -> 7 | V3: 1.35 | W3: =IF(A3="","",SUM(Y3:AA3)-V3) -> 573.65 | Y3: =IF(D3="Long",((J3-H3)*K3),((H3-J3)*K3))*100 -> 575 | Z3: =IF(D3="Long",((N3-H3)*O3),((H3-N3)*O3))*100 -> 0 | AA3: =IF(D3="Long",((R3-H3)*S3),((H3-R3)*S3))*100 -> 0 | AC3: Short
A4: AMD | B4: Day | C4: CALL | D4: Long | E4: 200 | F4: 18.3 | G4: 46059 | H4: 18.3 | I4: 1 | J4: 18.1 | K4: 1 | L4: 46059 | M4: =IF(L4="","",L4-G4) -> 0 | Q4: =IF(P4="",M4,P4-G4) -> 0 | U4: =IF(P4="",M4,IF(AND(P4="",T4=""),M4,IF(T4="",Q4,T4-G4))) -> 0 | V4: 1.35 | W4: =IF(A4="","",SUM(Y4:AA4)-V4) -> -21.35 | Y4: =IF(D4="Long",((J4-H4)*K4),((H4-J4)*K4))*100 -> -20 | Z4: =IF(D4="Long",((N4-H4)*O4),((H4-N4)*O4))*100 -> 0 | AA4: =IF(D4="Long",((R4-H4)*S4),((H4-R4)*S4))*100 -> 0 | AC4: -1.25 | AD4: Covered Call Exercised Win
A5: AMD | B5: P_116 | C5: CALL | D5: Long | E5: 210 | F5: 15.8 | G5: 46064 | H5: 15.8 | I5: 1 | J5: 12.25 | K5: 1 | L5: 46066 | M5: =IF(L5="","",L5-G5) -> 2 | Q5: =IF(P5="",M5,P5-G5) -> 2 | U5: =IF(P5="",M5,IF(AND(P5="",T5=""),M5,IF(T5="",Q5,T5-G5))) -> 2 | V5: 1.34 | W5: =IF(A5="","",SUM(Y5:AA5)-V5) -> -356.34 | Y5: =IF(D5="Long",((J5-H5)*K5),((H5-J5)*K5))*100 -> -355 | Z5: =IF(D5="Long",((N5-H5)*O5),((H5-N5)*O5))*100 -> 0 | AA5: =IF(D5="Long",((R5-H5)*S5),((H5-R5)*S5))*100 -> 0 | AC5: 4.6 | AD5: Exercised Loss
A6: AMT | B6: P_920 | C6: PUT | D6: Long | E6: 175 | F6: 2.25 | G6: 46066 | H6: 2.25 | I6: 1 | J6: 2.22 | K6: 1 | L6: 46066 | M6: =IF(L6="","",L6-G6) -> 0 | Q6: =IF(P6="",M6,P6-G6) -> 0 | U6: =IF(P6="",M6,IF(AND(P6="",T6=""),M6,IF(T6="",Q6,T6-G6))) -> 0 | V6: 1.33 | W6: =IF(A6="","",SUM(Y6:AA6)-V6) -> -4.33 | Y6: =IF(D6="Long",((J6-H6)*K6),((H6-J6)*K6))*100 -> -3 | Z6: =IF(D6="Long",((N6-H6)*O6),((H6-N6)*O6))*100 -> 0 | AA6: =IF(D6="Long",((R6-H6)*S6),((H6-R6)*S6))*100 -> 0 | AC6: 0.23 | AD6: Buybacks
A7: AMZN | B7: Day | C7: PUT | D7: Long | E7: 247.5 | F7: 15.85 | G7: 46045 | H7: 15.85 | I7: 1 | J7: 16.05 | K7: 1 | L7: 46045 | M7: =IF(L7="","",L7-G7) -> 0 | Q7: =IF(P7="",M7,P7-G7) -> 0 | U7: =IF(P7="",M7,IF(AND(P7="",T7=""),M7,IF(T7="",Q7,T7-G7))) -> 0 | V7: 1.35 | W7: =IF(A7="","",SUM(Y7:AA7)-V7) -> 18.65 | Y7: =IF(D7="Long",((J7-H7)*K7),((H7-J7)*K7))*100 -> 20 | Z7: =IF(D7="Long",((N7-H7)*O7),((H7-N7)*O7))*100 -> 0 | AA7: =IF(D7="Long",((R7-H7)*S7),((H7-R7)*S7))*100 -> 0 | AC7: 0 | AD7: Not Exercised Win
A8: APLD | B8: P_115 | C8: CALL | D8: Long | E8: 35 | F8: 3.4 | G8: 46056 | H8: 3.4 | I8: 4 | M8: =IF(L8="","",L8-G8) | Q8: =IF(P8="",M8,P8-G8) | U8: =IF(P8="",M8,IF(AND(P8="",T8=""),M8,IF(T8="",Q8,T8-G8))) | V8: 2.62 | W8: =IF(A8="","",SUM(Y8:AA8)-V8) -> -2.62 | Y8: =IF(D8="Long",((J8-H8)*K8),((H8-J8)*K8))*100 -> 0 | Z8: =IF(D8="Long",((N8-H8)*O8),((H8-N8)*O8))*100 -> 0 | AA8: =IF(D8="Long",((R8-H8)*S8),((H8-R8)*S8))*100 -> 0 | AC8: 4.25 | AD8: Option CALL Wins
A9: APLD | B9: P_115 | C9: CALL | D9: Long | E9: 35 | F9: 0.9 | G9: 46058 | H9: 0.9 | I9: 3 | M9: =IF(L9="","",L9-G9) | Q9: =IF(P9="",M9,P9-G9) | U9: =IF(P9="",M9,IF(AND(P9="",T9=""),M9,IF(T9="",Q9,T9-G9))) | V9: 1.97 | W9: =IF(A9="","",SUM(Y9:AA9)-V9) -> -1.97 | Y9: =IF(D9="Long",((J9-H9)*K9),((H9-J9)*K9))*100 -> 0 | Z9: =IF(D9="Long",((N9-H9)*O9),((H9-N9)*O9))*100 -> 0 | AA9: =IF(D9="Long",((R9-H9)*S9),((H9-R9)*S9))*100 -> 0
A10: AZN | B10: P_118 | C10: CALL | D10: Long | E10: 95 | F10: 1.8 | G10: 46028 | H10: 1.8 | I10: 4 | J10: 2.5 | K10: 4 | L10: 46028 | M10: =IF(L10="","",L10-G10) -> 0 | Q10: =IF(P10="",M10,P10-G10) -> 0 | U10: =IF(P10="",M10,IF(AND(P10="",T10=""),M10,IF(T10="",Q10,T10-G10))) -> 0 | V10: 5.26 | W10: =IF(A10="","",SUM(Y10:AA10)-V10) -> 274.74 | Y10: =IF(D10="Long",((J10-H10)*K10),((H10-J10)*K10))*100 -> 280 | Z10: =IF(D10="Long",((N10-H10)*O10),((H10-N10)*O10))*100 -> 0 | AA10: =IF(D10="Long",((R10-H10)*S10),((H10-R10)*S10))*100 -> 0 | AC10: Trading Systems
A11: BG | B11: P_118 | C11: CALL | D11: Long | E11: 100 | F11: 3.9 | G11: 46034 | H11: 3.9 | I11: 3 | J11: 10.15 | K11: 3 | L11: 46037 | M11: =IF(L11="","",L11-G11) -> 3 | Q11: =IF(P11="",M11,P11-G11) -> 3 | U11: =IF(P11="",M11,IF(AND(P11="",T11=""),M11,IF(T11="",Q11,T11-G11))) -> 3 | V11: 3.99 | W11: =IF(A11="","",SUM(Y11:AA11)-V11) -> 1871.01 | Y11: =IF(D11="Long",((J11-H11)*K11),((H11-J11)*K11))*100 -> 1875 | Z11: =IF(D11="Long",((N11-H11)*O11),((H11-N11)*O11))*100 -> 0 | AA11: =IF(D11="Long",((R11-H11)*S11),((H11-R11)*S11))*100 -> 0 | AC11: 48Hr | AD11: 48 hour PUT Trades
A12: COIN | B12: P_117 | C12: CALL | D12: Long | E12: 165 | F12: 13.95 | G12: 46066 | H12: 13.95 | I12: 1 | J12: 13.85 | K12: 1 | L12: 46066 | M12: =IF(L12="","",L12-G12) -> 0 | Q12: =IF(P12="",M12,P12-G12) -> 0 | U12: =IF(P12="",M12,IF(AND(P12="",T12=""),M12,IF(T12="",Q12,T12-G12))) -> 0 | V12: 1.34 | W12: =IF(A12="","",SUM(Y12:AA12)-V12) -> -11.34 | Y12: =IF(D12="Long",((J12-H12)*K12),((H12-J12)*K12))*100 -> -10 | Z12: =IF(D12="Long",((N12-H12)*O12),((H12-N12)*O12))*100 -> 0 | AA12: =IF(D12="Long",((R12-H12)*S12),((H12-R12)*S12))*100 -> 0 | AC12: MW | AD12: Meta Wealth
A13: COMP | B13: P_117 | C13: CALL | D13: Long | E13: 11 | F13: 1.29 | G13: 46065 | H13: 1.29 | I13: 10 | J13: 0.89 | K13: 10 | L13: 46066 | M13: =IF(L13="","",L13-G13) -> 1 | Q13: =IF(P13="",M13,P13-G13) -> 1 | U13: =IF(P13="",M13,IF(AND(P13="",T13=""),M13,IF(T13="",Q13,T13-G13))) -> 1 | V13: 13.14 | W13: =IF(A13="","",SUM(Y13:AA13)-V13) -> -413.14 | Y13: =IF(D13="Long",((J13-H13)*K13),((H13-J13)*K13))*100 -> -400 | Z13: =IF(D13="Long",((N13-H13)*O13),((H13-N13)*O13))*100 -> 0 | AA13: =IF(D13="Long",((R13-H13)*S13),((H13-R13)*S13))*100 -> 0 | AC13: OFI | AD13: Options for Income
A14: EVTL | B14: TOS_Import | C14: CALL | D14: Long | E14: 7.5 | F14: 0.44 | G14: 46027 | H14: 0.44 | I14: 20 | J14: 0.35 | K14: 20 | L14: 46028 | M14: =IF(L14="","",L14-G14) -> 1 | Q14: =IF(P14="",M14,P14-G14) -> 1 | U14: =IF(P14="",M14,IF(AND(P14="",T14=""),M14,IF(T14="",Q14,T14-G14))) -> 1 | V14: 26.25 | W14: =IF(A14="","",SUM(Y14:AA14)-V14) -> -206.25 | Y14: =IF(D14="Long",((J14-H14)*K14),((H14-J14)*K14))*100 -> -180 | Z14: =IF(D14="Long",((N14-H14)*O14),((H14-N14)*O14))*100 -> 0 | AA14: =IF(D14="Long",((R14-H14)*S14),((H14-R14)*S14))*100 -> 0 | AC14: SMD | AD14: Steven Daigle Trades
A15: GFS | B15: TOS_Import | C15: CALL | D15: Long | E15: 50 | F15: 2.93 | G15: 46065 | H15: 2.93 | I15: 6 | J15: 2.6 | K15: 6 | L15: 46066 | M15: =IF(L15="","",L15-G15) -> 1 | Q15: =IF(P15="",M15,P15-G15) -> 1 | U15: =IF(P15="",M15,IF(AND(P15="",T15=""),M15,IF(T15="",Q15,T15-G15))) -> 1 | V15: 7.91 | W15: =IF(A15="","",SUM(Y15:AA15)-V15) -> -205.91 | Y15: =IF(D15="Long",((J15-H15)*K15),((H15-J15)*K15))*100 -> -198 | Z15: =IF(D15="Long",((N15-H15)*O15),((H15-N15)*O15))*100 -> 0 | AA15: =IF(D15="Long",((R15-H15)*S15),((H15-R15)*S15))*100 -> 0 | AC15: SPT | AD15: Schaeffer Power Trend
A16: GOOG | B16: P_118 | C16: CALL | D16: Long | E16: 320 | F16: 19.5 | G16: 46030 | H16: 19.5 | I16: 1 | J16: 29.05 | K16: 1 | L16: 46035 | M16: =IF(L16="","",L16-G16) -> 5 | Q16: =IF(P16="",M16,P16-G16) -> 5 | U16: =IF(P16="",M16,IF(AND(P16="",T16=""),M16,IF(T16="",Q16,T16-G16))) -> 5 | V16: 1.37 | W16: =IF(A16="","",SUM(Y16:AA16)-V16) -> 953.63 | Y16: =IF(D16="Long",((J16-H16)*K16),((H16-J16)*K16))*100 -> 955 | Z16: =IF(D16="Long",((N16-H16)*O16),((H16-N16)*O16))*100 -> 0 | AA16: =IF(D16="Long",((R16-H16)*S16),((H16-R16)*S16))*100 -> 0 | AC16: VPAI | AD16: Vantage Point AI
A17: GOOG | B17: Day | C17: CALL | D17: Long | E17: 325 | F17: 15.65 | G17: 46058 | H17: 15.65 | I17: 1 | J17: 14.8 | K17: 1 | L17: 46058 | M17: =IF(L17="","",L17-G17) -> 0 | Q17: =IF(P17="",M17,P17-G17) -> 0 | U17: =IF(P17="",M17,IF(AND(P17="",T17=""),M17,IF(T17="",Q17,T17-G17))) -> 0 | V17: 1.35 | W17: =IF(A17="","",SUM(Y17:AA17)-V17) -> -86.35 | Y17: =IF(D17="Long",((J17-H17)*K17),((H17-J17)*K17))*100 -> -85 | Z17: =IF(D17="Long",((N17-H17)*O17),((H17-N17)*O17))*100 -> 0 | AA17: =IF(D17="Long",((R17-H17)*S17),((H17-R17)*S17))*100 -> 0 | AC17: WIA | AD17: Weekly Income Accelator
A18: GOOG | B18: Day | C18: PUT | D18: Long | E18: 295 | F18: 9.4 | G18: 46070 | H18: 9.4 | I18: 1 | J18: 8.9 | K18: 1 | L18: 46070 | M18: =IF(L18="","",L18-G18) -> 0 | Q18: =IF(P18="",M18,P18-G18) -> 0 | U18: =IF(P18="",M18,IF(AND(P18="",T18=""),M18,IF(T18="",Q18,T18-G18))) -> 0 | V18: 1.34 | W18: =IF(A18="","",SUM(Y18:AA18)-V18) -> -51.34 | Y18: =IF(D18="Long",((J18-H18)*K18),((H18-J18)*K18))*100 -> -50 | Z18: =IF(D18="Long",((N18-H18)*O18),((H18-N18)*O18))*100 -> 0 | AA18: =IF(D18="Long",((R18-H18)*S18),((H18-R18)*S18))*100 -> 0 | AC18: WPMP | AD18: Wealthpop Mesh Prime
A19: IBM | B19: P_117 | C19: CALL | D19: Long | E19: 290 | F19: 5.6 | G19: 46024 | H19: 5.6 | I19: 2 | J19: 8.4 | K19: 2 | L19: 46027 | M19: =IF(L19="","",L19-G19) -> 3 | Q19: =IF(P19="",M19,P19-G19) -> 3 | U19: =IF(P19="",M19,IF(AND(P19="",T19=""),M19,IF(T19="",Q19,T19-G19))) -> 3 | V19: 2.65 | W19: =IF(A19="","",SUM(Y19:AA19)-V19) -> 557.35 | Y19: =IF(D19="Long",((J19-H19)*K19),((H19-J19)*K19))*100 -> 560 | Z19: =IF(D19="Long",((N19-H19)*O19),((H19-N19)*O19))*100 -> 0 | AA19: =IF(D19="Long",((R19-H19)*S19),((H19-R19)*S19))*100 -> 0 | AC19: Day
A20: IBM | B20: Day | C20: PUT | D20: Long | E20: 260 | F20: 11.15 | G20: 46071 | H20: 11.15 | I20: 1 | J20: 10.45 | K20: 1 | L20: 46071 | M20: =IF(L20="","",L20-G20) -> 0 | Q20: =IF(P20="",M20,P20-G20) -> 0 | U20: =IF(P20="",M20,IF(AND(P20="",T20=""),M20,IF(T20="",Q20,T20-G20))) -> 0 | V20: 1.34 | W20: =IF(A20="","",SUM(Y20:AA20)-V20) -> -71.34 | Y20: =IF(D20="Long",((J20-H20)*K20),((H20-J20)*K20))*100 -> -70 | Z20: =IF(D20="Long",((N20-H20)*O20),((H20-N20)*O20))*100 -> 0 | AA20: =IF(D20="Long",((R20-H20)*S20),((H20-R20)*S20))*100 -> 0
A21: ILMN | B21: P_118 | C21: CALL | D21: Long | E21: 150 | F21: 12 | G21: 46043 | H21: 12 | I21: 1 | J21: 14.4 | K21: 1 | L21: 46043 | M21: =IF(L21="","",L21-G21) -> 0 | Q21: =IF(P21="",M21,P21-G21) -> 0 | U21: =IF(P21="",M21,IF(AND(P21="",T21=""),M21,IF(T21="",Q21,T21-G21))) -> 0 | V21: 1.34 | W21: =IF(A21="","",SUM(Y21:AA21)-V21) -> 238.66 | Y21: =IF(D21="Long",((J21-H21)*K21),((H21-J21)*K21))*100 -> 240 | Z21: =IF(D21="Long",((N21-H21)*O21),((H21-N21)*O21))*100 -> 0 | AA21: =IF(D21="Long",((R21-H21)*S21),((H21-R21)*S21))*100 -> 0
A22: INTC | B22: Day | C22: CALL | D22: Long | E22: 49 | F22: 3.9 | G22: 46037 | H22: 3.9 | I22: 2 | J22: 4.05 | K22: 2 | L22: 46037 | M22: =IF(L22="","",L22-G22) -> 0 | Q22: =IF(P22="",M22,P22-G22) -> 0 | U22: =IF(P22="",M22,IF(AND(P22="",T22=""),M22,IF(T22="",Q22,T22-G22))) -> 0 | V22: 2.63 | W22: =IF(A22="","",SUM(Y22:AA22)-V22) -> 27.37 | Y22: =IF(D22="Long",((J22-H22)*K22),((H22-J22)*K22))*100 -> 30 | Z22: =IF(D22="Long",((N22-H22)*O22),((H22-N22)*O22))*100 -> 0 | AA22: =IF(D22="Long",((R22-H22)*S22),((H22-R22)*S22))*100 -> 0
A23: JMIA | B23: P_910 | C23: CALL | D23: Long | E23: 12 | F23: 1.9 | G23: 46045 | H23: 1.9 | I23: 4 | J23: 0.82 | K23: 4 | L23: 46057 | M23: =IF(L23="","",L23-G23) -> 12 | Q23: =IF(P23="",M23,P23-G23) -> 12 | U23: =IF(P23="",M23,IF(AND(P23="",T23=""),M23,IF(T23="",Q23,T23-G23))) -> 12 | V23: 5.25 | W23: =IF(A23="","",SUM(Y23:AA23)-V23) -> -437.25 | Y23: =IF(D23="Long",((J23-H23)*K23),((H23-J23)*K23))*100 -> -432 | Z23: =IF(D23="Long",((N23-H23)*O23),((H23-N23)*O23))*100 -> 0 | AA23: =IF(D23="Long",((R23-H23)*S23),((H23-R23)*S23))*100 -> 0
A24: MU | B24: Day | C24: CALL | D24: Long | E24: 370 | F24: 29.7 | G24: 46042 | H24: 29.7 | I24: 1 | J24: 29.55 | K24: 1 | L24: 46042 | M24: =IF(L24="","",L24-G24) -> 0 | Q24: =IF(P24="",M24,P24-G24) -> 0 | U24: =IF(P24="",M24,IF(AND(P24="",T24=""),M24,IF(T24="",Q24,T24-G24))) -> 0 | V24: 1.37 | W24: =IF(A24="","",SUM(Y24:AA24)-V24) -> -16.37 | Y24: =IF(D24="Long",((J24-H24)*K24),((H24-J24)*K24))*100 -> -15 | Z24: =IF(D24="Long",((N24-H24)*O24),((H24-N24)*O24))*100 -> 0 | AA24: =IF(D24="Long",((R24-H24)*S24),((H24-R24)*S24))*100 -> 0
A25: SOC | B25: P_115 | C25: CALL | D25: Long | E25: 10 | F25: 2.09 | G25: 46027 | H25: 2.09 | I25: 4 | J25: 1.18 | K25: 4 | L25: 46028 | M25: =IF(L25="","",L25-G25) -> 1 | Q25: =IF(P25="",M25,P25-G25) -> 1 | U25: =IF(P25="",M25,IF(AND(P25="",T25=""),M25,IF(T25="",Q25,T25-G25))) -> 1 | V25: 5.25 | W25: =IF(A25="","",SUM(Y25:AA25)-V25) -> -369.25 | Y25: =IF(D25="Long",((J25-H25)*K25),((H25-J25)*K25))*100 -> -364 | Z25: =IF(D25="Long",((N25-H25)*O25),((H25-N25)*O25))*100 -> 0 | AA25: =IF(D25="Long",((R25-H25)*S25),((H25-R25)*S25))*100 -> 0
A26: SPY | B26: P_110 | C26: CALL | D26: Long | E26: 692 | F26: 17.35 | G26: 46052 | H26: 17.35 | I26: 1 | J26: 16.39 | K26: 1 | L26: 46052 | M26: =IF(L26="","",L26-G26) -> 0 | Q26: =IF(P26="",M26,P26-G26) -> 0 | U26: =IF(P26="",M26,IF(AND(P26="",T26=""),M26,IF(T26="",Q26,T26-G26))) -> 0 | V26: 1.35 | W26: =IF(A26="","",SUM(Y26:AA26)-V26) -> -97.35 | Y26: =IF(D26="Long",((J26-H26)*K26),((H26-J26)*K26))*100 -> -96 | Z26: =IF(D26="Long",((N26-H26)*O26),((H26-N26)*O26))*100 -> 0 | AA26: =IF(D26="Long",((R26-H26)*S26),((H26-R26)*S26))*100 -> 0
A27: SPY | B27: P_010 | C27: PUT | D27: Long | E27: 681 | F27: 12.54 | G27: 46058 | H27: 12.54 | I27: 1 | J27: 11.36 | K27: 1 | L27: 46058 | M27: =IF(L27="","",L27-G27) -> 0 | Q27: =IF(P27="",M27,P27-G27) -> 0 | U27: =IF(P27="",M27,IF(AND(P27="",T27=""),M27,IF(T27="",Q27,T27-G27))) -> 0 | V27: 1.34 | W27: =IF(A27="","",SUM(Y27:AA27)-V27) -> -119.34 | Y27: =IF(D27="Long",((J27-H27)*K27),((H27-J27)*K27))*100 -> -118 | Z27: =IF(D27="Long",((N27-H27)*O27),((H27-N27)*O27))*100 -> 0 | AA27: =IF(D27="Long",((R27-H27)*S27),((H27-R27)*S27))*100 -> 0
A28: UNH | B28: P_117 | C28: CALL | D28: Long | E28: 280 | F28: 16.62 | G28: 46049 | H28: 16.62 | I28: 2 | J28: 16.6 | K28: 1 | L28: 46049 | M28: =IF(L28="","",L28-G28) -> 0 | N28: 16.65 | O28: 1 | P28: 46049 | Q28: =IF(P28="",M28,P28-G28) -> 0 | U28: =IF(P28="",M28,IF(AND(P28="",T28=""),M28,IF(T28="",Q28,T28-G28))) -> 0 | V28: 2.7 | W28: =IF(A28="","",SUM(Y28:AA28)-V28) -> -1.7 | Y28: =IF(D28="Long",((J28-H28)*K28),((H28-J28)*K28))*100 -> -2 | Z28: =IF(D28="Long",((N28-H28)*O28),((H28-N28)*O28))*100 -> 3 | AA28: =IF(D28="Long",((R28-H28)*S28),((H28-R28)*S28))*100 -> 0
A29: VSAT | B29: P_118 | C29: CALL | D29: Long | E29: 40 | F29: 4.9 | G29: 46034 | H29: 4.9 | I29: 1 | J29: 10.1 | K29: 1 | L29: 46050 | M29: =IF(L29="","",L29-G29) -> 16 | Q29: =IF(P29="",M29,P29-G29) -> 16 | U29: =IF(P29="",M29,IF(AND(P29="",T29=""),M29,IF(T29="",Q29,T29-G29))) -> 16 | V29: 1.34 | W29: =IF(A29="","",SUM(Y29:AA29)-V29) -> 518.66 | Y29: =IF(D29="Long",((J29-H29)*K29),((H29-J29)*K29))*100 -> 520 | Z29: =IF(D29="Long",((N29-H29)*O29),((H29-N29)*O29))*100 -> 0 | AA29: =IF(D29="Long",((R29-H29)*S29),((H29-R29)*S29))*100 -> 0
A30: VSAT | B30: P_118 | C30: CALL | D30: Long | E30: 42 | F30: 8.7 | G30: 46050 | H30: 8.7 | I30: 2 | J30: 10.1 | K30: 1 | L30: 46050 | M30: =IF(L30="","",L30-G30) -> 0 | N30: 8.45 | O30: 1 | P30: 46050 | Q30: =IF(P30="",M30,P30-G30) -> 0 | U30: =IF(P30="",M30,IF(AND(P30="",T30=""),M30,IF(T30="",Q30,T30-G30))) -> 0 | V30: 2.67 | W30: =IF(A30="","",SUM(Y30:AA30)-V30) -> 112.33 | Y30: =IF(D30="Long",((J30-H30)*K30),((H30-J30)*K30))*100 -> 140 | Z30: =IF(D30="Long",((N30-H30)*O30),((H30-N30)*O30))*100 -> -25 | AA30: =IF(D30="Long",((R30-H30)*S30),((H30-R30)*S30))*100 -> 0
A31: XLB | B31: P_118 | C31: CALL | D31: Long | E31: 52.5 | F31: 1.67 | G31: 46073 | H31: 1.67 | I31: 4 | M31: =IF(L31="","",L31-G31) | Q31: =IF(P31="",M31,P31-G31) | U31: =IF(P31="",M31,IF(AND(P31="",T31=""),M31,IF(T31="",Q31,T31-G31))) | V31: 2.62 | W31: =IF(A31="","",SUM(Y31:AA31)-V31) -> -2.62 | Y31: =IF(D31="Long",((J31-H31)*K31),((H31-J31)*K31))*100 -> 0 | Z31: =IF(D31="Long",((N31-H31)*O31),((H31-N31)*O31))*100 -> 0 | AA31: =IF(D31="Long",((R31-H31)*S31),((H31-R31)*S31))*100 -> 0
M32: =IF(L32="","",L32-G32) | Q32: =IF(P32="",M32,P32-G32) | U32: =IF(P32="",M32,IF(AND(P32="",T32=""),M32,IF(T32="",Q32,T32-G32))) | W32: =IF(A32="","",SUM(Y32:AA32)-V32) | Y32: =IF(D32="Long",((J32-H32)*K32),((H32-J32)*K32))*100 -> 0 | Z32: =IF(D32="Long",((N32-H32)*O32),((H32-N32)*O32))*100 -> 0 | AA32: =IF(D32="Long",((R32-H32)*S32),((H32-R32)*S32))*100 -> 0
M33: =IF(L33="","",L33-G33) | Q33: =IF(P33="",M33,P33-G33) | U33: =IF(P33="",M33,IF(AND(P33="",T33=""),M33,IF(T33="",Q33,T33-G33))) | W33: =IF(A33="","",SUM(Y33:AA33)-V33) | Y33: =IF(D33="Long",((J33-H33)*K33),((H33-J33)*K33))*100 -> 0 | Z33: =IF(D33="Long",((N33-H33)*O33),((H33-N33)*O33))*100 -> 0 | AA33: =IF(D33="Long",((R33-H33)*S33),((H33-R33)*S33))*100 -> 0
M34: =IF(L34="","",L34-G34) | Q34: =IF(P34="",M34,P34-G34) | U34: =IF(P34="",M34,IF(AND(P34="",T34=""),M34,IF(T34="",Q34,T34-G34))) | W34: =IF(A34="","",SUM(Y34:AA34)-V34) | Y34: =IF(D34="Long",((J34-H34)*K34),((H34-J34)*K34))*100 -> 0 | Z34: =IF(D34="Long",((N34-H34)*O34),((H34-N34)*O34))*100 -> 0 | AA34: =IF(D34="Long",((R34-H34)*S34),((H34-R34)*S34))*100 -> 0
M35: =IF(L35="","",L35-G35) | Q35: =IF(P35="",M35,P35-G35) | U35: =IF(P35="",M35,IF(AND(P35="",T35=""),M35,IF(T35="",Q35,T35-G35))) | W35: =IF(A35="","",SUM(Y35:AA35)-V35) | Y35: =IF(D35="Long",((J35-H35)*K35),((H35-J35)*K35))*100 -> 0 | Z35: =IF(D35="Long",((N35-H35)*O35),((H35-N35)*O35))*100 -> 0 | AA35: =IF(D35="Long",((R35-H35)*S35),((H35-R35)*S35))*100 -> 0
M36: =IF(L36="","",L36-G36) | Q36: =IF(P36="",M36,P36-G36) | U36: =IF(P36="",M36,IF(AND(P36="",T36=""),M36,IF(T36="",Q36,T36-G36))) | W36: =IF(A36="","",SUM(Y36:AA36)-V36) | Y36: =IF(D36="Long",((J36-H36)*K36),((H36-J36)*K36))*100 -> 0 | Z36: =IF(D36="Long",((N36-H36)*O36),((H36-N36)*O36))*100 -> 0 | AA36: =IF(D36="Long",((R36-H36)*S36),((H36-R36)*S36))*100 -> 0
M37: =IF(L37="","",L37-G37) | Q37: =IF(P37="",M37,P37-G37) | U37: =IF(P37="",M37,IF(AND(P37="",T37=""),M37,IF(T37="",Q37,T37-G37))) | W37: =IF(A37="","",SUM(Y37:AA37)-V37) | Y37: =IF(D37="Long",((J37-H37)*K37),((H37-J37)*K37))*100 -> 0 | Z37: =IF(D37="Long",((N37-H37)*O37),((H37-N37)*O37))*100 -> 0 | AA37: =IF(D37="Long",((R37-H37)*S37),((H37-R37)*S37))*100 -> 0
M38: =IF(L38="","",L38-G38) | Q38: =IF(P38="",M38,P38-G38) | U38: =IF(P38="",M38,IF(AND(P38="",T38=""),M38,IF(T38="",Q38,T38-G38))) | W38: =IF(A38="","",SUM(Y38:AA38)-V38) | Y38: =IF(D38="Long",((J38-H38)*K38),((H38-J38)*K38))*100 -> 0 | Z38: =IF(D38="Long",((N38-H38)*O38),((H38-N38)*O38))*100 -> 0 | AA38: =IF(D38="Long",((R38-H38)*S38),((H38-R38)*S38))*100 -> 0
M39: =IF(L39="","",L39-G39) | Q39: =IF(P39="",M39,P39-G39) | U39: =IF(P39="",M39,IF(AND(P39="",T39=""),M39,IF(T39="",Q39,T39-G39))) | W39: =IF(A39="","",SUM(Y39:AA39)-V39) | Y39: =IF(D39="Long",((J39-H39)*K39),((H39-J39)*K39))*100 -> 0 | Z39: =IF(D39="Long",((N39-H39)*O39),((H39-N39)*O39))*100 -> 0 | AA39: =IF(D39="Long",((R39-H39)*S39),((H39-R39)*S39))*100 -> 0
M40: =IF(L40="","",L40-G40) | Q40: =IF(P40="",M40,P40-G40) | U40: =IF(P40="",M40,IF(AND(P40="",T40=""),M40,IF(T40="",Q40,T40-G40))) | W40: =IF(A40="","",SUM(Y40:AA40)-V40) | Y40: =IF(D40="Long",((J40-H40)*K40),((H40-J40)*K40))*100 -> 0 | Z40: =IF(D40="Long",((N40-H40)*O40),((H40-N40)*O40))*100 -> 0 | AA40: =IF(D40="Long",((R40-H40)*S40),((H40-R40)*S40))*100 -> 0
...

Sheet Dashboard
B2: Cumulative Results | E2: Trades 1-25 | H2: Trades 26-50 | K2: Trades 51-75 | N2: Trades 76-100
B4: # of Trades | C4: =C5+C6 -> 30 | E4: # of Trades | F4: =F5+F6 -> 25 | H4: # of Trades | I4: {=SUMPRODUCT((ROW(TableLog[Symbol])-ROW(TableLog[#Headers])>=26)*(ROW(TableLog[Symbol])-ROW(TableLog[#Headers])<=50)*(TableLog[Symbol]<>""))} -> 5 | K4: # of Trades | L4: =L5+L6 -> 0 | N4: # of Trades | O4: =O5+O6 -> 0
B5: # of Winners | C5: =COUNTIF('Trade Log 2026'!W2:W101,">0") -> 11 | E5: # of Winners | F5: =COUNTIF('Trade Log 2026'!W2:W26,">0") -> 9 | H5: # of Winners | I5: =COUNTIF('Trade Log 2026'!W27:W51,">0") -> 2 | K5: # of Winners | L5: =COUNTIF('Trade Log 2026'!W52:W76,">0") -> 0 | N5: # of Winners | O5: =COUNTIF('Trade Log 2026'!W77:W101,">0") -> 0
B6: # of Losers | C6: =COUNTIF('Trade Log 2026'!W2:W101,"<0") -> 19 | E6: # of Losers | F6: =COUNTIF('Trade Log 2026'!W2:W26,"<0") -> 16 | H6: # of Losers | I6: =COUNTIF('Trade Log 2026'!W27:W51,"<0") -> 3 | K6: # of Losers | L6: =COUNTIF('Trade Log 2026'!W52:W76,"<0") -> 0 | N6: # of Losers | O6: =COUNTIF('Trade Log 2026'!W77:W101,"<0") -> 0
B7: % Winners | C7: =IF(C5=0,"0",C5/C4) -> 0.36666667 | E7: % Winners | F7: =IF(F5=0,"0",F5/F4) -> 0.36 | H7: % Winners | I7: =IF(I5=0,"0",I5/I4) -> 0.4 | K7: % Winners | L7: =IF(L5=0,"0",L5/L4) -> 0 | N7: % Winners | O7: =IF(O5=0,"0",O5/O4) -> 0
B8: % Losers | C8: =IF(C6=0,"0",C6/C4) -> 0.63333333 | E8: % Losers | F8: =IF(F6=0,"0",F6/F4) -> 0.64 | H8: % Losers | I8: =IF(I6=0,"0",I6/I4) -> 0.6 | K8: % Losers | L8: =IF(L6=0,"0",L6/L4) -> 0 | N8: % Losers | O8: =IF(O6=0,"0",O6/O4) -> 0
B9: Avg. $ Win | C9: =IF(C5=0,"0",C16/C5) -> 472.70091 | E9: Avg. $ Win | F9: =IF(F5=0,"0",F16/F5) -> 507.63556 | H9: Avg. $ Win | I9: =IF(I5=0,"0",I16/I5) -> 315.495 | K9: Avg. $ Win | L9: =IF(L5=0,"0",L16/L5) -> 0 | N9: Avg. $ Win | O9: =IF(O5=0,"0",O16/O5) -> 0
B10: Avg. $ Loss | C10: =IF(C5=0,"0",C17/C6) -> -130.32421 | E10: Avg. $ Loss | F10: =IF(F6=0,"0",F17/F6) -> -147.03125 | H10: Avg. $ Loss | I10: =IF(I6=0,"0",I17/I6) -> -41.22 | K10: Avg. $ Loss | L10: =IF(L6=0,"0",L17/L6) -> 0 | N10: Avg. $ Loss | O10: =IF(O6=0,"0",O17/O6) -> 0
B11: R-to-R Ratio | C11: =IF(C5=0,"0",C9/-C10) -> 3.6271151 | E11: R-to-R Ratio | F11: =IF(F5=0,"0",F9/-F10) -> 3.4525691 | H11: R-to-R Ratio | I11: =IF(I5=0,"0",I9/-I10) -> 7.6539301 | K11: R-to-R Ratio | L11: =IF(L5=0,"0",L9/-L10) -> 0 | N11: R-to-R Ratio | O11: =IF(O5=0,"0",O9/-O10) -> 0
B12: Expectancy % | C12: =(C11*C7)-C8 -> 0.69660886 | E12: Expectancy % | F12: =(F11*F7)-F8 -> 0.60292489 | H12: Expectancy % | I12: =(I11*I7)-I8 -> 2.4615721 | K12: Expectancy % | L12: =(L11*L7)-L8 -> 0 | N12: Expectancy % | O12: =(O11*O7)-O8 -> 0
B13: Kelly % | C13: =IF(C12=0,"0",C7-(C8/C11)) -> 0.1920559 | E13: Kelly % | F13: =IF(F12=0,"0",F7-(F8/F11)) -> 0.17463079 | H13: Kelly % | I13: =IF(I12=0,"0",I7-(I8/I11)) -> 0.3216089 | K13: Kelly % | L13: =IF(L12=0,"0",L7-(L8/L11)) -> 0 | N13: Kelly % | O13: =IF(O12=0,"0",O7-(O8/O11)) -> 0
B14: Breakeven % | C14: =C8/C7 -> 1.7272727 | E14: Breakeven % | F14: =F8/F7 -> 1.7777778 | H14: Breakeven % | I14: =I8/I7 -> 1.5 | K14: Breakeven % | L14: =IF(OR(L7=0,L7="0"),0,L8/L7) -> 0 | N14: Breakeven % | O14: =IF(OR(O7=0,O7="0"),0,O8/O7) -> 0
B16: Net Gains | C16: =SUMIF('Trade Log 2026'!W2:W101,">0") -> 5199.71 | E16: Net Gains | F16: =SUMIF('Trade Log 2026'!W2:W26,">0") -> 4568.72 | H16: Net Gains | I16: =SUMIF('Trade Log 2026'!W27:W51,">0") -> 630.99 | K16: Net Gains | L16: =SUMIF('Trade Log 2026'!W52:W76,">0") -> 0 | N16: Net Gains | O16: =SUMIF('Trade Log 2026'!W77:W101,">0") -> 0
B17: Net Losses | C17: =SUMIF('Trade Log 2026'!W2:W101,"<0") -> -2476.16 | E17: Net Losses | F17: =SUMIF('Trade Log 2026'!W2:W26,"<0") -> -2352.5 | H17: Net Losses | I17: =SUMIF('Trade Log 2026'!W27:W51,"<0") -> -123.66 | K17: Net Losses | L17: =SUMIF('Trade Log 2026'!W52:W76,"<0") -> 0 | N17: Net Losses | O17: =SUMIF('Trade Log 2026'!W77:W101,"<0") -> 0
B18: Net Profit/Loss | C18: =C16+C17 -> 2723.55 | E18: Net Profit/Loss | F18: =F16+F17 -> 2216.22 | H18: Net Profit/Loss | I18: =I16+I17 -> 507.33 | K18: Net Profit/Loss | L18: =L16+L17 -> 0 | N18: Net Profit/Loss | O18: =O16+O17 -> 0
B20: Contextual Info: | E20: Contextual Info: | H20: Contextual Info: | K20: Contextual Info: | N20: Contextual Info:
B22: Beginning Equity | C22: =IF(F22="","",AVERAGE(F22,I22,L22,O22)) -> 35000 | E22: Beginning Equity | F22: 35000 | H22: Beginning Equity | I22: 35000 | K22: Beginning Equity | L22: 35000 | N22: Beginning Equity | O22: 35000
B23: Trade Risk % | C23: 0.015 | E23: Trade Risk % | F23: 0.015 | H23: Trade Risk % | I23: 0.015 | K23: Trade Risk % | L23: 0.015 | N23: Trade Risk % | O23: 0.015
B24: Risk per Trade | C24: =AVERAGE(F24,I24,L24,O24) -> 525 | E24: Risk per Trade | F24: =IF(F22="","",F22*F23) -> 525 | H24: Risk per Trade | I24: =IF(I22="","",I22*I23) -> 525 | K24: Risk per Trade | L24: =IF(L22="","",L22*L23) -> 525 | N24: Risk per Trade | O24: =IF(O22="","",O22*O23) -> 525
B25: Loss-to-Risk Ratio | C25: =IFERROR(IF(F25=0,F25,IF(I25=0,F25,IF(L25=0,AVERAGE(F25,I25),IF(O25=0,AVERAGE(F25,I25,L25),AVERAGE(F25,I25,L25,O25))))),0) -> 0.1792869 | E25: Loss-to-Risk Ratio | F25: =IF(F6=0,0,F10/F24*-1) -> 0.28005952 | H25: Loss-to-Risk Ratio | I25: =IF(OR(I6=0,I24="",I24=0),0,I10/I24*-1) -> 0.078514286 | K25: Loss-to-Risk Ratio | L25: =IF(OR(L6=0,L24="",L24=0),0,L10/L24*-1) -> 0 | N25: Loss-to-Risk Ratio | O25: =IF(OR(O6=0,O24="",O24=0),0,O10/O24*-1) -> 0
B26: Avg. Days in Winners | C26: =IF(C5=0,0,AVERAGEIF('Trade Log 2026'!W2:W101,">0",('Trade Log 2026'!U2:U101))) -> 3.0909091 | E26: Avg. Days in Winners | F26: =IF(F5=0,0,AVERAGEIF('Trade Log 2026'!W2:W26,">0",('Trade Log 2026'!U2:U26))) -> 2 | H26: Avg. Days in Winners | I26: =IF(I4=0,0,AVERAGEIF('Trade Log 2026'!W27:W51,">0",('Trade Log 2026'!U27:U51))) -> 8 | K26: Avg. Days in Winners | L26: =IF(L4=0,0,AVERAGEIF('Trade Log 2026'!W52:W76,">0",('Trade Log 2026'!U52:U76))) -> 0 | N26: Avg. Days in Winners | O26: =IF(O4=0,0,AVERAGEIF('Trade Log 2026'!W77:W101,">0",('Trade Log 2026'!U77:U101))) -> 0
B27: Avg. Days in Losers | C27: =IF(C6=0,F27,AVERAGEIF('Trade Log 2026'!W2:W101,"<0",('Trade Log 2026'!U2:U101))) -> 1.125 | E27: Avg. Days in Losers | F27: =IF(F6=0,F6,AVERAGEIF('Trade Log 2026'!W2:W26,"<0",('Trade Log 2026'!U2:U26))) -> 1.2857143 | H27: Avg. Days in Losers | I27: =IF(I6=0,0,AVERAGEIF('Trade Log 2026'!W27:W51,"<0",('Trade Log 2026'!U27:U51))) -> 0 | K27: Avg. Days in Losers | L27: =IF(L6=0,0,AVERAGEIF('Trade Log 2026'!W52:W76,"<0",('Trade Log 2026'!U52:U76))) -> 0 | N27: Avg. Days in Losers | O27: =IF(O6=0,0,AVERAGEIF('Trade Log 2026'!W77:W101,"<0",('Trade Log 2026'!U77:U101))) -> 0
B28: Days after Scale out | C28: =IF(C4=0,0,AVERAGE('Trade Log 2026'!U2:U101)) -> 1.9259259 | E28: Days after Scale out | F28: =IF(F4=0,0,AVERAGE('Trade Log 2026'!U2:U26)) -> 1.5652174 | H28: Days after Scale out | I28: {=IF(OR(I4=0, I4=""), "", IFERROR(ROUND(AVERAGE(_xlfn._xlws.FILTER(INDEX(TableLog[],,17), (ROW(TableLog[Symbol])-ROW(TableLog[#Headers])>=26)*(ROW(TableLog[Symbol])-ROW(TableLog[#Headers])<=50)*ISNUMBER(INDEX(TableLog[],,17)))), 2), ""))} -> 4 | K28: Days after Scale out | L28: =IF(L4=0,0,AVERAGE('Trade Log 2026'!U52:U76)) -> 0 | N28: Days after Scale out | O28: =IF(O4=0,0,AVERAGE('Trade Log 2026'!U77:U101)) -> 0
B29: Net Return % | C29: =IF(C4=0,0,C18/C22) -> 0.077815714 | E29: Net Return % | F29: =IF(F4=0,0,F18/F22) -> 0.063320571 | H29: Net Return % | I29: =IF(OR(I4=0,I22="",I22=0),0,I18/I22) -> 0.014495143 | K29: Net Return % | L29: =IF(OR(L4=0,L22="",L22=0),0,L18/L22) -> 0 | N29: Net Return % | O29: =IF(OR(O4=0,O22="",O22=0),0,O18/O22) -> 0
B30: Beginning Date | C30: =IF('Trade Log 2026'!G2="","",'Trade Log 2026'!G2) -> 46071 | E30: Beginning Date | F30: =IF('Trade Log 2026'!G2="","",'Trade Log 2026'!G2) -> 46071 | H30: Beginning Date | I30: =IF('Trade Log 2026'!G27="","",'Trade Log 2026'!G27) -> 46058 | K30: Beginning Date | L30: =IF('Trade Log 2026'!G52="","",'Trade Log 2026'!G52) | N30: Beginning Date | O30: =IF('Trade Log 2026'!G77="","",'Trade Log 2026'!G77)
B31: End Date | C31: =IF('Trade Log 2026'!L101="","Last 101 Trade",'Trade Log 2026'!L101) -> Last 101 Trade | E31: End Date | F31: =IF('Trade Log 2026'!L26="","",IF('Trade Log 2026'!P26="",'Trade Log 2026'!L26,IF('Trade Log 2026'!T26="",'Trade Log 2026'!P26,'Trade Log 2026'!T26))) -> 46052 | H31: End Date | I31: =IF('Trade Log 2026'!L51="","",IF('Trade Log 2026'!P51="",'Trade Log 2026'!L51,IF('Trade Log 2026'!T51="",'Trade Log 2026'!P51,'Trade Log 2026'!T51))) | K31: End Date | L31: =IF('Trade Log 2026'!L76="","",IF('Trade Log 2026'!P76="",'Trade Log 2026'!L76,IF('Trade Log 2026'!T76="",'Trade Log 2026'!P76,'Trade Log 2026'!T76))) | N31: End Date | O31: =IF('Trade Log 2026'!L101="","",IF('Trade Log 2026'!P101="",'Trade Log 2026'!L101,IF('Trade Log 2026'!T101="",'Trade Log 2026'!P101,'Trade Log 2026'!T101)))
B33: Edited by Steven Daigle 30Sep2024
B35: For the Dashboard to function correctly, one must fill in the gray boxes with their beginning equity and trade risk %.
B36: I still need to work on the End Date formula. Everything else has been checked.
B37: I am working on a complete narrative to explain what these terms mean and how one should evaluate them to improve ones trading plan.
B38: If one finds an error or has a question, please send me a message under members in Circle.
