Workbook

Sheet Trade Log
A1: Symbol | B1: System | C1: Long/Short | D1: Trade Date | E1: Entry Price | F1: Shares | G1: Exit #1 | H1: # Exited | I1: Exit Date | J1: # of Days | K1: Exit #2 | L1: # Exited2 | M1: Exit Date3 | N1: # of Days4 | O1: Comm. | P1: Gain/Loss | Q1: ROI | R1: Trade Comments | S1: Exit #1 Gain | T1: Exit #2 Gain | U1: Total Gain | V1: Total ROI % | W1: R:R Ratio | X1: Win/Loss | Y1: Strategy Notes | Z1: Review Status
A2: ATMU | B2: VP_Grok | C2: Long | D2: 45965 | E2: 45.36 | F2: 287 | G2: 50.26 | H2: 287 | I2: 45968 | J2: =IF(I2="","",I2-D2) -> 3 | N2: =IF(M2="","",M2-I2) | P2: =IF(OR($F2=0, SUM($H2, $L2)<$F2), "", IF($C2="Long", (IFERROR($G2*$H2,0) + IFERROR($K2*$L2,0)) - ($E2*$F2), ($E2*$F2) - (IFERROR($G2*$H2,0) + IFERROR($K2*$L2,0))) - IFERROR($O2,0)) -> 1406.3 | Q2: =IF(P2="", "", P2 / ($E2 * $F2)) -> 0.10802469 | S2: =IF(C2="Long",((G2-E2)*H2),((E2-G2)*H2)) -> 1406.3 | T2: =IF(C2="Long",((K2-E2)*L2),((E2-K2)*L2)) -> 0 | V2: Long
A3: VDNA | B3: VP_Grok | C3: Short | D3: 45965 | E3: 4.4 | F3: 100 | G3: 4.37 | H3: 100 | I3: 45968 | J3: =IF(I3="","",I3-D3) -> 3 | N3: =IF(M3="","",M3-I3) | P3: =IF(OR($F3=0, SUM($H3, $L3)<$F3), "", IF($C3="Long", (IFERROR($G3*$H3,0) + IFERROR($K3*$L3,0)) - ($E3*$F3), ($E3*$F3) - (IFERROR($G3*$H3,0) + IFERROR($K3*$L3,0))) - IFERROR($O3,0)) -> 3 | Q3: =IF(P3="", "", P3 / ($E3 * $F3)) -> 0.0068181818 | S3: =IF(C3="Long",((G3-E3)*H3),((E3-G3)*H3)) -> 3 | T3: =IF(C3="Long",((K3-E3)*L3),((E3-K3)*L3)) -> 0 | V3: Short
A4: ATMU | B4: VP_Grok | C4: Long | D4: 45965 | E4: 45.36 | F4: 287 | G4: 50.26 | H4: 287 | I4: 45968 | J4: =IF(I4="","",I4-D4) -> 3 | N4: =IF(M4="","",M4-I4) | P4: =IF(OR($F4=0, SUM($H4, $L4)<$F4), "", IF($C4="Long", (IFERROR($G4*$H4,0) + IFERROR($K4*$L4,0)) - ($E4*$F4), ($E4*$F4) - (IFERROR($G4*$H4,0) + IFERROR($K4*$L4,0))) - IFERROR($O4,0)) -> 1406.3 | Q4: =IF(P4="", "", P4 / ($E4 * $F4)) -> 0.10802469 | S4: =IF(C4="Long",((G4-E4)*H4),((E4-G4)*H4)) -> 1406.3 | T4: =IF(C4="Long",((K4-E4)*L4),((E4-K4)*L4)) -> 0
A5: MS | B5: VP_Grok | C5: Long | D5: 45971 | E5: 165.02 | F5: 100 | G5: 169.08 | H5: 100 | I5: 45973 | J5: =IF(I5="","",I5-D5) -> 2 | N5: =IF(M5="","",M5-I5) | P5: =IF(OR($F5=0, SUM($H5, $L5)<$F5), "", IF($C5="Long", (IFERROR($G5*$H5,0) + IFERROR($K5*$L5,0)) - ($E5*$F5), ($E5*$F5) - (IFERROR($G5*$H5,0) + IFERROR($K5*$L5,0))) - IFERROR($O5,0)) -> 406 | Q5: =IF(P5="", "", P5 / ($E5 * $F5)) -> 0.024603078 | S5: =IF(C5="Long",((G5-E5)*H5),((E5-G5)*H5)) -> 406 | T5: =IF(C5="Long",((K5-E5)*L5),((E5-K5)*L5)) -> 0
A6: PLTR | B6: VP_Grok | C6: Long | D6: 45971 | E6: 193.67 | F6: 36 | G6: 194 | H6: 36 | I6: 45971 | J6: =IF(I6="","",I6-D6) -> 0 | N6: =IF(M6="","",M6-I6) | P6: =IF(OR($F6=0, SUM($H6, $L6)<$F6), "", IF($C6="Long", (IFERROR($G6*$H6,0) + IFERROR($K6*$L6,0)) - ($E6*$F6), ($E6*$F6) - (IFERROR($G6*$H6,0) + IFERROR($K6*$L6,0))) - IFERROR($O6,0)) -> 11.88 | Q6: =IF(P6="", "", P6 / ($E6 * $F6)) -> 0.0017039294 | R6: TrailStop | S6: =IF(C6="Long",((G6-E6)*H6),((E6-G6)*H6)) -> 11.88 | T6: =IF(C6="Long",((K6-E6)*L6),((E6-K6)*L6)) -> 0
A7: SKYT | B7: VP_Grok | C7: Long | D7: 45971 | E7: 23.56 | F7: 240 | G7: 24 | H7: 240 | I7: 45971 | J7: =IF(I7="","",I7-D7) -> 0 | N7: =IF(M7="","",M7-I7) | P7: =IF(OR($F7=0, SUM($H7, $L7)<$F7), "", IF($C7="Long", (IFERROR($G7*$H7,0) + IFERROR($K7*$L7,0)) - ($E7*$F7), ($E7*$F7) - (IFERROR($G7*$H7,0) + IFERROR($K7*$L7,0))) - IFERROR($O7,0)) -> 105.6 | Q7: =IF(P7="", "", P7 / ($E7 * $F7)) -> 0.018675722 | S7: =IF(C7="Long",((G7-E7)*H7),((E7-G7)*H7)) -> 105.6 | T7: =IF(C7="Long",((K7-E7)*L7),((E7-K7)*L7)) -> 0
A8: BBAI | B8: VP_Grok | C8: Long | D8: 45973 | E8: 7.14 | F8: 200 | G8: 6.35 | H8: 200 | I8: 45974 | J8: =IF(I8="","",I8-D8) -> 1 | N8: =IF(M8="","",M8-I8) | P8: =IF(OR($F8=0, SUM($H8, $L8)<$F8), "", IF($C8="Long", (IFERROR($G8*$H8,0) + IFERROR($K8*$L8,0)) - ($E8*$F8), ($E8*$F8) - (IFERROR($G8*$H8,0) + IFERROR($K8*$L8,0))) - IFERROR($O8,0)) -> -158 | Q8: =IF(P8="", "", P8 / ($E8 * $F8)) -> -0.11064426 | S8: =IF(C8="Long",((G8-E8)*H8),((E8-G8)*H8)) -> -158 | T8: =IF(C8="Long",((K8-E8)*L8),((E8-K8)*L8)) -> 0
A9: BTU | B9: VP_Grok | C9: Long | D9: 45973 | E9: 30.18 | F9: 362 | G9: 29.34 | H9: 362 | I9: 45974 | J9: =IF(I9="","",I9-D9) -> 1 | N9: =IF(M9="","",M9-I9) | P9: =IF(OR($F9=0, SUM($H9, $L9)<$F9), "", IF($C9="Long", (IFERROR($G9*$H9,0) + IFERROR($K9*$L9,0)) - ($E9*$F9), ($E9*$F9) - (IFERROR($G9*$H9,0) + IFERROR($K9*$L9,0))) - IFERROR($O9,0)) -> -304.08 | Q9: =IF(P9="", "", P9 / ($E9 * $F9)) -> -0.027833002 | S9: =IF(C9="Long",((G9-E9)*H9),((E9-G9)*H9)) -> -304.08 | T9: =IF(C9="Long",((K9-E9)*L9),((E9-K9)*L9)) -> 0
A10: CTVA | B10: VP_Grok | C10: Long | D10: 45973 | E10: 66.75 | F10: 324 | G10: 65.13 | H10: 324 | I10: 45978 | J10: =IF(I10="","",I10-D10) -> 5 | N10: =IF(M10="","",M10-I10) | P10: =IF(OR($F10=0, SUM($H10, $L10)<$F10), "", IF($C10="Long", (IFERROR($G10*$H10,0) + IFERROR($K10*$L10,0)) - ($E10*$F10), ($E10*$F10) - (IFERROR($G10*$H10,0) + IFERROR($K10*$L10,0))) - IFERROR($O10,0)) -> -524.88 | Q10: =IF(P10="", "", P10 / ($E10 * $F10)) -> -0.024269663 | S10: =IF(C10="Long",((G10-E10)*H10),((E10-G10)*H10)) -> -524.88 | T10: =IF(C10="Long",((K10-E10)*L10),((E10-K10)*L10)) -> 0
A11: KVUE | B11: VP_Grok | C11: Long | D11: 45973 | E11: 16.84 | F11: 729 | G11: 16.12 | H11: 729 | I11: 45978 | J11: =IF(I11="","",I11-D11) -> 5 | N11: =IF(M11="","",M11-I11) | P11: =IF(OR($F11=0, SUM($H11, $L11)<$F11), "", IF($C11="Long", (IFERROR($G11*$H11,0) + IFERROR($K11*$L11,0)) - ($E11*$F11), ($E11*$F11) - (IFERROR($G11*$H11,0) + IFERROR($K11*$L11,0))) - IFERROR($O11,0)) -> -524.88 | Q11: =IF(P11="", "", P11 / ($E11 * $F11)) -> -0.042755344 | S11: =IF(C11="Long",((G11-E11)*H11),((E11-G11)*H11)) -> -524.88 | T11: =IF(C11="Long",((K11-E11)*L11),((E11-K11)*L11)) -> 0
A12: LMT | B12: VP_Grok | C12: Long | D12: 45980 | E12: 471.76 | F12: 50 | G12: 481.94 | H12: 50 | I12: 45985 | J12: =IF(I12="","",I12-D12) -> 5 | N12: =IF(M12="","",M12-I12) | P12: =IF(OR($F12=0, SUM($H12, $L12)<$F12), "", IF($C12="Long", (IFERROR($G12*$H12,0) + IFERROR($K12*$L12,0)) - ($E12*$F12), ($E12*$F12) - (IFERROR($G12*$H12,0) + IFERROR($K12*$L12,0))) - IFERROR($O12,0)) -> 509 | Q12: =IF(P12="", "", P12 / ($E12 * $F12)) -> 0.021578769 | S12: =IF(C12="Long",((G12-E12)*H12),((E12-G12)*H12)) -> 509 | T12: =IF(C12="Long",((K12-E12)*L12),((E12-K12)*L12)) -> 0
A13: FIZZ | B13: VP_Grok | C13: Long | D13: 45980 | E13: 33.54 | F13: 108 | G13: 34.91 | H13: 108 | I13: 45992 | J13: =IF(I13="","",I13-D13) -> 12 | N13: =IF(M13="","",M13-I13) | P13: =IF(OR($F13=0, SUM($H13, $L13)<$F13), "", IF($C13="Long", (IFERROR($G13*$H13,0) + IFERROR($K13*$L13,0)) - ($E13*$F13), ($E13*$F13) - (IFERROR($G13*$H13,0) + IFERROR($K13*$L13,0))) - IFERROR($O13,0)) -> 147.96 | Q13: =IF(P13="", "", P13 / ($E13 * $F13)) -> 0.04084675 | S13: =IF(C13="Long",((G13-E13)*H13),((E13-G13)*H13)) -> 147.96 | T13: =IF(C13="Long",((K13-E13)*L13),((E13-K13)*L13)) -> 0
A14: MUSA | B14: VP_Grok | C14: Long | D14: 45980 | E14: 368.57 | F14: 28 | G14: 397.42 | H14: 28 | I14: 45999 | J14: =IF(I14="","",I14-D14) -> 19 | N14: =IF(M14="","",M14-I14) | P14: =IF(OR($F14=0, SUM($H14, $L14)<$F14), "", IF($C14="Long", (IFERROR($G14*$H14,0) + IFERROR($K14*$L14,0)) - ($E14*$F14), ($E14*$F14) - (IFERROR($G14*$H14,0) + IFERROR($K14*$L14,0))) - IFERROR($O14,0)) -> 807.8 | Q14: =IF(P14="", "", P14 / ($E14 * $F14)) -> 0.078275497 | S14: =IF(C14="Long",((G14-E14)*H14),((E14-G14)*H14)) -> 807.8 | T14: =IF(C14="Long",((K14-E14)*L14),((E14-K14)*L14)) -> 0
A15: ASGN | B15: VP_Grok | C15: Long | D15: 45986 | E15: 45.95 | F15: 10 | G15: 48.42 | H15: 10 | I15: 46010 | J15: =IF(I15="","",I15-D15) -> 24 | N15: =IF(M15="","",M15-I15) | P15: =IF(OR($F15=0, SUM($H15, $L15)<$F15), "", IF($C15="Long", (IFERROR($G15*$H15,0) + IFERROR($K15*$L15,0)) - ($E15*$F15), ($E15*$F15) - (IFERROR($G15*$H15,0) + IFERROR($K15*$L15,0))) - IFERROR($O15,0)) -> 24.7 | Q15: =IF(P15="", "", P15 / ($E15 * $F15)) -> 0.053754081 | S15: =IF(C15="Long",((G15-E15)*H15),((E15-G15)*H15)) -> 24.7 | T15: =IF(C15="Long",((K15-E15)*L15),((E15-K15)*L15)) -> 0
A16: WEN | B16: VP_Grok | C16: Long | D16: 45992 | E16: 8.22 | F16: 500 | G16: 8.21 | H16: 500 | I16: 45993 | J16: =IF(I16="","",I16-D16) -> 1 | N16: =IF(M16="","",M16-I16) | P16: =IF(OR($F16=0, SUM($H16, $L16)<$F16), "", IF($C16="Long", (IFERROR($G16*$H16,0) + IFERROR($K16*$L16,0)) - ($E16*$F16), ($E16*$F16) - (IFERROR($G16*$H16,0) + IFERROR($K16*$L16,0))) - IFERROR($O16,0)) -> -5 | Q16: =IF(P16="", "", P16 / ($E16 * $F16)) -> -0.001216545 | S16: =IF(C16="Long",((G16-E16)*H16),((E16-G16)*H16)) -> -5 | T16: =IF(C16="Long",((K16-E16)*L16),((E16-K16)*L16)) -> 0
A17: WEN | B17: VP_Grok | C17: Long | D17: 45992 | E17: 8.22 | F17: 500 | G17: 8.01 | H17: 500 | I17: 45993 | J17: =IF(I17="","",I17-D17) -> 1 | N17: =IF(M17="","",M17-I17) | P17: =IF(OR($F17=0, SUM($H17, $L17)<$F17), "", IF($C17="Long", (IFERROR($G17*$H17,0) + IFERROR($K17*$L17,0)) - ($E17*$F17), ($E17*$F17) - (IFERROR($G17*$H17,0) + IFERROR($K17*$L17,0))) - IFERROR($O17,0)) -> -105 | Q17: =IF(P17="", "", P17 / ($E17 * $F17)) -> -0.025547445 | S17: =IF(C17="Long",((G17-E17)*H17),((E17-G17)*H17)) -> -105 | T17: =IF(C17="Long",((K17-E17)*L17),((E17-K17)*L17)) -> 0
A18: CNDT | B18: VP_Grok | C18: Long | D18: 45993 | E18: 1.92 | F18: 5000 | G18: 1.87 | H18: 5000 | I18: 45994 | J18: =IF(I18="","",I18-D18) -> 1 | N18: =IF(M18="","",M18-I18) | P18: =IF(OR($F18=0, SUM($H18, $L18)<$F18), "", IF($C18="Long", (IFERROR($G18*$H18,0) + IFERROR($K18*$L18,0)) - ($E18*$F18), ($E18*$F18) - (IFERROR($G18*$H18,0) + IFERROR($K18*$L18,0))) - IFERROR($O18,0)) -> -250 | Q18: =IF(P18="", "", P18 / ($E18 * $F18)) -> -0.026041667 | S18: =IF(C18="Long",((G18-E18)*H18),((E18-G18)*H18)) -> -250 | T18: =IF(C18="Long",((K18-E18)*L18),((E18-K18)*L18)) -> 0
... A21: GLP1 | B21: VP_Grok | C21: Long | D21: 45996 | E21: 43.8 | F21: 200 | G21: 43.79 | H21: 200 | I21: 45993 | J21: =IF(I21="","",I21-D21) -> -3 | N21: =IF(M21="","",M21-I21) | P21: =IF(OR($F21=0, SUM($H21, $L21)<$F21), "", IF($C21="Long", (IFERROR($G21*$H21,0) + IFERROR($K21*$L21,0)) - ($E21*$F21), ($E21*$F21) - (IFERROR($G21*$H21,0) + IFERROR($K21*$L21,0))) - IFERROR($O21,0)) -> -2 | Q21: =IF(P21="", "", P21 / ($E21 * $F21)) -> -0.0002283105 | S21: =IF(C21="Long",((G21-E21)*H21),((E21-G21)*H21)) -> -2 | T21: =IF(C21="Long",((K21-E21)*L21),((E21-K21)*L21)) -> 0
A22: ITGR | B22: P_115 | C22: Long | D22: 46010 | E22: 77.7 | F22: 4 | J22: =IF(I22="","",I22-D22) | N22: =IF(M22="","",M22-I22) | P22: =IF(OR($F22=0, SUM($H22, $L22)<$F22), "", IF($C22="Long", (IFERROR($G22*$H22,0) + IFERROR($K22*$L22,0)) - ($E22*$F22), ($E22*$F22) - (IFERROR($G22*$H22,0) + IFERROR($K22*$L22,0))) - IFERROR($O22,0)) | Q22: =IF(P22="", "", P22 / ($E22 * $F22)) | S22: =IF(C22="Long",((G22-E22)*H22),((E22-G22)*H22)) -> 0 | T22: =IF(C22="Long",((K22-E22)*L22),((E22-K22)*L22)) -> 0
A23: SOC | B23: P_115 | C23: Long | D23: 46010 | E23: 8.37 | F23: 11 | G23: 10.59 | H23: 11 | I23: 46014 | J23: =IF(I23="","",I23-D23) -> 4 | N23: =IF(M23="","",M23-I23) | P23: =IF(OR($F23=0, SUM($H23, $L23)<$F23), "", IF($C23="Long", (IFERROR($G23*$H23,0) + IFERROR($K23*$L23,0)) - ($E23*$F23), ($E23*$F23) - (IFERROR($G23*$H23,0) + IFERROR($K23*$L23,0))) - IFERROR($O23,0)) -> 24.42 | Q23: =IF(P23="", "", P23 / ($E23 * $F23)) -> 0.26523297 | S23: =IF(C23="Long",((G23-E23)*H23),((E23-G23)*H23)) -> 24.42 | T23: =IF(C23="Long",((K23-E23)*L23),((E23-K23)*L23)) -> 0
A24: SPSC | B24: P_115 | C24: Long | D24: 46010 | E24: 90.94 | F24: 6 | J24: =IF(I24="","",I24-D24) | N24: =IF(M24="","",M24-I24) | P24: =IF(OR($F24=0, SUM($H24, $L24)<$F24), "", IF($C24="Long", (IFERROR($G24*$H24,0) + IFERROR($K24*$L24,0)) - ($E24*$F24), ($E24*$F24) - (IFERROR($G24*$H24,0) + IFERROR($K24*$L24,0))) - IFERROR($O24,0)) | Q24: =IF(P24="", "", P24 / ($E24 * $F24)) | S24: =IF(C24="Long",((G24-E24)*H24),((E24-G24)*H24)) -> 0 | T24: =IF(C24="Long",((K24-E24)*L24),((E24-K24)*L24)) -> 0
A25: EGY | B25: VP_GROK | C25: Long | D25: 45995 | E25: 3.63 | F25: 16 | G25: 3.43 | H25: 16 | I25: 46007 | J25: =IF(I25="","",I25-D25) -> 12 | N25: =IF(M25="","",M25-I25) | P25: =IF(OR($F25=0, SUM($H25, $L25)<$F25), "", IF($C25="Long", (IFERROR($G25*$H25,0) + IFERROR($K25*$L25,0)) - ($E25*$F25), ($E25*$F25) - (IFERROR($G25*$H25,0) + IFERROR($K25*$L25,0))) - IFERROR($O25,0)) -> -3.2 | Q25: =IF(P25="", "", P25 / ($E25 * $F25)) -> -0.055096419 | S25: =IF(C25="Long",((G25-E25)*H25),((E25-G25)*H25)) -> -3.2 | T25: =IF(C25="Long",((K25-E25)*L25),((E25-K25)*L25)) -> 0
A26: AUPH | B26: D_102 | C26: Long | D26: 45995 | E26: 14.88 | F26: 100 | G26: 15.37 | H26: 100 | I26: 46002 | J26: =IF(I26="","",I26-D26) -> 7 | N26: =IF(M26="","",M26-I26) | P26: =IF(OR($F26=0, SUM($H26, $L26)<$F26), "", IF($C26="Long", (IFERROR($G26*$H26,0) + IFERROR($K26*$L26,0)) - ($E26*$F26), ($E26*$F26) - (IFERROR($G26*$H26,0) + IFERROR($K26*$L26,0))) - IFERROR($O26,0)) -> 49 | Q26: =IF(P26="", "", P26 / ($E26 * $F26)) -> 0.032930108 | S26: =IF(C26="Long",((G26-E26)*H26),((E26-G26)*H26)) -> 49 | T26: =IF(C26="Long",((K26-E26)*L26),((E26-K26)*L26)) -> 0
A27: GLPI | B27: VP_Grok | C27: Long | D27: 45995 | E27: 43.8 | F27: 200 | G27: 43.79 | H27: 100 | I27: 45995 | J27: =IF(I27="","",I27-D27) -> 0 | N27: =IF(M27="","",M27-I27) | P27: =IF(OR($F27=0, SUM($H27, $L27)<$F27), "", IF($C27="Long", (IFERROR($G27*$H27,0) + IFERROR($K27*$L27,0)) - ($E27*$F27), ($E27*$F27) - (IFERROR($G27*$H27,0) + IFERROR($K27*$L27,0))) - IFERROR($O27,0)) | Q27: =IF(P27="", "", P27 / ($E27 * $F27)) | S27: =IF(C27="Long",((G27-E27)*H27),((E27-G27)*H27)) -> -1 | T27: =IF(C27="Long",((K27-E27)*L27),((E27-K27)*L27)) -> 0
A28: BB | B28: VP_Grok | C28: Long | D28: 45996 | E28: 4.24 | F28: 200 | G28: 3.98 | H28: 200 | I28: 46010 | J28: =IF(I28="","",I28-D28) -> 14 | N28: =IF(M28="","",M28-I28) | P28: =IF(OR($F28=0, SUM($H28, $L28)<$F28), "", IF($C28="Long", (IFERROR($G28*$H28,0) + IFERROR($K28*$L28,0)) - ($E28*$F28), ($E28*$F28) - (IFERROR($G28*$H28,0) + IFERROR($K28*$L28,0))) - IFERROR($O28,0)) -> -52 | Q28: =IF(P28="", "", P28 / ($E28 * $F28)) -> -0.061320755 | S28: =IF(C28="Long",((G28-E28)*H28),((E28-G28)*H28)) -> -52 | T28: =IF(C28="Long",((K28-E28)*L28),((E28-K28)*L28)) -> 0
A29: CALM | B29: VP_GROK | C29: Long | D29: 45996 | E29: 85.44 | F29: 20 | G29: 81.45 | H29: 20 | I29: 46020 | J29: =IF(I29="","",I29-D29) -> 24 | N29: =IF(M29="","",M29-I29) | P29: =IF(OR($F29=0, SUM($H29, $L29)<$F29), "", IF($C29="Long", (IFERROR($G29*$H29,0) + IFERROR($K29*$L29,0)) - ($E29*$F29), ($E29*$F29) - (IFERROR($G29*$H29,0) + IFERROR($K29*$L29,0))) - IFERROR($O29,0)) -> -79.8 | Q29: =IF(P29="", "", P29 / ($E29 * $F29)) -> -0.046699438 | R29: =SUM('Trade Log'!$P$2:$P$96) -> 2634.23 | S29: =IF(C29="Long",((G29-E29)*H29),((E29-G29)*H29)) -> -79.8 | T29: =IF(C29="Long",((K29-E29)*L29),((E29-K29)*L29)) -> 0
A30: ARKB | B30: VP_Grok | C30: Long | D30: 45996 | E30: 30.04 | F30: 100 | G30: 28.9 | H30: 100 | I30: 46006 | J30: =IF(I30="","",I30-D30) -> 10 | N30: =IF(M30="","",M30-I30) | P30: =IF(OR($F30=0, SUM($H30, $L30)<$F30), "", IF($C30="Long", (IFERROR($G30*$H30,0) + IFERROR($K30*$L30,0)) - ($E30*$F30), ($E30*$F30) - (IFERROR($G30*$H30,0) + IFERROR($K30*$L30,0))) - IFERROR($O30,0)) -> -114 | Q30: =IF(P30="", "", P30 / ($E30 * $F30)) -> -0.037949401 | S30: =IF(C30="Long",((G30-E30)*H30),((E30-G30)*H30)) -> -114 | T30: =IF(C30="Long",((K30-E30)*L30),((E30-K30)*L30)) -> 0
A31: STX | B31: P_118 | C31: Long | D31: 45999 | E31: 283.67 | F31: 10 | G31: 298.63 | H31: 10 | I31: 46001 | J31: =IF(I31="","",I31-D31) -> 2 | N31: =IF(M31="","",M31-I31) | P31: =IF(OR($F31=0, SUM($H31, $L31)<$F31), "", IF($C31="Long", (IFERROR($G31*$H31,0) + IFERROR($K31*$L31,0)) - ($E31*$F31), ($E31*$F31) - (IFERROR($G31*$H31,0) + IFERROR($K31*$L31,0))) - IFERROR($O31,0)) -> 149.6 | Q31: =IF(P31="", "", P31 / ($E31 * $F31)) -> 0.052737336 | S31: =IF(C31="Long",((G31-E31)*H31),((E31-G31)*H31)) -> 149.6 | T31: =IF(C31="Long",((K31-E31)*L31),((E31-K31)*L31)) -> 0
A32: SANM | B32: P_118 | C32: Long | D32: 46000 | E32: 163.87 | F32: 10 | G32: 156.22 | H32: 10 | I32: 46007 | J32: =IF(I32="","",I32-D32) -> 7 | N32: =IF(M32="","",M32-I32) | P32: =IF(OR($F32=0, SUM($H32, $L32)<$F32), "", IF($C32="Long", (IFERROR($G32*$H32,0) + IFERROR($K32*$L32,0)) - ($E32*$F32), ($E32*$F32) - (IFERROR($G32*$H32,0) + IFERROR($K32*$L32,0))) - IFERROR($O32,0)) -> -76.5 | Q32: =IF(P32="", "", P32 / ($E32 * $F32)) -> -0.046683347 | S32: =IF(C32="Long",((G32-E32)*H32),((E32-G32)*H32)) -> -76.5 | T32: =IF(C32="Long",((K32-E32)*L32),((E32-K32)*L32)) -> 0
A33: RDW | B33: P_115 | C33: Long | D33: 46001 | E33: 7.27 | F33: 200 | G33: 6.57 | H33: 200 | I33: 46007 | J33: =IF(I33="","",I33-D33) -> 6 | N33: =IF(M33="","",M33-I33) | P33: =IF(OR($F33=0, SUM($H33, $L33)<$F33), "", IF($C33="Long", (IFERROR($G33*$H33,0) + IFERROR($K33*$L33,0)) - ($E33*$F33), ($E33*$F33) - (IFERROR($G33*$H33,0) + IFERROR($K33*$L33,0))) - IFERROR($O33,0)) -> -140 | Q33: =IF(P33="", "", P33 / ($E33 * $F33)) -> -0.096286107 | S33: =IF(C33="Long",((G33-E33)*H33),((E33-G33)*H33)) -> -140 | T33: =IF(C33="Long",((K33-E33)*L33),((E33-K33)*L33)) -> 0
A34: URBN | B34: P_118 | C34: Long | D34: 46002 | E34: 81.75 | F34: 100 | G34: 79.87 | H34: 100 | I34: 46014 | J34: =IF(I34="","",I34-D34) -> 12 | N34: =IF(M34="","",M34-I34) | P34: =IF(OR($F34=0, SUM($H34, $L34)<$F34), "", IF($C34="Long", (IFERROR($G34*$H34,0) + IFERROR($K34*$L34,0)) - ($E34*$F34), ($E34*$F34) - (IFERROR($G34*$H34,0) + IFERROR($K34*$L34,0))) - IFERROR($O34,0)) -> -188 | Q34: =IF(P34="", "", P34 / ($E34 * $F34)) -> -0.022996942 | S34: =IF(C34="Long",((G34-E34)*H34),((E34-G34)*H34)) -> -188 | T34: =IF(C34="Long",((K34-E34)*L34),((E34-K34)*L34)) -> 0
A35: AMTM | B35: P_118 | C35: Long | D35: 46002 | E35: 29.78 | F35: 300 | G35: 29.15 | H35: 300 | I35: 46006 | J35: =IF(I35="","",I35-D35) -> 4 | N35: =IF(M35="","",M35-I35) | P35: =IF(OR($F35=0, SUM($H35, $L35)<$F35), "", IF($C35="Long", (IFERROR($G35*$H35,0) + IFERROR($K35*$L35,0)) - ($E35*$F35), ($E35*$F35) - (IFERROR($G35*$H35,0) + IFERROR($K35*$L35,0))) - IFERROR($O35,0)) -> -189 | Q35: =IF(P35="", "", P35 / ($E35 * $F35)) -> -0.021155138 | S35: =IF(C35="Long",((G35-E35)*H35),((E35-G35)*H35)) -> -189 | T35: =IF(C35="Long",((K35-E35)*L35),((E35-K35)*L35)) -> 0
A36: RCUS | B36: D_102 | C36: Long | D36: 46003 | E36: 23.22 | F36: 50 | G36: 24.35 | H36: 50 | I36: 46037 | J36: =IF(I36="","",I36-D36) -> 34 | N36: =IF(M36="","",M36-I36) | P36: =IF(OR($F36=0, SUM($H36, $L36)<$F36), "", IF($C36="Long", (IFERROR($G36*$H36,0) + IFERROR($K36*$L36,0)) - ($E36*$F36), ($E36*$F36) - (IFERROR($G36*$H36,0) + IFERROR($K36*$L36,0))) - IFERROR($O36,0)) -> 56.5 | Q36: =IF(P36="", "", P36 / ($E36 * $F36)) -> 0.048664944 | S36: =IF(C36="Long",((G36-E36)*H36),((E36-G36)*H36)) -> 56.5 | T36: =IF(C36="Long",((K36-E36)*L36),((E36-K36)*L36)) -> 0
A37: CTOR | B37: D_102 | C37: Long | D37: 46010 | E37: 1.32 | F37: 5 | J37: =IF(I37="","",I37-D37) | N37: =IF(M37="","",M37-I37) | P37: =IF(OR($F37=0, SUM($H37, $L37)<$F37), "", IF($C37="Long", (IFERROR($G37*$H37,0) + IFERROR($K37*$L37,0)) - ($E37*$F37), ($E37*$F37) - (IFERROR($G37*$H37,0) + IFERROR($K37*$L37,0))) - IFERROR($O37,0)) | Q37: =IF(P37="", "", P37 / ($E37 * $F37)) | S37: =IF(C37="Long",((G37-E37)*H37),((E37-G37)*H37)) -> 0 | T37: =IF(C37="Long",((K37-E37)*L37),((E37-K37)*L37)) -> 0
A38: ASIX | B38: P_115 | C38: Long | D38: 46013 | E38: 16.62 | F38: 78 | G38: 18.43 | H38: 78 | I38: 46030 | J38: =IF(I38="","",I38-D38) -> 17 | N38: =IF(M38="","",M38-I38) | P38: =IF(OR($F38=0, SUM($H38, $L38)<$F38), "", IF($C38="Long", (IFERROR($G38*$H38,0) + IFERROR($K38*$L38,0)) - ($E38*$F38), ($E38*$F38) - (IFERROR($G38*$H38,0) + IFERROR($K38*$L38,0))) - IFERROR($O38,0)) -> 141.18 | Q38: =IF(P38="", "", P38 / ($E38 * $F38)) -> 0.10890493 | S38: =IF(C38="Long",((G38-E38)*H38),((E38-G38)*H38)) -> 141.18 | T38: =IF(C38="Long",((K38-E38)*L38),((E38-K38)*L38)) -> 0
A39: ITGR | B39: P_115 | C39: Long | D39: 46013 | E39: 78.5 | F39: 19 | J39: =IF(I39="","",I39-D39) | N39: =IF(M39="","",M39-I39) | P39: =IF(OR($F39=0, SUM($H39, $L39)<$F39), "", IF($C39="Long", (IFERROR($G39*$H39,0) + IFERROR($K39*$L39,0)) - ($E39*$F39), ($E39*$F39) - (IFERROR($G39*$H39,0) + IFERROR($K39*$L39,0))) - IFERROR($O39,0)) | Q39: =IF(P39="", "", P39 / ($E39 * $F39)) | S39: =IF(C39="Long",((G39-E39)*H39),((E39-G39)*H39)) -> 0 | T39: =IF(C39="Long",((K39-E39)*L39),((E39-K39)*L39)) -> 0
A40: NMAX | B40: P_115 | C40: Long | D40: 46013 | E40: 9.16 | F40: 93 | G40: 8.07 | H40: 93 | I40: 46021 | J40: =IF(I40="","",I40-D40) -> 8 | N40: =IF(M40="","",M40-I40) | P40: =IF(OR($F40=0, SUM($H40, $L40)<$F40), "", IF($C40="Long", (IFERROR($G40*$H40,0) + IFERROR($K40*$L40,0)) - ($E40*$F40), ($E40*$F40) - (IFERROR($G40*$H40,0) + IFERROR($K40*$L40,0))) - IFERROR($O40,0)) -> -101.37 | Q40: =IF(P40="", "", P40 / ($E40 * $F40)) -> -0.11899563 | S40: =IF(C40="Long",((G40-E40)*H40),((E40-G40)*H40)) -> -101.37 | T40: =IF(C40="Long",((K40-E40)*L40),((E40-K40)*L40)) -> 0
A41: WVE | B41: P_115 | C41: Long | D41: 46013 | J41: =IF(I41="","",I41-D41) | N41: =IF(M41="","",M41-I41) | P41: =IF(OR($F41=0, SUM($H41, $L41)<$F41), "", IF($C41="Long", (IFERROR($G41*$H41,0) + IFERROR($K41*$L41,0)) - ($E41*$F41), ($E41*$F41) - (IFERROR($G41*$H41,0) + IFERROR($K41*$L41,0))) - IFERROR($O41,0)) | Q41: =IF(P41="", "", P41 / ($E41 * $F41)) | S41: =IF(C41="Long",((G41-E41)*H41),((E41-G41)*H41)) -> 0 | T41: =IF(C41="Long",((K41-E41)*L41),((E41-K41)*L41)) -> 0
A42: GPK | B42: P_115 | C42: Long | D42: 46013 | J42: =IF(I42="","",I42-D42) | N42: =IF(M42="","",M42-I42) | P42: =IF(OR($F42=0, SUM($H42, $L42)<$F42), "", IF($C42="Long", (IFERROR($G42*$H42,0) + IFERROR($K42*$L42,0)) - ($E42*$F42), ($E42*$F42) - (IFERROR($G42*$H42,0) + IFERROR($K42*$L42,0))) - IFERROR($O42,0)) | Q42: =IF(P42="", "", P42 / ($E42 * $F42)) | S42: =IF(C42="Long",((G42-E42)*H42),((E42-G42)*H42)) -> 0 | T42: =IF(C42="Long",((K42-E42)*L42),((E42-K42)*L42)) -> 0
...

Sheet Dashboard
A1: v4.0
B2: Cumulative Results | E2: Trades 1-25 | H2: Trades 26-50 | K2: Trades 51-75 | N2: Trades 76-100
B4: # of Trades | C4: =COUNT('Trade Log'!$P$2:$P$96) -> 35 | E4: # of Trades | F4: =F5+F6 -> 27 | H4: # of Trades | I4: =I5+I6 -> 12 | K4: # of Trades | L4: =L5+L6 -> 0 | N4: # of Trades | O4: =O5+O6 -> 0
B5: # of Winners | C5: =COUNTIF(TradeLog[Gain/Loss],">0") -> 16 | E5: # of Winners | F5: =COUNTIF(TradeLog[Gain/Loss],">0") -> 16 | H5: # of Winners | I5: =COUNTIF('Trade Log'!P27:P46,">0") -> 4 | K5: # of Winners | L5: =COUNTIF('Trade Log'!P47:P71,">0") -> 0 | N5: # of Winners | O5: =COUNTIF('Trade Log'!P72:P96,">0") -> 0
B6: # of Losers | C6: =COUNTIF(TradeLog[Gain/Loss],"<0") -> 19 | E6: # of Losers | F6: =COUNTIF('Trade Log'!P2:P26,"<0") -> 11 | H6: # of Losers | I6: =COUNTIF('Trade Log'!P27:P46,"<0") -> 8 | K6: # of Losers | L6: =COUNTIF('Trade Log'!P47:P71,"<0") -> 0 | N6: # of Losers | O6: =COUNTIF('Trade Log'!P72:P96,"<0") -> 0
B7: % Winners | C7: =IF(C5=0,"0",C5/C4) -> 0.45714286 | E7: % Winners | F7: =IF(F5=0,"0",F5/F4) -> 0.59259259 | H7: % Winners | I7: =IF(I5=0,"0",I5/I4) -> 0.33333333 | K7: % Winners | L7: =IF(L5=0,"0",L5/L4) -> 0 | N7: % Winners | O7: =IF(O5=0,"0",O5/O4) -> 0
B8: % Losers | C8: =IF(C6=0,"0",C6/C4) -> 0.54285714 | E8: % Losers | F8: =IF(F6=0,"0",F6/F4) -> 0.40740741 | H8: % Losers | I8: =IF(I6=0,"0",I6/I4) -> 0.66666667 | K8: % Losers | L8: =IF(L6=0,"0",L6/L4) -> 0 | N8: % Losers | O8: =IF(O6=0,"0",O6/O4) -> 0
B9: Avg. $ Win | C9: =IFERROR(AVERAGEIF('Trade Log'!$P$2:$P$96, ">0"), 0) -> 347.3275 | E9: Avg. $ Win | F9: =IF(F5=0,"0",F15/F5) -> 306.3725 | H9: Avg. $ Win | I9: =IF(I5=0,"0",I15/I5) -> 163.82 | K9: Avg. $ Win | L9: =IF(L5=0,"0",L15/L5) -> 0 | N9: Avg. $ Win | O9: =IF(O5=0,"0",O15/O5) -> 0
B10: Avg. $ Loss | C10: =IFERROR(AVERAGEIF('Trade Log'!$P$2:$P$96, "<0"), 0) -> -153.84263 | E10: Avg. $ Loss | F10: =IF(F6=0,"0",F16/F6) -> -180.21273 | H10: Avg. $ Loss | I10: =IF(I6=0,"0",I16/I6) -> -117.58375 | K10: Avg. $ Loss | L10: =IF(L6=0,"0",L16/L6) -> 0 | N10: Avg. $ Loss | O10: =IF(O6=0,"0",O16/O6) -> 0
B11: R-to-R Ratio | C11: =IF(C5=0,"0",C9/-C10) -> 2.2576804 | E11: R-to-R Ratio | F11: =IF(F5=0,"0",F9/-F10) -> 1.7000603 | H11: R-to-R Ratio | I11: =IF(I5=0,"0",I9/-I10) -> 1.3932197 | K11: R-to-R Ratio | L11: =IF(L5=0,"0",L9/-L10) -> 0 | N11: R-to-R Ratio | O11: =IF(O5=0,"0",O9/-O10) -> 0
B12: Expectancy % | C12: =(C11*C7)-C8 -> 0.48922534 | E12: Expectancy % | F12: =(F11*F7)-F8 -> 0.60003572 | H12: Expectancy % | I12: =(I11*I7)-I8 -> -0.20226009 | K12: Expectancy % | L12: =(L11*L7)-L8 -> 0 | N12: Expectancy % | O12: =(O11*O7)-O8 -> 0
B13: Kelly % | C13: =IF(C12=0,"0",C7-(C8/C11)) -> 0.2166938 | E13: Kelly % | F13: =IF(F12=0,"0",F7-(F8/F11)) -> 0.35294967 | H13: Kelly % | I13: =IF(I12=0,"0",I7-(I8/I11)) -> -0.14517458 | K13: Kelly % | L13: =IF(L12=0,"0",L7-(L8/L11)) -> 0 | N13: Kelly % | O13: =IF(O12=0,"0",O7-(O8/O11)) -> 0
B15: Net Gains | C15: =SUMIF('Trade Log'!P2:P96,">0") -> 5557.24 | E15: Net Gains | F15: =SUMIF('Trade Log'!P2:P26,">0") -> 4901.96 | H15: Net Gains | I15: =SUMIF('Trade Log'!P27:P46,">0") -> 655.28 | K15: Net Gains | L15: =SUMIF('Trade Log'!P47:P71,">0") -> 0 | N15: Net Gains | O15: =SUMIF('Trade Log'!P72:P96,">0") -> 0
B16: Net Losses | C16: =SUMIF('Trade Log'!P2:P96,"<0") -> -2923.01 | E16: Net Losses | F16: =SUMIF('Trade Log'!P2:P26,"<0") -> -1982.34 | H16: Net Losses | I16: =SUMIF('Trade Log'!P27:P46,"<0") -> -940.67 | K16: Net Losses | L16: =SUMIF('Trade Log'!P47:P71,"<0") -> 0 | N16: Net Losses | O16: =SUMIF('Trade Log'!P72:P96,"<0") -> 0
B17: Net Profit/Loss | C17: =C15+C16 -> 2634.23 | E17: Net Profit/Loss | F17: =F15+F16 -> 2919.62 | H17: Net Profit/Loss | I17: =I15+I16 -> -285.39 | K17: Net Profit/Loss | L17: =L15+L16 -> 0 | N17: Net Profit/Loss | O17: =O15+O16 -> 0
B19: Contextual Info: | E19: Contextual Info: | H19: Contextual Info: | K19: Contextual Info: | N19: Contextual Info:
B21: Beginning Equity | C21: =IF(F21="","",F21) -> 35000 | E21: Beginning Equity | F21: 35000 | H21: Beginning Equity | I21: 35000 | K21: Beginning Equity | L21: 35000 | N21: Beginning Equity | O21: 35000
B22: Trade Risk % | C22: 0.015 | E22: Trade Risk % | F22: 0.015 | H22: Trade Risk % | I22: 0.015 | K22: Trade Risk % | L22: 0.015 | N22: Trade Risk % | O22: 0.015
B23: Risk per Trade | C23: =C21*C22 -> 525 | E23: Risk per Trade | F23: =IF(F21="","",F21*F22) -> 525 | H23: Risk per Trade | I23: =IF(I21="","",I21*I22) -> 525 | K23: Risk per Trade | L23: =IF(L21="","",L21*L22) -> 525 | N23: Risk per Trade | O23: =IF(O21="","",O21*O22) -> 525
B24: Loss-to-Risk Ratio | C24: =IF(C6=0,"",C16/C21*-1) -> 0.083514571 | E24: Loss-to-Risk Ratio | F24: =IF(F6=0,"",F16/F21*-1) -> 0.056638286 | H24: Loss-to-Risk Ratio | I24: =IF(I6=0,"",I10/I21*-1) -> 0.0033595357 | K24: Loss-to-Risk Ratio | L24: =IF(L6=0,"",L10/L21*-1) | N24: Loss-to-Risk Ratio | O24: =IF(O6=0,"",O10/O21*-1)
B25: Avg. Days in Winners | C25: =IF(C5=0,"",ROUND(AVERAGEIF('Trade Log'!P2:P96,">0",('Trade Log'!J2:J96)),2)) -> 9.38 | E25: Avg. Days in Winners | F25: =IF(F5=0, "", ROUND(AVERAGEIF('Trade Log'!P2:P26, ">0", 'Trade Log'!J2:J26), 2)) -> 6.83 | H25: Avg. Days in Winners | I25: =IF(I5=0,"",AVERAGEIF('Trade Log'!P26:P46,">0",('Trade Log'!J26:J46))) -> 15 | K25: Avg. Days in Winners | L25: =IF(L5=0,"",ROUND(AVERAGEIF('Trade Log'!P47:P71,">0",('Trade Log'!J47:J51)),2)) | N25: Avg. Days in Winners | O25: =IF(O5=0,"",ROUND(AVERAGEIF('Trade Log'!P72:P96,">0",('Trade Log'!J72:J96)),2))
B26: Avg. Days in Losers | C26: =IF(C6=0,"",ROUND(AVERAGEIF('Trade Log'!P2:P96,"<0",('Trade Log'!J2:J96)),2)) -> 6.68 | E26: Avg. Days in Losers | F26: =IF(F6=0, "", ROUND(AVERAGEIF('Trade Log'!P2:P26, "<0", 'Trade Log'!J2:J26), 2)) -> 3.82 | H26: Avg. Days in Losers | I26: =IF(I6=0,"",ROUND(AVERAGEIF('Trade Log'!P26:P46,"<0",('Trade Log'!J26:J46)),2)) -> 10.63 | K26: Avg. Days in Losers | L26: =IF(L6=0,"",ROUND(AVERAGEIF('Trade Log'!P47:P71,"<0",('Trade Log'!J47:J71)),2)) | N26: Avg. Days in Losers | O26: =IF(O6=0,"",ROUND(AVERAGEIF('Trade Log'!P72:P96,"<0",('Trade Log'!J72:J96)),2))
B27: Days after Scale out | C27: =IFERROR(IF(C4=0, "", AVERAGEIF('Trade Log'!N2:N96,"<>")), "") | E27: Days after Scale out | F27: =IFERROR(IF(F4=0, "", AVERAGEIF('Trade Log'!N2:N26,"<>")), "") | H27: Days after Scale out | I27: =IFERROR(IF(I4=0, "", AVERAGEIF('Trade Log'!N27:N51,"<>")), "") | K27: Days after Scale out | L27: =IFERROR(IF(L4=0, "", AVERAGEIF('Trade Log'!N52:N76,"<>")), "") | N27: Days after Scale out | O27: =IFERROR(IF(O4=0, "", AVERAGEIF('Trade Log'!N77:N96,"<>")), "")
B28: Net Return % | C28: =IFERROR(C17 / C21, "") -> 0.075263714 | E28: Net Return % | F28: =IF(F4=0,"",F17/F21) -> 0.083417714 | H28: Net Return % | I28: =IF(I4=0,"",I17/I21) -> -0.008154 | K28: Net Return % | L28: =IF(L4=0,"",L17/L21) | N28: Net Return % | O28: =IF(O4=0,"",O17/O21)
B29: Beginning Date | C29: =IF('Trade Log'!D2="","",'Trade Log'!D2) -> 45965 | E29: Beginning Date | F29: =IF('Trade Log'!D2="","",'Trade Log'!D2) -> 45965 | H29: Beginning Date | I29: =IF('Trade Log'!D27="","",'Trade Log'!D27) -> 45995 | K29: Beginning Date | L29: =IF('Trade Log'!D47="","",'Trade Log'!D47) | N29: Beginning Date | O29: =IF('Trade Log'!D72="","",'Trade Log'!D72)
B30: End Date | C30: =IF('Trade Log'!I96="","",'Trade Log'!I96) | E30: End Date | F30: =IF('Trade Log'!I26="","",'Trade Log'!I26) -> 46002 | H30: End Date | I30: =IF('Trade Log'!I46="","",'Trade Log'!I46) | K30: End Date | L30: =IF('Trade Log'!I71="","",'Trade Log'!I71) | N30: End Date | O30: =IF('Trade Log'!I96="","",'Trade Log'!I96)
H37: Forget it
