Workbook

Sheet Trade_Log
A1: Symbol | B1: System | C1: Trade Type | D1: Long | E1: Trade Date | F1: Entry Price | G1: Contracts | H1: Exit #1 | I1: # Exited | J1: Exit Date | K1: # of Days | L1: Exit #2 | M1: # Exited2 | N1: Exit Date3 | O1: # of Days4 | P1: Comm. | Q1: Gain/Loss | R1: Trade Comments | S1: Exit #1 Gain | T1: Exit #2 Gain
A2: GSAT | B2: VP_Grok | C2: Call | D2: Long | E2: 45957 | F2: 6.2 | G2: 2 | H2: 4.7 | I2: 1 | J2: 45957 | K2: =IF(J2="","",J2-E2) -> 0 | L2: 4.3 | M2: 1 | N2: 45957 | O2: =IF(N2="","",N2-J2) -> 0 | Q2: =IF(A2="","", S2+T2) -> -340 | S2: =IF(D2="Long",((H2-F2)*I2),((F2-H2)*I2))*100 -> -150 | T2: =IF(D2="Long",((L2-F2)*M2),((F2-L2)*M2))*100 -> -190 | V2: Short
A3: ACGO | B3: VP_Grok | C3: Call | D3: Long | E3: 45957 | F3: 17.35 | G3: 1 | H3: 21.75 | I3: 1 | J3: 45958 | K3: =IF(J3="","",J3-E3) -> 1 | O3: =IF(N3="","",N3-J3) | Q3: =IF(A3="","", S3+T3) -> 440 | S3: =IF(D3="Long",((H3-F3)*I3),((F3-H3)*I3))*100 -> 440 | T3: =IF(D3="Long",((L3-F3)*M3),((F3-L3)*M3))*100 -> 0
A4: AVGO | B4: VP_Grok | C4: Call | D4: Long | E4: 45958 | F4: 23.25 | G4: 1 | H4: 29.95 | I4: 1 | J4: 45958 | K4: =IF(J4="","",J4-E4) -> 0 | O4: =IF(N4="","",N4-J4) | Q4: =IF(A4="","", S4+T4) -> 670 | S4: =IF(D4="Long",((H4-F4)*I4),((F4-H4)*I4))*100 -> 670 | T4: =IF(D4="Long",((L4-F4)*M4),((F4-L4)*M4))*100 -> 0
A5: AMZN | B5: VP_Grok | C5: Call | D5: Long | E5: 45958 | F5: 11.15 | G5: 1 | H5: 13.4 | I5: 1 | J5: 45958 | K5: =IF(J5="","",J5-E5) -> 0 | O5: =IF(N5="","",N5-J5) | Q5: =IF(A5="","", S5+T5) -> 225 | S5: =IF(D5="Long",((H5-F5)*I5),((F5-H5)*I5))*100 -> 225 | T5: =IF(D5="Long",((L5-F5)*M5),((F5-L5)*M5))*100 -> 0
A6: UBER | B6: VP_Grok | C6: Call | D6: Long | E6: 45950 | F6: 5.05 | G6: 3 | H6: 6.35 | I6: 1 | J6: 45954 | K6: =IF(J6="","",J6-E6) -> 4 | L6: 7.1 | M6: 1 | N6: 45964 | O6: =IF(N6="","",N6-J6) -> 10 | Q6: =IF(A6="","", S6+T6) -> 335 | R6: Still 2 Remaining ? | S6: =IF(D6="Long",((H6-F6)*I6),((F6-H6)*I6))*100 -> 130 | T6: =IF(D6="Long",((L6-F6)*M6),((F6-L6)*M6))*100 -> 205
A7: PLTR | B7: VP_Grok | C7: Call | D7: Long | E7: 45958 | F7: 15.8 | G7: 1 | H7: 19.8 | I7: 1 | J7: 45959 | K7: =IF(J7="","",J7-E7) -> 1 | O7: =IF(N7="","",N7-J7) | Q7: =IF(A7="","", S7+T7) -> 400 | R7: Still 1 Remaining ? | S7: =IF(D7="Long",((H7-F7)*I7),((F7-H7)*I7))*100 -> 400 | T7: =IF(D7="Long",((L7-F7)*M7),((F7-L7)*M7))*100 -> 0
A8: VSAT | B8: VP_Grok | C8: Call | D8: Long | E8: 45957 | F8: 4.4 | G8: 3 | H8: 5 | I8: 3 | J8: 45957 | K8: =IF(J8="","",J8-E8) -> 0 | O8: =IF(N8="","",N8-J8) | Q8: =IF(A8="","", S8+T8) -> 180 | S8: =IF(D8="Long",((H8-F8)*I8),((F8-H8)*I8))*100 -> 180 | T8: =IF(D8="Long",((L8-F8)*M8),((F8-L8)*M8))*100 -> 0
A9: RMBS | B9: VP_Grok | C9: Call | D9: Long | E9: 45965 | F9: 4.9 | G9: 2 | H9: 7.6 | I9: 1 | J9: 45966 | K9: =IF(J9="","",J9-E9) -> 1 | L9: 7.6 | M9: 1 | N9: 45967 | O9: =IF(N9="","",N9-J9) -> 1 | Q9: =IF(A9="","", S9+T9) -> 540 | S9: =IF(D9="Long",((H9-F9)*I9),((F9-H9)*I9))*100 -> 270 | T9: =IF(D9="Long",((L9-F9)*M9),((F9-L9)*M9))*100 -> 270
A10: GILD | B10: P_118 | C10: Call | D10: Long | E10: 45965 | F10: 3.4 | G10: 2 | H10: 3.35 | I10: 1 | J10: 45967 | K10: =IF(J10="","",J10-E10) -> 2 | L10: 3.3 | M10: 1 | N10: 45967 | O10: =IF(N10="","",N10-J10) -> 0 | Q10: =IF(A10="","", S10+T10) -> -15 | S10: =IF(D10="Long",((H10-F10)*I10),((F10-H10)*I10))*100 -> -5 | T10: =IF(D10="Long",((L10-F10)*M10),((F10-L10)*M10))*100 -> -10
A11: QQQ | B11: VP_Grok | C11: Call | D11: Long | E11: 45979 | F11: 2.77 | G11: 4 | H11: 2.79 | I11: 2 | J11: 45979 | K11: =IF(J11="","",J11-E11) -> 0 | L11: 3.49 | M11: 2 | N11: 45979 | O11: =IF(N11="","",N11-J11) -> 0 | Q11: =IF(A11="","", S11+T11) -> 148 | S11: =IF(D11="Long",((H11-F11)*I11),((F11-H11)*I11))*100 -> 4 | T11: =IF(D11="Long",((L11-F11)*M11),((F11-L11)*M11))*100 -> 144
A12: QMC | B12: VP_Grok | C12: Call | D12: Long | E12: 45980 | F12: 2.86 | G12: 3 | H12: 3.72 | I12: 3 | J12: 45980 | K12: =IF(J12="","",J12-E12) -> 0 | O12: =IF(N12="","",N12-J12) | Q12: =IF(A12="","", S12+T12) -> 258 | S12: =IF(D12="Long",((H12-F12)*I12),((F12-H12)*I12))*100 -> 258 | T12: =IF(D12="Long",((L12-F12)*M12),((F12-L12)*M12))*100 -> 0
A13: TPR | B13: VP_Grok | C13: Call | D13: Long | E13: 45980 | F13: 19 | G13: 1 | H13: 29 | I13: 1 | J13: 46001 | K13: =IF(J13="","",J13-E13) -> 21 | O13: =IF(N13="","",N13-J13) | Q13: =IF(A13="","", S13+T13) -> 1000 | R13: Expied iTM (104 on 1119 114 on 12 10) | S13: =IF(D13="Long",((H13-F13)*I13),((F13-H13)*I13))*100 -> 1000 | T13: =IF(D13="Long",((L13-F13)*M13),((F13-L13)*M13))*100 -> 0
A14: NIU | B14: VP_Grok | C14: Call | D14: Long | E14: 45980 | F14: 0.45 | G14: 5 | H14: 0.41 | I14: 5 | J14: 45992 | K14: =IF(J14="","",J14-E14) -> 12 | O14: =IF(N14="","",N14-J14) | Q14: =IF(A14="","", S14+T14) -> -20 | S14: =IF(D14="Long",((H14-F14)*I14),((F14-H14)*I14))*100 -> -20 | T14: =IF(D14="Long",((L14-F14)*M14),((F14-L14)*M14))*100 -> 0
A15: SIMO | B15: VP_Grok | C15: Call | D15: Long | E15: 45992 | F15: 6.15 | G15: 1 | H15: 10.83 | I15: 1 | J15: 46000 | K15: =IF(J15="","",J15-E15) -> 8 | O15: =IF(N15="","",N15-J15) | Q15: =IF(A15="","", S15+T15) -> 468 | S15: =IF(D15="Long",((H15-F15)*I15),((F15-H15)*I15))*100 -> 468 | T15: =IF(D15="Long",((L15-F15)*M15),((F15-L15)*M15))*100 -> 0
A16: WY | B16: VP_Grok | C16: Call | D16: Long | E16: 45992 | F16: 0.74 | G16: 16 | H16: 1.27 | I16: 16 | J16: 46001 | K16: =IF(J16="","",J16-E16) -> 9 | O16: =IF(N16="","",N16-J16) | Q16: =IF(A16="","", S16+T16) -> 848 | S16: =IF(D16="Long",((H16-F16)*I16),((F16-H16)*I16))*100 -> 848 | T16: =IF(D16="Long",((L16-F16)*M16),((F16-L16)*M16))*100 -> 0
A17: BOOT | B17: VP_Grok | C17: Call | D17: Long | E17: 45994 | F17: 7.45 | G17: 1 | H17: 0.93 | I17: 1 | J17: 46008 | K17: =IF(J17="","",J17-E17) -> 14 | O17: =IF(N17="","",N17-J17) | Q17: =IF(A17="","", S17+T17) -> -652 | S17: =IF(D17="Long",((H17-F17)*I17),((F17-H17)*I17))*100 -> -652 | T17: =IF(D17="Long",((L17-F17)*M17),((F17-L17)*M17))*100 -> 0
A18: CAT | B18: VP_Grok | C18: Call | D18: Long | E18: 45994 | F18: 18.5 | G18: 1 | H18: 34.9 | I18: 1 | J18: 46002 | K18: =IF(J18="","",J18-E18) -> 8 | O18: =IF(N18="","",N18-J18) | Q18: =IF(A18="","", S18+T18) -> 1640 | S18: =IF(D18="Long",((H18-F18)*I18),((F18-H18)*I18))*100 -> 1640 | T18: =IF(D18="Long",((L18-F18)*M18),((F18-L18)*M18))*100 -> 0
A19: IBM | B19: VP_Grok | C19: Call | D19: Long | E19: 45994 | F19: 8.05 | G19: 1 | H19: 9.75 | I19: 1 | J19: 45995 | K19: =IF(J19="","",J19-E19) -> 1 | O19: =IF(N19="","",N19-J19) | Q19: =IF(A19="","", S19+T19) -> 170 | S19: =IF(D19="Long",((H19-F19)*I19),((F19-H19)*I19))*100 -> 170 | T19: =IF(D19="Long",((L19-F19)*M19),((F19-L19)*M19))*100 -> 0
A20: RGTI | B20: VP_Grok | C20: Call | D20: Long | E20: 45995 | F20: 1.68 | G20: 10 | H20: 4.15 | I20: 8 | J20: 45995 | K20: =IF(J20="","",J20-E20) -> 0 | L20: 2.18 | M20: 2 | N20: 45999 | O20: =IF(N20="","",N20-J20) -> 4 | Q20: =IF(A20="","", S20+T20) -> 2076 | R20: Removed TLSA Transactions from Log Not sure what I tried | S20: =IF(D20="Long",((H20-F20)*I20),((F20-H20)*I20))*100 -> 1976 | T20: =IF(D20="Long",((L20-F20)*M20),((F20-L20)*M20))*100 -> 100
A21: MOD | B21: P_115 | C21: Call | D21: Long | E21: 45995 | F21: 1.65 | G21: 1 | H21: 5.45 | I21: 1 | J21: 46001 | K21: =IF(J21="","",J21-E21) -> 6 | O21: =IF(N21="","",N21-J21) | Q21: =IF(A21="","", S21+T21) -> 380 | S21: =IF(D21="Long",((H21-F21)*I21),((F21-H21)*I21))*100 -> 380 | T21: =IF(D21="Long",((L21-F21)*M21),((F21-L21)*M21))*100 -> 0
A22: ATI | B22: P_118 | C22: Call | D22: Long | E22: 45995 | F22: 5.45 | G22: 2 | H22: 11.15 | I22: 1 | J22: 46002 | K22: =IF(J22="","",J22-E22) -> 7 | L22: 11.15 | M22: 1 | N22: 46002 | O22: =IF(N22="","",N22-J22) -> 0 | Q22: =IF(A22="","", S22+T22) -> 1140 | S22: =IF(D22="Long",((H22-F22)*I22),((F22-H22)*I22))*100 -> 570 | T22: =IF(D22="Long",((L22-F22)*M22),((F22-L22)*M22))*100 -> 570
A23: UAMY | B23: VP_Grok | C23: Call | D23: Long | E23: 45995 | F23: 0.4 | G23: 20 | H23: 0.4 | I23: 20 | J23: 45996 | K23: =IF(J23="","",J23-E23) -> 1 | O23: =IF(N23="","",N23-J23) | Q23: =IF(A23="","", S23+T23) -> 0 | S23: =IF(D23="Long",((H23-F23)*I23),((F23-H23)*I23))*100 -> 0 | T23: =IF(D23="Long",((L23-F23)*M23),((F23-L23)*M23))*100 -> 0
A24: CALM | B24: VP_Grok | C24: Call | D24: Long | E24: 45996 | F24: 2.4 | G24: 3 | H24: 2.47 | I24: 3 | J24: 45996 | K24: =IF(J24="","",J24-E24) -> 0 | O24: =IF(N24="","",N24-J24) | Q24: =IF(A24="","", S24+T24) -> 21 | S24: =IF(D24="Long",((H24-F24)*I24),((F24-H24)*I24))*100 -> 21 | T24: =IF(D24="Long",((L24-F24)*M24),((F24-L24)*M24))*100 -> 0
A25: UAMY | B25: VP_Grok | C25: Call | D25: Long | E25: 45996 | F25: 0.45 | G25: 5 | H25: 0.45 | I25: 5 | J25: 45996 | K25: =IF(J25="","",J25-E25) -> 0 | O25: =IF(N25="","",N25-J25) | Q25: =IF(A25="","", S25+T25) -> 0 | S25: =IF(D25="Long",((H25-F25)*I25),((F25-H25)*I25))*100 -> 0 | T25: =IF(D25="Long",((L25-F25)*M25),((F25-L25)*M25))*100 -> 0
A26: UAMY | B26: VP_Grok | C26: Call | D26: Long | E26: 45996 | F26: 0.46 | G26: 10 | H26: 0 | I26: 10 | J26: 46010 | K26: =IF(J26="","",J26-E26) -> 14 | O26: =IF(N26="","",N26-J26) | Q26: =IF(A26="","", S26+T26) -> -460 | R26: Expired OTM | S26: =IF(D26="Long",((H26-F26)*I26),((F26-H26)*I26))*100 -> -460 | T26: =IF(D26="Long",((L26-F26)*M26),((F26-L26)*M26))*100 -> 0
A27: LRN | B27: VP_Grok | C27: Call | D27: Long | E27: 45996 | F27: 3.56 | G27: 3 | H27: 7.6 | I27: 3 | J27: 46007 | K27: =IF(J27="","",J27-E27) -> 11 | O27: =IF(N27="","",N27-J27) | Q27: =IF(A27="","", S27+T27) -> 1212 | S27: =IF(D27="Long",((H27-F27)*I27),((F27-H27)*I27))*100 -> 1212 | T27: =IF(D27="Long",((L27-F27)*M27),((F27-L27)*M27))*100 -> 0
A28: URBN | B28: VP_Grok | C28: Call | D28: Long | E28: 45999 | F28: 5.25 | G28: 1 | H28: 6.4 | I28: 1 | J28: 46001 | K28: =IF(J28="","",J28-E28) -> 2 | O28: =IF(N28="","",N28-J28) | Q28: =IF(A28="","", S28+T28) -> 115 | S28: =IF(D28="Long",((H28-F28)*I28),((F28-H28)*I28))*100 -> 115 | T28: =IF(D28="Long",((L28-F28)*M28),((F28-L28)*M28))*100 -> 0
A29: CLS | B29: VP_Grok | C29: Call | D29: Long | E29: 46000 | F29: 31.65 | G29: 1 | H29: 17.05 | I29: 1 | J29: 46001 | K29: =IF(J29="","",J29-E29) -> 1 | O29: =IF(N29="","",N29-J29) | Q29: =IF(A29="","", S29+T29) -> -1460 | R29: Typed in Incorrect STOP price.74 instead 1.74 | S29: =IF(D29="Long",((H29-F29)*I29),((F29-H29)*I29))*100 -> -1460 | T29: =IF(D29="Long",((L29-F29)*M29),((F29-L29)*M29))*100 -> 0
A30: MGNI | B30: VP_Grok | C30: Call | D30: Long | E30: 46002 | F30: 1.32 | G30: 10 | H30: 1.16 | I30: 10 | J30: 46002 | K30: =IF(J30="","",J30-E30) -> 0 | O30: =IF(N30="","",N30-J30) | Q30: =IF(A30="","", S30+T30) -> -160 | S30: =IF(D30="Long",((H30-F30)*I30),((F30-H30)*I30))*100 -> -160 | T30: =IF(D30="Long",((L30-F30)*M30),((F30-L30)*M30))*100 -> 0
A31: AZN | B31: VP_Grok | C31: Call | D31: Long | E31: 46007 | F31: 1.12 | G31: 4 | H31: 1.16 | I31: 4 | J31: 46007 | K31: =IF(J31="","",J31-E31) -> 0 | O31: =IF(N31="","",N31-J31) | Q31: =IF(A31="","", S31+T31) -> 16 | S31: =IF(D31="Long",((H31-F31)*I31),((F31-H31)*I31))*100 -> 16 | T31: =IF(D31="Long",((L31-F31)*M31),((F31-L31)*M31))*100 -> 0
A32: FOXA | B32: P_117 | C32: Call | D32: Long | E32: 46007 | F32: 2.49 | G32: 2 | H32: 2.49 | I32: 2 | J32: 46007 | K32: =IF(J32="","",J32-E32) -> 0 | O32: =IF(N32="","",N32-J32) | Q32: =IF(A32="","", S32+T32) -> 0 | S32: =IF(D32="Long",((H32-F32)*I32),((F32-H32)*I32))*100 -> 0 | T32: =IF(D32="Long",((L32-F32)*M32),((F32-L32)*M32))*100 -> 0
A33: FOXA | B33: P_117 | C33: Call | D33: Long | E33: 46007 | F33: 2.44 | G33: 2 | H33: 4.25 | I33: 2 | J33: 46013 | K33: =IF(J33="","",J33-E33) -> 6 | O33: =IF(N33="","",N33-J33) | Q33: =IF(A33="","", S33+T33) -> 362 | S33: =IF(D33="Long",((H33-F33)*I33),((F33-H33)*I33))*100 -> 362 | T33: =IF(D33="Long",((L33-F33)*M33),((F33-L33)*M33))*100 -> 0
A34: TXTX | B34: P_118 | C34: Call | D34: Long | E34: 46008 | F34: 5.9 | G34: 3 | H34: 3.2 | I34: 3 | J34: 46008 | K34: =IF(J34="","",J34-E34) -> 0 | O34: =IF(N34="","",N34-J34) | Q34: =IF(A34="","", S34+T34) -> -810 | S34: =IF(D34="Long",((H34-F34)*I34),((F34-H34)*I34))*100 -> -810 | T34: =IF(D34="Long",((L34-F34)*M34),((F34-L34)*M34))*100 -> 0
A35: ROKU | B35: P_118 | C35: Call | D35: Long | E35: 46008 | F35: 6.65 | G35: 2 | H35: 3.2 | I35: 3 | J35: 46008 | K35: =IF(J35="","",J35-E35) -> 0 | O35: =IF(N35="","",N35-J35) | Q35: =IF(A35="","", S35+T35) -> -1035 | S35: =IF(D35="Long",((H35-F35)*I35),((F35-H35)*I35))*100 -> -1035 | T35: =IF(D35="Long",((L35-F35)*M35),((F35-L35)*M35))*100 -> 0
A36: TSLA | B36: P_118 | C36: Call | D36: Long | E36: 46008 | F36: 29.3 | G36: 1 | H36: 21.35 | I36: 1 | J36: 46008 | K36: =IF(J36="","",J36-E36) -> 0 | O36: =IF(N36="","",N36-J36) | Q36: =IF(A36="","", S36+T36) -> -795 | S36: =IF(D36="Long",((H36-F36)*I36),((F36-H36)*I36))*100 -> -795 | T36: =IF(D36="Long",((L36-F36)*M36),((F36-L36)*M36))*100 -> 0
A37: TWLO | B37: P_118 | C37: Call | D37: Long | E37: 46008 | F37: 3.7 | G37: 2 | K37: =IF(J37="","",J37-E37) | O37: =IF(N37="","",N37-J37) | Q37: =IF(A37="","", S37+T37) -> 0 | S37: =IF(D37="Long",((H37-F37)*I37),((F37-H37)*I37))*100 -> 0 | T37: =IF(D37="Long",((L37-F37)*M37),((F37-L37)*M37))*100 -> 0
A38: CLF | B38: P_118 | C38: Call | D38: Long | E38: 46010 | F38: 0.17 | G38: 20 | K38: =IF(J38="","",J38-E38) | O38: =IF(N38="","",N38-J38) | Q38: =IF(A38="","", S38+T38) -> 0 | S38: =IF(D38="Long",((H38-F38)*I38),((F38-H38)*I38))*100 -> 0 | T38: =IF(D38="Long",((L38-F38)*M38),((F38-L38)*M38))*100 -> 0
A39: PRMB | B39: P_118 | C39: Call | D39: Long | E39: 46020 | F39: 1.88 | G39: 6 | H39: 1.25 | I39: 6 | J39: 46027 | K39: =IF(J39="","",J39-E39) -> 7 | O39: =IF(N39="","",N39-J39) | Q39: =IF(A39="","", S39+T39) -> -378 | S39: =IF(D39="Long",((H39-F39)*I39),((F39-H39)*I39))*100 -> -378 | T39: =IF(D39="Long",((L39-F39)*M39),((F39-L39)*M39))*100 -> 0
A40: WVE | B40: SNT | C40: Call | D40: Long | E40: 46027 | K40: =IF(J40="","",J40-E40) | O40: =IF(N40="","",N40-J40) | Q40: =IF(A40="","", S40+T40) -> 0 | S40: =IF(D40="Long",((H40-F40)*I40),((F40-H40)*I40))*100 -> 0 | T40: =IF(D40="Long",((L40-F40)*M40),((F40-L40)*M40))*100 -> 0
...

Sheet Dashboard
A1: v2.0
B2: Cumulative Results | E2: Trades 1-25 | H2: Trades 26-50 | K2: Trades 51-75 | N2: Trades 76-100
B4: # of Trades | C4: =N(F4) + N(I4) + N(L4) + N(O4) -> 34 | E4: # of Trades | F4: =F5+F6 -> 23 | H4: # of Trades | I4: =I5 + I6 -> 11 | K4: # of Trades | L4: =L5+L6 -> 0 | N4: # of Trades | O4: =O5+O6 -> 0
B5: # of Winners | C5: =VALUE(F5) + VALUE(I5) + VALUE(L5) + VALUE(O5) -> 22 | E5: # of Winners | F5: =COUNTIF(Trade_Log!Q2:Q26, ">0") -> 18 | H5: # of Winners | I5: =COUNTIF(Trade_Log!Q25:Q49,">0") -> 4 | K5: # of Winners | L5: =COUNTIF(Trade_Log!Q50:Q74,">0") -> 0 | N5: # of Winners | O5: =COUNTIF(Trade_Log!Q77:Q101,">0") -> 0
B6: # of Losers | C6: =VALUE(F6) + VALUE(I6) + VALUE(L6) + VALUE(O6) -> 12 | E6: # of Losers | F6: =COUNTIF(Trade_Log!Q2:Q26, "<0") -> 5 | H6: # of Losers | I6: =COUNTIF(Trade_Log!Q25:Q49, "<0") -> 7 | K6: # of Losers | L6: =COUNTIF(Trade_Log!Q50:Q74,"<0") -> 0 | N6: # of Losers | O6: =COUNTIF(Trade_Log!Q77:Q101,"<0") -> 0
B7: % Winners | C7: =IF(C5=0,"0",C5/C4) -> 0.64705882 | E7: % Winners | F7: =IF(F5=0,"0",F5/F4) -> 0.7826087 | H7: % Winners | I7: =IF(I5=0,"0",I5/I4) -> 0.36363636 | K7: % Winners | L7: =IF(L5=0,"0",L5/L4) -> 0 | N7: % Winners | O7: =IF(O5=0,"0",O5/O4) -> 0
B8: % Losers | C8: =IF(C6=0,"0",C6/C4) -> 0.35294118 | E8: % Losers | F8: =IF(F6=0,"0",F6/F4) -> 0.2173913 | H8: % Losers | I8: =IF(I6=0,"0",I6/I4) -> 0.63636364 | K8: % Losers | L8: =IF(L6=0,"0",L6/L4) -> 0 | N8: % Losers | O8: =IF(O6=0,"0",O6/O4) -> 0
B9: Avg. $ Win | C9: =IF(C5=0,"0",C15/C5) -> 574.72727 | E9: Avg. $ Win | F9: =IF(F5=0,"0",F15/F5) -> 607.72222 | H9: Avg. $ Win | I9: =IF(I5=0,"0",I15/I5) -> 426.25 | K9: Avg. $ Win | L9: =IF(L5=0,"0",L15/L5) -> 0 | N9: Avg. $ Win | O9: =IF(O5=0,"0",O15/O5) -> 0
B10: Avg. $ Loss | C10: =IF(C6=0,"0",C16/C6) -> -510.41667 | E10: Avg. $ Loss | F10: =IF(F6=0,"0",F16/F6) -> -297.4 | H10: Avg. $ Loss | I10: =IF(I6=0,"0",I16/I6) -> -728.28571 | K10: Avg. $ Loss | L10: =IF(L6=0,"0",L16/L6) -> 0 | N10: Avg. $ Loss | O10: =IF(O6=0,"0",O16/O6) -> 0
B11: R-to-R Ratio | C11: =IF(C5=0,"0",C9/-C10) -> 1.1259963 | E11: R-to-R Ratio | F11: =IF(F5=0,"0",F9/-F10) -> 2.0434506 | H11: R-to-R Ratio | I11: =IF(I5=0,"0",I9/-I10) -> 0.58527854 | K11: R-to-R Ratio | L11: =IF(L5=0,"0",L9/-L10) -> 0 | N11: R-to-R Ratio | O11: =IF(O5=0,"0",O9/-O10) -> 0
B12: Expectancy % | C12: =(C11*C7)-C8 -> 0.37564466 | E12: Expectancy % | F12: =(F11*F7)-F8 -> 1.3818309 | H12: Expectancy % | I12: =(I11*I7)-I8 -> -0.42353508 | K12: Expectancy % | L12: =(L11*L7)-L8 -> 0 | N12: Expectancy % | O12: =(O11*O7)-O8 -> 0
B13: Kelly % | C13: =IF(C12=0,"0",C7-(C8/C11)) -> 0.33361092 | E13: Kelly % | F13: =IF(F12=0,"0",F7-(F8/F11)) -> 0.67622428 | H13: Kelly % | I13: =IF(I12=0,"0",I7-(I8/I11)) -> -0.72364703 | K13: Kelly % | L13: =IF(L12=0,"0",L7-(L8/L11)) -> 0 | N13: Kelly % | O13: =IF(O12=0,"0",O7-(O8/O11)) -> 0
B15: Net Gains | C15: =SUMIF(Trade_Log!Q:Q, ">0") -> 12644 | E15: Net Gains | F15: =SUMIF(Trade_Log!Q2:Q26,">0") -> 10939 | H15: Net Gains | I15: =SUMIF(Trade_Log!Q26:Q51,">0") -> 1705 | K15: Net Gains | L15: =SUMIF(Trade_Log!Q52:Q77,">0") -> 0 | N15: Net Gains | O15: =SUMIF(Trade_Log!Q78:Q101,">0") -> 0
B16: Net Losses | C16: =SUMIF(Trade_Log!Q:Q, "<0") -> -6125 | E16: Net Losses | F16: =SUMIF(Trade_Log!Q2:Q26,"<0") -> -1487 | H16: Net Losses | I16: =SUMIF(Trade_Log!Q26:Q51,"<0") -> -5098 | K16: Net Losses | L16: =SUMIF(Trade_Log!Q52:Q77,"<0") -> 0 | N16: Net Losses | O16: =SUMIF(Trade_Log!Q75:Q99,"<0") -> 0
B17: Net Profit/Loss | C17: =N(F17) + N(I17) + N(L17) + N(O17) -> 6059 | E17: Net Profit/Loss | F17: =SUM(Trade_Log!Q2:Q26) -> 9452 | H17: Net Profit/Loss | I17: =SUM(Trade_Log!Q26:Q51) -> -3393 | K17: Net Profit/Loss | L17: =SUM(Trade_Log!Q52:Q77) -> 0 | N17: Net Profit/Loss | O17: =SUM(Trade_Log!Q78:Q101) -> 0
B19: Contextual Info: | E19: Contextual Info: | F19: One final check on GSAT: | H19: Contextual Info: | K19: Contextual Info: | N19: Contextual Info:
B21: Beginning Equity | C21: 35000 | E21: Beginning Equity | F21: 35000 | H21: Beginning Equity | I21: 35000 | K21: Beginning Equity | N21: Beginning Equity
B22: Trade Risk % | C22: 0.015 | E22: Trade Risk % | F22: 0.015 | H22: Trade Risk % | I22: 0.015 | K22: Trade Risk % | N22: Trade Risk %
B23: Risk per Trade | C23: =C21*C22 -> 525 | E23: Risk per Trade | F23: =IF(F21="","",F21*F22) -> 525 | H23: Risk per Trade | I23: =IF(I21="","",I21*I22) -> 525 | K23: Risk per Trade | L23: =IF(L21="","",L21*L22) | N23: Risk per Trade | O23: =IF(O21="","",O21*O22)
B24: Loss-to-Risk Ratio | C24: =IF(I24="",F24,AVERAGE(F24,I24,L24,O24)) -> 0.97684354 | E24: Loss-to-Risk Ratio | F24: =IF(F6=0,"",F10/F23*-1) -> 0.56647619 | H24: Loss-to-Risk Ratio | I24: =IF(I6=0,"",I10/I23*-1) -> 1.3872109 | K24: Loss-to-Risk Ratio | L24: =IF(L6=0,"",L10/L23*-1) | N24: Loss-to-Risk Ratio | O24: =IF(O6=0,"",O10/O23*-1)
B25: Avg. Days in Winners | C25: =IF(C5=0, "", ROUNDUP(AVERAGEIF(Trade_Log!Q2:Q94, ">0", Trade_Log!K2:K94), 0)) -> 4 | E25: Avg. Days in Winners | F25: =IF(F5=0, "", ROUNDUP(AVERAGEIF(Trade_Log!Q2:Q26, ">0", Trade_Log!K2:K26),0)) -> 4 | H25: Avg. Days in Winners | I25: =IF(I5=0, "", ROUNDUP(AVERAGEIF(Trade_Log!Q27:Q51, ">0", Trade_Log!K27:K51), 0)) -> 5 | K25: Avg. Days in Winners | L25: =IF(L5=0, "", ROUNDUP(AVERAGEIF(Trade_Log!Q52:Q76, ">0", Trade_Log!K52:K76), 0)) | N25: Avg. Days in Winners | O25: =IF(O5=0, "", ROUND(AVERAGEIF(Trade_Log!Q77:Q101, "<0", Trade_Log!K77:K101), 2))
B26: Avg. Days in Losers | C26: =IF(C6=0, "", ROUNDUP(AVERAGEIF(Trade_Log!Q2:Q94, "<0", Trade_Log!K2:K94), 0)) -> 5 | E26: Avg. Days in Losers | F26: =IF(F6=0, "", ROUNDUP(AVERAGEIF(Trade_Log!Q2:Q26, "<0", Trade_Log!K2:K26), 0)) -> 9 | H26: Avg. Days in Losers | I26: =IF(I6=0,"",ROUNDUP(AVERAGEIF(Trade_Log!Q27:Q51,"<0",Trade_Log!K27:K51),0)) -> 2 | K26: Avg. Days in Losers | L26: =IF(L6=0,"",ROUNDUP(AVERAGEIF(Trade_Log!Q52:Q76,"<0",Trade_Log!K52:K76),0)) | N26: Avg. Days in Losers | O26: =IF(O6=0,"",ROUNDUP(AVERAGEIF(Trade_Log!Q77:Q101,"<0",Trade_Log!K77:K101),0))
B27: Days after Scale out | C27: =ROUND(IFERROR(AVERAGEIF(Trade_Log!O:O,"<>"), 0), 0) -> 2 | E27: Days after Scale out | F27: =IF(I4=0, "", IFERROR(ROUND(AVERAGEIF(Trade_Log!O2:O26, ">-1"), 2), "")) -> 2.14 | H27: Days after Scale out | I27: =IF(I4=0, "", IFERROR(ROUND(AVERAGEIF(Trade_Log!O26:O51, ">-1"), 2), "")) | K27: Days after Scale out | L27: =IF(L4=0, "", IFERROR(ROUND(AVERAGEIF(Trade_Log!O52:O77, ">-1"), 2), "")) | N27: Days after Scale out | O27: =IF(O4=0, "", IFERROR(ROUNDUP(AVERAGEIF(Trade_Log!O78:O101, ">-1"), 0), ""))
B28: Net Return % | C28: =IFERROR(C17 / C21, 0) -> 0.17311429 | E28: Net Return % | F28: =IFERROR(F17 / F21, 0) -> 0.27005714 | H28: Net Return % | I28: =IF(I4=0,"",I17/I21) -> -0.096942857 | K28: Net Return % | L28: =IF(L4=0,"",L17/L21) | N28: Net Return % | O28: =IF(O4=0,"",O17/O21)
B29: Beginning Date | C29: =IF(Trade_Log!E2="","",Trade_Log!E2) -> 45957 | E29: Beginning Date | F29: =IF(Trade_Log!E2="","",Trade_Log!E2) -> 45957 | H29: Beginning Date | I29: =IF(Trade_Log!E26="","",Trade_Log!E26) -> 45996 | K29: Beginning Date | L29: =IF(Trade_Log!E52="","",Trade_Log!E52) | N29: Beginning Date | O29: =IF(Trade_Log!E77="","",Trade_Log!E77)
B30: End Date | C30: =IF(Trade_Log!J103="","",Trade_Log!J103) | E30: End Date | F30: =IF(Trade_Log!J26="","",Trade_Log!J26) -> 46010 | H30: End Date | I30: =IF(Trade_Log!J51="","",Trade_Log!J51) | K30: End Date | L30: =IF(Trade_Log!J76="","",Trade_Log!J76) | N30: End Date | O30: =IF(Trade_Log!J101="","",Trade_Log!J101)
